Workbook

Sheet Distilled
A1: Type | B1: Time (min) | C1: Avg Temp (°C) | D1: m Measured 4He nccSTP | E1: ±2σ | F1: n0 4He nccSTP in Tube | G1: ±2σ | H1: ω Apatite-Evolved 4He nccSTP | J1: FHeApatite Corrected | K1: Corrected ln(d/a^2) | L1: ±2σ | M1: Uncorrected ln(d/a^2) | N1: FHeTube
A2: Permeation | B2: 15 | C2: 24.3 | D2: 0.0070397161 | E2: 0.00046366283 | F2: 1.4795008 | G2: 0.17715777 | N2: 0.0047581697
A3: Experirmental | B3: 240 | C3: 100 | D3: 0.16997322 | E3: 0.0010689647 | F3: 1.4724611 | G3: 0.177161 | H3: 0.049585314 | I3: 0.23714865 | J3: 8.0292822e-05 | K3: -- | L3: -- | M3: -28.390539
B4: 15 | C4: 28 | D4: 0.0072063928 | E4: 0.00039277365 | F4: 1.3520732 | G4: 0.15764618
B5: 15 | C5: 24 | D5: 0.0063909671 | E5: 0.00039211574 | F5: 1.3448668 | G5: 0.15764569
A6: Permeation | B6: 15 | C6: 24 | D6: 0.0063035258 | E6: 0.0003922416 | F6: 1.3384758 | G6: 0.1576452 | N6: 0.0047094805
A7: Experirmental | B7: 240 | C7: 150 | D7: 0.30898586 | E7: 0.0023276047 | F7: 1.3321723 | G7: 0.15764569 | H7: 0.011125653 | I7: 0.20543141 | J7: 9.830844e-05 | K7: -- | L7: -- | M7: -26.979613
B8: 15 | C8: 28.1 | D8: 0.0054182507 | E8: 0.00039240748 | F8: 1.0343121 | G8: 0.13169845
B9: 15 | C9: 24.3 | D9: 0.0048442465 | E9: 0.00039173705 | F9: 1.0288939 | G9: 0.13169787
A10: Permeation | B10: 15 | C10: 24.2 | D10: 0.0048470052 | E10: 0.00039195139 | F10: 1.0240496 | G10: 0.13169729 | N10: 0.0047331742
A11: Experirmental | B11: 240 | C11: 200.1 | D11: 0.94159047 | E11: 0.008454219 | F11: 1.0192026 | G11: 0.13169787 | H11: 1.6418389 | I11: 0.2316491 | J11: 0.0027569157 | K11: -23.80233 | L11: 0.27582053 | M11: -25.016905
B12: 15 | C12: 29.9 | D12: 0.0094679763 | E12: 0.00040549037 | F12: 1.719451 | G12: 0.19038252
B13: 15 | C13: 23.8 | D13: 0.0078570308 | E13: 0.00040143492 | F13: 1.7099831 | G13: 0.19038209
A14: Permeation | B14: 15 | C14: 24 | D14: 0.0080357965 | E14: 0.00040261459 | F14: 1.702126 | G14: 0.19038167 | N14: 0.004721035
A15: Experirmental | B15: 60 | C15: 250.2 | D15: 1.0965443 | E15: 0.010927819 | F15: 1.6940902 | G15: 0.19038209 | H15: 3.6974788 | I15: 0.47601417 | J15: 0.0087441927 | K15: -20.210909 | L15: 0.19957032 | M15: -24.010252
B16: 15 | C16: 33 | D16: 0.026533466 | E16: 0.00049953195 | F16: 4.2950248 | G16: 0.4361476
B17: 15 | C17: 23.5 | D17: 0.020157554 | E17: 0.00046327781 | F17: 4.2684913 | G17: 0.43614732
A18: Permeation | B18: 15 | C18: 24 | D18: 0.020031989 | E18: 0.00046537633 | F18: 4.2483338 | G18: 0.43614707 | N18: 0.0047152577
A19: Experirmental | B19: 60 | C19: 270.3 | D19: 2.5076806 | E19: 0.027419363 | F19: 4.2283018 | G19: 0.43614732 | H19: 5.2581583 | I19: 0.82875713 | J19: 0.017258657 | K19: -19.043016 | L19: 0.2216449 | M19: -22.51444
B20: 15 | C20: 33.9 | D20: 0.044142938 | E20: 0.0006690419 | F20: 6.9787795 | G20: 0.70417474
A21: Permeation | B21: 15 | C21: 23.6 | D21: 0.032460046 | E21: 0.00057270788 | F21: 6.9346365 | G21: 0.70417443 | N21: 0.0046808576
A22: Experirmental | B22: 60 | C22: 290.3 | D22: 4.9788581 | E22: 0.058309248 | F22: 6.9021765 | G22: 0.70417466 | H22: 8.9926264 | I22: 1.305291 | J22: 0.031820294 | K22: -17.871168 | L22: 0.20363213 | M22: -21.100115
B23: 15 | C23: 33.6 | D23: 0.06816375 | E23: 0.00095428102 | F23: 10.915945 | G23: 1.0975075
A24: Permeation | B24: 15 | C24: 23.6 | D24: 0.050498404 | E24: 0.0007758697 | F24: 10.847781 | G24: 1.097507 | N24: 0.0046551829
A25: Experirmental | B25: 60 | C25: 300.3 | D25: 7.2425431 | E25: 0.090504533 | F25: 10.797283 | G25: 1.0975073 | H25: 9.508228 | I25: 1.7092683 | J25: 0.047216838 | K25: -17.338928 | L25: 0.25013333 | M25: -20.072096
B26: 15 | C26: 34.2 | D26: 0.084341606 | E26: 0.0012002647 | F26: 13.062967 | G26: 1.3072432
B27: 15 | C27: 23.5 | D27: 0.061603994 | E27: 0.00094346982 | F27: 12.978626 | G27: 1.3072426
A28: Permeation | B28: 15 | C28: 24.1 | D28: 0.060966654 | E28: 0.00094853967 | F28: 12.917022 | G28: 1.3072423 | N28: 0.0047198693
A29: Experirmental | B29: 60 | C29: 285.3 | D29: 5.9192547 | E29: 0.07989536 | F29: 12.856055 | G29: 1.3072426 | H29: 3.5751129 | I29: 1.6845151 | J29: 0.053005969 | K29: -18.039226 | L29: 0.70831059 | M29: -20.648811
B30: 15 | C30: 36.8 | D30: 0.072903363 | E30: 0.001136436 | F30: 10.511913 | G30: 1.0593981
A31: Permeation | B31: 15 | C31: 23.6 | D31: 0.048461489 | E31: 0.00083811801 | F31: 10.43901 | G31: 1.0593975 | N31: 0.0046423453
A32: Experirmental | B32: 80 | C32: 275.2 | D32: 5.38248 | E32: 0.077292051 | F32: 10.390548 | G32: 1.0593979 | H32: 2.5210172 | I32: 1.3076851 | J32: 0.057088218 | K32: -18.578245 | L32: 1.0903722 | M32: -19.801766
B33: 15 | C33: 37 | D33: 0.052427731 | E33: 0.00092166798 | F33: 7.5290856 | G33: 0.76272036
A34: Permeation | B34: 15 | C34: 23.6 | D34: 0.034869197 | E34: 0.00070324153 | F34: 7.4766579 | G34: 0.7627198 | N34: 0.0046637412
A35: Experirmental | B35: 100 | C35: 255.2 | D35: 3.3818034 | E35: 0.051757902 | F35: 7.4417887 | G35: 0.76272012 | H35: 0.60143931 | I35: 0.90195738 | J35: 0.05806212 | K35: -- | L35: -- | M35: -20.215546
B36: 15 | C36: 37.1 | D36: 0.032063068 | E36: 0.00069073226 | F36: 4.6614246 | G36: 0.47865045
A37: Permeation | B37: 15 | C37: 23.6 | D37: 0.021471284 | E37: 0.00056416692 | F37: 4.6293615 | G37: 0.47864996 | N37: 0.004638066
A38: Experirmental | B38: 60 | C38: 300.3 | D38: 3.6843249 | E38: 0.059302486 | F38: 4.6078902 | G38: 0.47865029 | H38: 6.6769386 | I38: 0.91078037 | J38: 0.068873996 | K38: -17.16709 | L38: 0.19601763 | M38: -20.762091
B39: 15 | C39: 36.3 | D39: 0.051808902 | E39: 0.00100351 | F39: 7.600504 | G39: 0.77259174
A40: Permeation | B40: 15 | C40: 23.6 | D40: 0.035129789 | E40: 0.00076566699 | F40: 7.5486951 | G40: 0.77259109 | N40: 0.0046537565
...

Sheet Raw Data and Corrections
C1: Encapsulated Durango Apatite (r = 150 micron, 3.18mg) in tube ID 850 OD 1350 micron | E1: G = | F1: =2/(LN(0.135/0.085)*((0.085/2)^2)) -> 2393.4504 | G1: cm^-2 | V1: R (cm^3 * atm * atoms^-1 * K^1) | W1: 1.3621e-22
J2: Automated Reduction | L2: Manual Reduction with Tracked Sensitivities
A3: Avg Temp | B3: Analysis | C3: Time (min) | D3: Set Temp | E3: Timestamp | F3: 2 Int | G3: 3 Int | H3: 4 Int | I3: Ratio Int | J3: Raw nCC | K3: BC nCC | L3: sensitivity | M3: 2σ | N3: Raw nCC | O3: 2σ | P3: Blank | Q3: 2σ | R3: BC nCC | S3: 2σ | T3: cumulative measured 4He nCC | U3: 2σ | V3: total time (seconds) | W3: K 4He (Swets et al., 1961) | X3: FHeTube | Y3: n0 calc | Z3: 2σ | AA3: n0 | AB3: 2σ | AC3: ω | AD3: 2σ | AE3: C_gas/Cap
A4: 53.3 | B4: Diff Cell | C4: 15 | D4: 25C | E4: 45235.418 | F4: 656.74479 | G4: 7880.3732 | H4: 33.250194 | I4: =H4/G4 -> 0.0042193679 | J4: 0.012772 | K4: 0.007835 | L4: =(((E4-STDs!$F$12)/STDs!$E$12)*STDs!$G$13)+((1-((E4-STDs!$F$12)/STDs!$E$12))*STDs!$G$12) -> 3.2892163 | M4: =(((E4-STDs!$F$12)/STDs!$E$12)*STDs!$H$13)+((1-((E4-STDs!$F$12)/STDs!$E$12))*STDs!$H$12) -> 0.026028269 | N4: =I4*L4 -> 0.013878414 | O4: =(M4/L4)*N4 -> 0.00010982285 | P4: =(((E4-STDs!$F$12)/STDs!$E$12)*STDs!$I$13)+((1-((E4-STDs!$F$12)/STDs!$E$12))*STDs!$I$12) -> 0.005376714 | Q4: =(((E4-STDs!$F$12)/STDs!$E$12)*STDs!$J$13)+((1-((E4-STDs!$F$12)/STDs!$E$12))*STDs!$J$12) -> 0.00038710164 | R4: =N4-P4 -> 0.0085016997 | S4: =O4+Q4 -> 0.00049692449 | T4: 0 | U4: 0
A5: 24.3 | B5: Diff Cell | C5: 15 | D5: 25C | E5: 45235.459 | F5: 814.49787 | G5: 7861.865 | H5: 30.103685 | I5: =H5/G5 -> 0.0038290768 | J5: 0.01159 | K5: 0.006653 | L5: =(((E5-STDs!$F$12)/STDs!$E$12)*STDs!$G$13)+((1-((E5-STDs!$F$12)/STDs!$E$12))*STDs!$G$12) -> 3.2929816 | M5: =(((E5-STDs!$F$12)/STDs!$E$12)*STDs!$H$13)+((1-((E5-STDs!$F$12)/STDs!$E$12))*STDs!$H$12) -> 0.023179326 | N5: =I5*L5 -> 0.01260908 | O5: =(M5/L5)*N5 -> 8.8755419e-05 | P5: =(((E5-STDs!$F$12)/STDs!$E$12)*STDs!$I$13)+((1-((E5-STDs!$F$12)/STDs!$E$12))*STDs!$I$12) -> 0.0053830216 | Q5: =(((E5-STDs!$F$12)/STDs!$E$12)*STDs!$J$13)+((1-((E5-STDs!$F$12)/STDs!$E$12))*STDs!$J$12) -> 0.00038707682 | R5: =N5-P5 -> 0.007226058 | S5: =O5+Q5 -> 0.00047583224 | T5: 0 | U5: 0 | V5: =((E5-E4)*24*3600)-(5*60) -> 3244 | W5: =(0.000304*199000000000000000)*EXP(-(5580-680)/(1.987*(A5+273))) -> 1.5113411e+10 | X5: =1-EXP(-W5*$W$1*$F$1*(A5+273)*V5) -> 0.0047406751 | Y5: =R5/(X5) -> 1.5242677 | Z5: =(((S5/R5)*Y5)^2+(Y5*0.1)^2)^0.5 -> 0.18250619
A6: 24.3 | B6: Diff Cell | C6: 15 | D6: 25C | E6: 45235.5 | F6: 915.96127 | G6: 7752.5459 | H6: 29.227762 | I6: =H6/G6 -> 0.0037700856 | J6: 0.011411 | K6: 0.006474 | L6: =(((E6-STDs!$F$12)/STDs!$E$12)*STDs!$G$13)+((1-((E6-STDs!$F$12)/STDs!$E$12))*STDs!$G$12) -> 3.2967598 | M6: =(((E6-STDs!$F$12)/STDs!$E$12)*STDs!$H$13)+((1-((E6-STDs!$F$12)/STDs!$E$12))*STDs!$H$12) -> 0.020320736 | N6: =I6*L6 -> 0.012429067 | O6: =(M6/L6)*N6 -> 7.6610913e-05 | P6: =(((E6-STDs!$F$12)/STDs!$E$12)*STDs!$I$13)+((1-((E6-STDs!$F$12)/STDs!$E$12))*STDs!$I$12) -> 0.0053893506 | Q6: =(((E6-STDs!$F$12)/STDs!$E$12)*STDs!$J$13)+((1-((E6-STDs!$F$12)/STDs!$E$12))*STDs!$J$12) -> 0.00038705192 | R6: =N6-P6 -> 0.0070397161 | S6: =O6+Q6 -> 0.00046366283 | T6: 0 | U6: 0 | V6: =((E6-E5)*24*3600)-(5*60) -> 3256 | W6: =(0.000304*199000000000000000)*EXP(-(5580-680)/(1.987*(A6+273))) -> 1.5113411e+10 | X6: =1-EXP(-W6*$W$1*$F$1*(A6+273)*V6) -> 0.0047581697 | Y6: =R6/(X6) -> 1.4795008 | Z6: =(((S6/R6)*Y6)^2+(Y6*0.1)^2)^0.5 -> 0.17715777 | AA6: =Y6 -> 1.4795008 | AB6: =Z6 -> 0.17715777
A7: STD | B7: 4He STD | E7: 45235.552 | F7: 936.58464 | G7: 7849.1801 | H7: 9522.7807 | I7: =H7/G7 -> 1.2132198 | J7: 3.997998 | K7: 3.992623 | L7: =J7/I7 -> 3.2953616 | P7: =J7-K7 -> 0.005375 | T7: 0 | U7: 0 | V7: =((E7-E6)*24*3600)-(5*60) -> 4196 | AA7: -
A8: STD | B8: 4He STD | E8: 45235.586 | F8: 917.64049 | G8: 7734.4132 | H8: 9337.7776 | I8: =H8/G8 -> 1.2073027 | J8: 3.997225 | K8: 3.991825 | L8: =J8/I8 -> 3.3108724 | P8: =J8-K8 -> 0.0054 | T8: =T7 -> 0 | U8: 0 | V8: =((E8-E7)*24*3600)-(5*60) -> 2675 | AA8: -
A9: 100 | B9: Diff Cell | C9: 240 | D9: 100C | E9: 45235.767 | F9: 880.96997 | G9: 7864.4798 | H9: 417.9725 | I9: =H9/G9 -> 0.053146872 | J9: 0.175964 | K9: 0.170564 | L9: =(((E9-STDs!$F$13)/STDs!$E$13)*STDs!$G$14)+((1-((E9-STDs!$F$13)/STDs!$E$13)))*STDs!$G$13 -> 3.2997455 | M9: =(((E9-STDs!$F$13)/STDs!$E$13)*STDs!$H$14)+((1-((E9-STDs!$F$13)/STDs!$E$13))*STDs!$H$13) -> 0.018756896 | N9: =I9*L9 -> 0.17537115 | O9: =(M9/L9)*N9 -> 0.00099687037 | P9: =(((E9-STDs!$F$13)/STDs!$E$13)*STDs!$I$14)+((1-((E9-STDs!$F$13)/STDs!$E$13))*STDs!$I$13) -> 0.0053979315 | Q9: =(((E9-STDs!$F$13)/STDs!$E$13)*STDs!$J$14)+((1-((E9-STDs!$F$13)/STDs!$E$13))*STDs!$J$13) -> 0.00038592098 | R9: =N9-P9 -> 0.16997322 | S9: =(O9^2+Q9^2)^0.5 -> 0.0010689647 | T9: =R9+T8 -> 0.16997322 | U9: =(S9^2+U8^2)^0.5 -> 0.0010689647 | V9: =((E9-E8)*24*3600)-(5*60) -> 15286 | W9: =(0.000304*199000000000000000)*EXP(-(5580-680)/(1.987*(A9+273))) -> 8.1368988e+10 | AA9: =Y6-R6 -> 1.4724611 | AB9: =(AB6^2+S9^2)^0.5 -> 0.177161 | AC9: =R9+AA10-AA9 -> 0.049585314 | AD9: =(S9^2+AB9^2+AB10^2)^0.5 -> 0.23714865 | AE9: =0.2*AA9/($D$89-T9) -> 0.00047699852
A10: 28 | B10: Diff Cell | C10: 15 | D10: 25C | E10: 45235.808 | F10: 1023.8112 | G10: 7730.9796 | H10: 29.535947 | I10: =H10/G10 -> 0.0038204663 | J10: 0.012648 | K10: 0.007248 | L10: =(((E10-STDs!$F$13)/STDs!$E$13)*STDs!$G$14)+((1-((E10-STDs!$F$13)/STDs!$E$13)))*STDs!$G$13 -> 3.2990463 | M10: =(((E10-STDs!$F$13)/STDs!$E$13)*STDs!$H$14)+((1-((E10-STDs!$F$13)/STDs!$E$13))*STDs!$H$13) -> 0.019430143 | N10: =I10*L10 -> 0.012603895 | O10: =(M10/L10)*N10 -> 7.4232205e-05 | P10: =(((E10-STDs!$F$13)/STDs!$E$13)*STDs!$I$14)+((1-((E10-STDs!$F$13)/STDs!$E$13))*STDs!$I$13) -> 0.0053975025 | Q10: =(((E10-STDs!$F$13)/STDs!$E$13)*STDs!$J$14)+((1-((E10-STDs!$F$13)/STDs!$E$13))*STDs!$J$13) -> 0.00038569511 | R10: =N10-P10 -> 0.0072063928 | S10: =(O10^2+Q10^2)^0.5 -> 0.00039277365 | T10: =R10+T9 -> 0.17717962 | U10: =(S10^2+U9^2)^0.5 -> 0.0011388401 | V10: =((E10-E9)*24*3600)-(5*60) -> 3241 | W10: =(0.000304*199000000000000000)*EXP(-(5580-680)/(1.987*(A10+273))) -> 1.6735706e+10 | X10: =1-EXP(-W10*$W$1*$F$1*(A10+273)*V10) -> 0.0053084497 | Y10: =R10/(X10) -> 1.3575325 | Z10: =(((S10/R10)*Y10)^2+(Y10*0.1)^2)^0.5 -> 0.15460758 | AA10: =AA11+R10 -> 1.3520732 | AB10: =(S10^2+AB11^2)^0.5 -> 0.15764618 | AE10: =0.2*AA10/($D$89-T10) -> 0.0004380044
A11: 24 | B11: Diff Cell | C11: 15 | D11: 25C | E11: 45235.85 | F11: 1051.7218 | G11: 7742.8887 | H11: 27.672663 | I11: =H11/G11 -> 0.0035739456 | J11: 0.01183 | K11: 0.00643 | L11: =(((E11-STDs!$F$13)/STDs!$E$13)*STDs!$G$14)+((1-((E11-STDs!$F$13)/STDs!$E$13)))*STDs!$G$13 -> 3.2983226 | M11: =(((E11-STDs!$F$13)/STDs!$E$13)*STDs!$H$14)+((1-((E11-STDs!$F$13)/STDs!$E$13))*STDs!$H$13) -> 0.020126965 | N11: =I11*L11 -> 0.011788026 | O11: =(M11/L11)*N11 -> 7.1932678e-05 | P11: =(((E11-STDs!$F$13)/STDs!$E$13)*STDs!$I$14)+((1-((E11-STDs!$F$13)/STDs!$E$13))*STDs!$I$13) -> 0.0053970584 | Q11: =(((E11-STDs!$F$13)/STDs!$E$13)*STDs!$J$14)+((1-((E11-STDs!$F$13)/STDs!$E$13))*STDs!$J$13) -> 0.00038546134 | R11: =N11-P11 -> 0.0063909671 | S11: =(O11^2+Q11^2)^0.5 -> 0.00039211574 | T11: =R11+T10 -> 0.18357058 | U11: =(S11^2+U10^2)^0.5 -> 0.0012044548 | V11: =((E11-E10)*24*3600)-(5*60) -> 3365 | W11: =(0.000304*199000000000000000)*EXP(-(5580-680)/(1.987*(A11+273))) -> 1.4987311e+10 | X11: =1-EXP(-W11*$W$1*$F$1*(A11+273)*V11) -> 0.0048712312 | Y11: =R11/(X11) -> 1.3119819 | Z11: =(((S11/R11)*Y11)^2+(Y11*0.1)^2)^0.5 -> 0.15392403 | AA11: =AA12+R11 -> 1.3448668 | AB11: =(S11^2+AB12^2)^0.5 -> 0.15764569 | AE11: =0.2*AA11/($D$89-T11) -> 0.0004356744
A12: 24 | B12: Diff Cell | C12: 15 | D12: 25C | E12: 45235.891 | F12: 1057.6855 | G12: 7748.2243 | H12: 27.491157 | I12: =H12/G12 -> 0.003548059 | J12: 0.011745 | K12: 0.006345 | L12: =(((E12-STDs!$F$13)/STDs!$E$13)*STDs!$G$14)+((1-((E12-STDs!$F$13)/STDs!$E$13)))*STDs!$G$13 -> 3.297621 | M12: =(((E12-STDs!$F$13)/STDs!$E$13)*STDs!$H$14)+((1-((E12-STDs!$F$13)/STDs!$E$13))*STDs!$H$13) -> 0.020802493 | N12: =I12*L12 -> 0.011700154 | O12: =(M12/L12)*N12 -> 7.3808471e-05 | P12: =(((E12-STDs!$F$13)/STDs!$E$13)*STDs!$I$14)+((1-((E12-STDs!$F$13)/STDs!$E$13))*STDs!$I$13) -> 0.005396628 | Q12: =(((E12-STDs!$F$13)/STDs!$E$13)*STDs!$J$14)+((1-((E12-STDs!$F$13)/STDs!$E$13))*STDs!$J$13) -> 0.00038523471 | R12: =N12-P12 -> 0.0063035258 | S12: =(O12^2+Q12^2)^0.5 -> 0.0003922416 | T12: =R12+T11 -> 0.18987411 | U12: =(S12^2+U11^2)^0.5 -> 0.0012667142 | V12: =((E12-E11)*24*3600)-(5*60) -> 3253 | W12: =(0.000304*199000000000000000)*EXP(-(5580-680)/(1.987*(A12+273))) -> 1.4987311e+10 | X12: =1-EXP(-W12*$W$1*$F$1*(A12+273)*V12) -> 0.0047094805 | Y12: =R12/(X12) -> 1.3384758 | Z12: =(((S12/R12)*Y12)^2+(Y12*0.1)^2)^0.5 -> 0.1576452 | AA12: =Y12 -> 1.3384758 | AB12: =Z12 -> 0.1576452 | AE12: =0.2*AA12/($D$89-T12) -> 0.00043360845
A13: 150 | B13: Diff Cell | C13: 240 | D13: 150C | E13: 45236.089 | F13: 831.40539 | G13: 7867.4312 | H13: 750.81487 | I13: =H13/G13 -> 0.095433294 | J13: 0.315964 | K13: 0.310564 | L13: =(((E13-STDs!$F$13)/STDs!$E$13)*STDs!$G$14)+((1-((E13-STDs!$F$13)/STDs!$E$13)))*STDs!$G$13 -> 3.2942425 | M13: =(((E13-STDs!$F$13)/STDs!$E$13)*STDs!$H$14)+((1-((E13-STDs!$F$13)/STDs!$E$13))*STDs!$H$13) -> 0.024055407 | N13: =I13*L13 -> 0.31438041 | O13: =(M13/L13)*N13 -> 0.0022956867 | P13: =(((E13-STDs!$F$13)/STDs!$E$13)*STDs!$I$14)+((1-((E13-STDs!$F$13)/STDs!$E$13))*STDs!$I$13) -> 0.0053945551 | Q13: =(((E13-STDs!$F$13)/STDs!$E$13)*STDs!$J$14)+((1-((E13-STDs!$F$13)/STDs!$E$13))*STDs!$J$13) -> 0.00038414341 | R13: =N13-P13 -> 0.30898586 | S13: =(O13^2+Q13^2)^0.5 -> 0.0023276047 | T13: =R13+T12 -> 0.49885997 | U13: =(S13^2+U12^2)^0.5 -> 0.0026499639 | V13: =((E13-E12)*24*3600)-(5*60) -> 16809 | W13: =(0.000304*199000000000000000)*EXP(-(5580-680)/(1.987*(A13+273))) -> 1.7776746e+11 | AA13: =AA12-R12 -> 1.3321723 | AB13: =(AB12^2+S12^2)^0.5 -> 0.15764569 | AC13: =R13+AA14-AA13 -> 0.011125653 | AD13: =(S13^2+AB13^2+AB14^2)^0.5 -> 0.20543141 | AE13: =0.2*AA13/($D$89-T13) -> 0.00043178248
A14: 28.1 | B14: Diff Cell | C14: 15 | D14: 25C | E14: 45236.13 | F14: 933.10524 | G14: 7806.0965 | H14: 25.626654 | I14: =H14/G14 -> 0.0032829025 | J14: 0.010868 | K14: 0.005467 | L14: =(((E14-STDs!$F$13)/STDs!$E$13)*STDs!$G$14)+((1-((E14-STDs!$F$13)/STDs!$E$13)))*STDs!$G$13 -> 3.2935415 | M14: =(((E14-STDs!$F$13)/STDs!$E$13)*STDs!$H$14)+((1-((E14-STDs!$F$13)/STDs!$E$13))*STDs!$H$13) -> 0.024730364 | N14: =I14*L14 -> 0.010812376 | O14: =(M14/L14)*N14 -> 8.1187376e-05 | P14: =(((E14-STDs!$F$13)/STDs!$E$13)*STDs!$I$14)+((1-((E14-STDs!$F$13)/STDs!$E$13))*STDs!$I$13) -> 0.005394125 | Q14: =(((E14-STDs!$F$13)/STDs!$E$13)*STDs!$J$14)+((1-((E14-STDs!$F$13)/STDs!$E$13))*STDs!$J$13) -> 0.00038391698 | R14: =N14-P14 -> 0.0054182507 | S14: =(O14^2+Q14^2)^0.5 -> 0.00039240748 | T14: =R14+T13 -> 0.50427822 | U14: =(S14^2+U13^2)^0.5 -> 0.0026788603 | V14: =((E14-E13)*24*3600)-(5*60) -> 3250 | W14: =(0.000304*199000000000000000)*EXP(-(5580-680)/(1.987*(A14+273))) -> 1.6781305e+10 | X14: =1-EXP(-W14*$W$1*$F$1*(A14+273)*V14) -> 0.0053393851 | Y14: =R14/(X14) -> 1.0147705 | Z14: =(((S14/R14)*Y14)^2+(Y14*0.1)^2)^0.5 -> 0.12529491 | AA14: =AA15+R14 -> 1.0343121 | AB14: =(S14^2+AB15^2)^0.5 -> 0.13169845 | AE14: =0.2*AA14/($D$89-T14) -> 0.00033524325
A15: 24.3 | B15: Diff Cell | C15: 15 | D15: 25C | E15: 45236.172 | F15: 945.61404 | G15: 7820.007 | H15: 24.313596 | I15: =H15/G15 -> 0.0031091527 | J15: 0.010292 | K15: 0.004892 | L15: =(((E15-STDs!$F$13)/STDs!$E$13)*STDs!$G$14)+((1-((E15-STDs!$F$13)/STDs!$E$13)))*STDs!$G$13 -> 3.2928395 | M15: =(((E15-STDs!$F$13)/STDs!$E$13)*STDs!$H$14)+((1-((E15-STDs!$F$13)/STDs!$E$13))*STDs!$H$13) -> 0.025406272 | N15: =I15*L15 -> 0.010237941 | O15: =(M15/L15)*N15 -> 7.8991981e-05 | P15: =(((E15-STDs!$F$13)/STDs!$E$13)*STDs!$I$14)+((1-((E15-STDs!$F$13)/STDs!$E$13))*STDs!$I$13) -> 0.0053936943 | Q15: =(((E15-STDs!$F$13)/STDs!$E$13)*STDs!$J$14)+((1-((E15-STDs!$F$13)/STDs!$E$13))*STDs!$J$13) -> 0.00038369022 | R15: =N15-P15 -> 0.0048442465 | S15: =(O15^2+Q15^2)^0.5 -> 0.00039173705 | T15: =R15+T14 -> 0.50912246 | U15: =(S15^2+U14^2)^0.5 -> 0.0027073511 | V15: =((E15-E14)*24*3600)-(5*60) -> 3255 | W15: =(0.000304*199000000000000000)*EXP(-(5580-680)/(1.987*(A15+273))) -> 1.5113411e+10 | X15: =1-EXP(-W15*$W$1*$F$1*(A15+273)*V15) -> 0.0047567119 | Y15: =R15/(X15) -> 1.0184023 | Z15: =(((S15/R15)*Y15)^2+(Y15*0.1)^2)^0.5 -> 0.13097218 | AA15: =AA16+R15 -> 1.0288939 | AB15: =(S15^2+AB16^2)^0.5 -> 0.13169787 | AE15: =0.2*AA15/($D$89-T15) -> 0.00033348969
A16: 24.2 | B16: Diff Cell | C16: 15 | D16: 25C | E16: 45236.213 | F16: 952.35268 | G16: 7799.0326 | H16: 24.259062 | I16: =H16/G16 -> 0.0031105219 | J16: 0.010297 | K16: 0.004897 | L16: =(((E16-STDs!$F$13)/STDs!$E$13)*STDs!$G$14)+((1-((E16-STDs!$F$13)/STDs!$E$13)))*STDs!$G$13 -> 3.2921387 | M16: =(((E16-STDs!$F$13)/STDs!$E$13)*STDs!$H$14)+((1-((E16-STDs!$F$13)/STDs!$E$13))*STDs!$H$13) -> 0.02608104 | N16: =I16*L16 -> 0.01024027 | O16: =(M16/L16)*N16 -> 8.1125646e-05 | P16: =(((E16-STDs!$F$13)/STDs!$E$13)*STDs!$I$14)+((1-((E16-STDs!$F$13)/STDs!$E$13))*STDs!$I$13) -> 0.0053932643 | Q16: =(((E16-STDs!$F$13)/STDs!$E$13)*STDs!$J$14)+((1-((E16-STDs!$F$13)/STDs!$E$13))*STDs!$J$13) -> 0.00038346385 | R16: =N16-P16 -> 0.0048470052 | S16: =(O16^2+Q16^2)^0.5 -> 0.00039195139 | T16: =R16+T15 -> 0.51396947 | U16: =(S16^2+U15^2)^0.5 -> 0.002735576 | V16: =((E16-E15)*24*3600)-(5*60) -> 3249 | W16: =(0.000304*199000000000000000)*EXP(-(5580-680)/(1.987*(A16+273))) -> 1.5071289e+10 | X16: =1-EXP(-W16*$W$1*$F$1*(A16+273)*V16) -> 0.0047331742 | Y16: =R16/(X16) -> 1.0240496 | Z16: =(((S16/R16)*Y16)^2+(Y16*0.1)^2)^0.5 -> 0.13169729 | AA16: =Y16 -> 1.0240496 | AB16: =Z16 -> 0.13169729 | AE16: =0.2*AA16/($D$89-T16) -> 0.00033192216
A17: 200.1 | B17: Diff Cell | C17: 240 | D17: 200C | E17: 45236.41 | F17: 791.26508 | G17: 7925.1603 | H17: 2282.0069 | I17: =H17/G17 -> 0.28794457 | J17: 0.953359 | K17: 0.947959 | L17: =(((E17-STDs!$F$13)/STDs!$E$13)*STDs!$G$14)+((1-((E17-STDs!$F$13)/STDs!$E$13)))*STDs!$G$13 -> 3.2887638 | M17: =(((E17-STDs!$F$13)/STDs!$E$13)*STDs!$H$14)+((1-((E17-STDs!$F$13)/STDs!$E$13))*STDs!$H$13) -> 0.029330532 | N17: =I17*L17 -> 0.94698166 | O17: =(M17/L17)*N17 -> 0.0084455674 | P17: =(((E17-STDs!$F$13)/STDs!$E$13)*STDs!$I$14)+((1-((E17-STDs!$F$13)/STDs!$E$13))*STDs!$I$13) -> 0.0053911937 | Q17: =(((E17-STDs!$F$13)/STDs!$E$13)*STDs!$J$14)+((1-((E17-STDs!$F$13)/STDs!$E$13))*STDs!$J$13) -> 0.00038237369 | R17: =N17-P17 -> 0.94159047 | S17: =(O17^2+Q17^2)^0.5 -> 0.008454219 | T17: =R17+T16 -> 1.4555599 | U17: =(S17^2+U16^2)^0.5 -> 0.0088857861 | V17: =((E17-E16)*24*3600)-(5*60) -> 16791 | W17: =(0.000304*199000000000000000)*EXP(-(5580-680)/(1.987*(A17+273))) -> 3.295876e+11 | AA17: =AA16-R16 -> 1.0192026 | AB17: =(AB16^2+S16^2)^0.5 -> 0.13169787 | AC17: =R17+AA18-AA17 -> 1.6418389 | AD17: =(S17^2+AB17^2+AB18^2)^0.5 -> 0.2316491 | AE17: =0.2*AA17/($D$89-T17) -> 0.00033085599
A18: 29.9 | B18: Diff Cell | C18: 15 | D18: 25C | E18: 45236.452 | F18: 872.70806 | G18: 7868.7416 | H18: 35.558806 | I18: =H18/G18 -> 0.0045189953 | J18: 0.014959 | K18: 0.009559 | L18: =(((E18-STDs!$F$13)/STDs!$E$13)*STDs!$G$14)+((1-((E18-STDs!$F$13)/STDs!$E$13)))*STDs!$G$13 -> 3.2880627 | M18: =(((E18-STDs!$F$13)/STDs!$E$13)*STDs!$H$14)+((1-((E18-STDs!$F$13)/STDs!$E$13))*STDs!$H$13) -> 0.030005489 | N18: =I18*L18 -> 0.01485874 | O18: =(M18/L18)*N18 -> 0.00013559466 | P18: =(((E18-STDs!$F$13)/STDs!$E$13)*STDs!$I$14)+((1-((E18-STDs!$F$13)/STDs!$E$13))*STDs!$I$13) -> 0.0053907636 | Q18: =(((E18-STDs!$F$13)/STDs!$E$13)*STDs!$J$14)+((1-((E18-STDs!$F$13)/STDs!$E$13))*STDs!$J$13) -> 0.00038214726 | R18: =N18-P18 -> 0.0094679763 | S18: =(O18^2+Q18^2)^0.5 -> 0.00040549037 | T18: =R18+T17 -> 1.4650279 | U18: =(S18^2+U17^2)^0.5 -> 0.0088950333 | V18: =((E18-E17)*24*3600)-(5*60) -> 3250 | W18: =(0.000304*199000000000000000)*EXP(-(5580-680)/(1.987*(A18+273))) -> 1.7618252e+10 | X18: =1-EXP(-W18*$W$1*$F$1*(A18+273)*V18) -> 0.0056383448 | Y18: =R18/(X18) -> 1.679212 | Z18: =(((S18/R18)*Y18)^2+(Y18*0.1)^2)^0.5 -> 0.18267327 | AA18: =AA19+R18 -> 1.719451 | AB18: =(S18^2+AB19^2)^0.5 -> 0.19038252 | AE18: =0.2*AA18/($D$89-T18) -> 0.00055818089
A19: 23.8 | B19: Diff Cell | C19: 15 | D19: 25C | E19: 45236.493 | F19: 903.34539 | G19: 7850.6412 | H19: 31.636412 | I19: =H19/G19 -> 0.004029787 | J19: 0.013339 | K19: 0.007939 | L19: =(((E19-STDs!$F$13)/STDs!$E$13)*STDs!$G$14)+((1-((E19-STDs!$F$13)/STDs!$E$13)))*STDs!$G$13 -> 3.2873607 | M19: =(((E19-STDs!$F$13)/STDs!$E$13)*STDs!$H$14)+((1-((E19-STDs!$F$13)/STDs!$E$13))*STDs!$H$13) -> 0.030681397 | N19: =I19*L19 -> 0.013247364 | O19: =(M19/L19)*N19 -> 0.0001236395 | P19: =(((E19-STDs!$F$13)/STDs!$E$13)*STDs!$I$14)+((1-((E19-STDs!$F$13)/STDs!$E$13))*STDs!$I$13) -> 0.0053903329 | Q19: =(((E19-STDs!$F$13)/STDs!$E$13)*STDs!$J$14)+((1-((E19-STDs!$F$13)/STDs!$E$13))*STDs!$J$13) -> 0.0003819205 | R19: =N19-P19 -> 0.0078570308 | S19: =(O19^2+Q19^2)^0.5 -> 0.00040143492 | T19: =R19+T18 -> 1.4728849 | U19: =(S19^2+U18^2)^0.5 -> 0.0089040871 | V19: =((E19-E18)*24*3600)-(5*60) -> 3255 | W19: =(0.000304*199000000000000000)*EXP(-(5580-680)/(1.987*(A19+273))) -> 1.490369e+10 | X19: =1-EXP(-W19*$W$1*$F$1*(A19+273)*V19) -> 0.00468299 | Y19: =R19/(X19) -> 1.6777808 | Z19: =(((S19/R19)*Y19)^2+(Y19*0.1)^2)^0.5 -> 0.18840842 | AA19: =AA20+R19 -> 1.7099831 | AB19: =(S19^2+AB20^2)^0.5 -> 0.19038209 | AE19: =0.2*AA19/($D$89-T19) -> 0.0005551144
A20: 24 | B20: Diff Cell | C20: 15 | D20: 25C | E20: 45236.534 | F20: 916.37698 | G20: 7827.0216 | H20: 31.972673 | I20: =H20/G20 -> 0.0040849093 | J20: 0.013523 | K20: 0.008123 | L20: =(((E20-STDs!$F$13)/STDs!$E$13)*STDs!$G$14)+((1-((E20-STDs!$F$13)/STDs!$E$13)))*STDs!$G$13 -> 3.2866576 | M20: =(((E20-STDs!$F$13)/STDs!$E$13)*STDs!$H$14)+((1-((E20-STDs!$F$13)/STDs!$E$13))*STDs!$H$13) -> 0.031358446 | N20: =I20*L20 -> 0.013425698 | O20: =(M20/L20)*N20 -> 0.00012809641 | P20: =(((E20-STDs!$F$13)/STDs!$E$13)*STDs!$I$14)+((1-((E20-STDs!$F$13)/STDs!$E$13))*STDs!$I$13) -> 0.0053899014 | Q20: =(((E20-STDs!$F$13)/STDs!$E$13)*STDs!$J$14)+((1-((E20-STDs!$F$13)/STDs!$E$13))*STDs!$J$13) -> 0.00038169336 | R20: =N20-P20 -> 0.0080357965 | S20: =(O20^2+Q20^2)^0.5 -> 0.00040261459 | T20: =R20+T19 -> 1.4809207 | U20: =(S20^2+U19^2)^0.5 -> 0.0089131849 | V20: =((E20-E19)*24*3600)-(5*60) -> 3261 | W20: =(0.000304*199000000000000000)*EXP(-(5580-680)/(1.987*(A20+273))) -> 1.4987311e+10 | X20: =1-EXP(-W20*$W$1*$F$1*(A20+273)*V20) -> 0.004721035 | Y20: =R20/(X20) -> 1.702126 | Z20: =(((S20/R20)*Y20)^2+(Y20*0.1)^2)^0.5 -> 0.19038167 | AA20: =Y20 -> 1.702126 | AB20: =Z20 -> 0.19038167 | AE20: =0.2*AA20/($D$89-T20) -> 0.00055257097
A21: 250.2 | B21: Diff Cell | C21: 60 | D21: 250C | E21: 45236.607 | F21: 892.57698 | G21: 7873.4076 | H21: 2640.7589 | I21: =H21/G21 -> 0.33540228 | J21: 1.110473 | K21: 1.105073 | L21: =(((E21-STDs!$F$13)/STDs!$E$13)*STDs!$G$14)+((1-((E21-STDs!$F$13)/STDs!$E$13)))*STDs!$G$13 -> 3.2854082 | M21: =(((E21-STDs!$F$13)/STDs!$E$13)*STDs!$H$14)+((1-((E21-STDs!$F$13)/STDs!$E$13))*STDs!$H$13) -> 0.032561391 | N21: =I21*L21 -> 1.1019334 | O21: =(M21/L21)*N21 -> 0.010921165 | P21: =(((E21-STDs!$F$13)/STDs!$E$13)*STDs!$I$14)+((1-((E21-STDs!$F$13)/STDs!$E$13))*STDs!$I$13) -> 0.0053891349 | Q21: =(((E21-STDs!$F$13)/STDs!$E$13)*STDs!$J$14)+((1-((E21-STDs!$F$13)/STDs!$E$13))*STDs!$J$13) -> 0.00038128979 | R21: =N21-P21 -> 1.0965443 | S21: =(O21^2+Q21^2)^0.5 -> 0.010927819 | T21: =R21+T20 -> 2.577465 | U21: =(S21^2+U20^2)^0.5 -> 0.014101847 | V21: =((E21-E20)*24*3600)-(5*60) -> 6027 | W21: =(0.000304*199000000000000000)*EXP(-(5580-680)/(1.987*(A21+273))) -> 5.4292652e+11 | AA21: =AA20-R20 -> 1.6940902 | AB21: =(AB20^2+S20^2)^0.5 -> 0.19038209 | AC21: =R21+AA22-AA21 -> 3.6974788 | AD21: =(S21^2+AB21^2+AB22^2)^0.5 -> 0.47601417 | AE21: =0.2*AA21/($D$89-T21) -> 0.00055094288
A22: 33 | B22: Diff Cell | C22: 15 | D22: 25C | E22: 45236.648 | F22: 909.96203 | G22: 7826.0568 | H22: 76.056889 | I22: =H22/G22 -> 0.0097184178 | J22: 0.032173 | K22: 0.026773 | L22: =(((E22-STDs!$F$13)/STDs!$E$13)*STDs!$G$14)+((1-((E22-STDs!$F$13)/STDs!$E$13)))*STDs!$G$13 -> 3.2847087 | M22: =(((E22-STDs!$F$13)/STDs!$E$13)*STDs!$H$14)+((1-((E22-STDs!$F$13)/STDs!$E$13))*STDs!$H$13) -> 0.033234828 | N22: =I22*L22 -> 0.031922172 | O22: =(M22/L22)*N22 -> 0.00032298994 | P22: =(((E22-STDs!$F$13)/STDs!$E$13)*STDs!$I$14)+((1-((E22-STDs!$F$13)/STDs!$E$13))*STDs!$I$13) -> 0.0053887058 | Q22: =(((E22-STDs!$F$13)/STDs!$E$13)*STDs!$J$14)+((1-((E22-STDs!$F$13)/STDs!$E$13))*STDs!$J$13) -> 0.00038106387 | R22: =N22-P22 -> 0.026533466 | S22: =(O22^2+Q22^2)^0.5 -> 0.00049953195 | T22: =R22+T21 -> 2.6039985 | U22: =(S22^2+U21^2)^0.5 -> 0.014110692 | V22: =((E22-E21)*24*3600)-(5*60) -> 3242 | W22: =(0.000304*199000000000000000)*EXP(-(5580-680)/(1.987*(A22+273))) -> 1.9132981e+10 | X22: =1-EXP(-W22*$W$1*$F$1*(A22+273)*V22) -> 0.0061688965 | Y22: =R22/(X22) -> 4.301169 | Z22: =(((S22/R22)*Y22)^2+(Y22*0.1)^2)^0.5 -> 0.43767298 | AA22: =AA23+R22 -> 4.2950248 | AB22: =(S22^2+AB23^2)^0.5 -> 0.4361476 | AE22: =0.2*AA22/($D$89-T22) -> 0.001396865
A23: 23.5 | B23: Diff Cell | C23: 15 | D23: 25C | E23: 45236.689 | F23: 904.40351 | G23: 7834.5351 | H23: 60.943779 | I23: =H23/G23 -> 0.0077788635 | J23: 0.025753 | K23: 0.020353 | L23: =(((E23-STDs!$F$13)/STDs!$E$13)*STDs!$G$14)+((1-((E23-STDs!$F$13)/STDs!$E$13)))*STDs!$G$13 -> 3.2840052 | M23: =(((E23-STDs!$F$13)/STDs!$E$13)*STDs!$H$14)+((1-((E23-STDs!$F$13)/STDs!$E$13))*STDs!$H$13) -> 0.033912257 | N23: =I23*L23 -> 0.025545828 | O23: =(M23/L23)*N23 -> 0.00026379882 | P23: =(((E23-STDs!$F$13)/STDs!$E$13)*STDs!$I$14)+((1-((E23-STDs!$F$13)/STDs!$E$13))*STDs!$I$13) -> 0.0053882741 | Q23: =(((E23-STDs!$F$13)/STDs!$E$13)*STDs!$J$14)+((1-((E23-STDs!$F$13)/STDs!$E$13))*STDs!$J$13) -> 0.0003808366 | R23: =N23-P23 -> 0.020157554 | S23: =(O23^2+Q23^2)^0.5 -> 0.00046327781 | T23: =R23+T22 -> 2.624156 | U23: =(S23^2+U22^2)^0.5 -> 0.014118295 | V23: =((E23-E22)*24*3600)-(5*60) -> 3263 | W23: =(0.000304*199000000000000000)*EXP(-(5580-680)/(1.987*(A23+273))) -> 1.4778923e+10 | X23: =1-EXP(-W23*$W$1*$F$1*(A23+273)*V23) -> 0.0046505696 | Y23: =R23/(X23) -> 4.3344268 | Z23: =(((S23/R23)*Y23)^2+(Y23*0.1)^2)^0.5 -> 0.44474284 | AA23: =AA24+R23 -> 4.2684913 | AB23: =(S23^2+AB24^2)^0.5 -> 0.43614732 | AE23: =0.2*AA23/($D$89-T23) -> 0.0013882811
A24: 24 | B24: Diff Cell | C24: 15 | D24: 25C | E24: 45236.73 | F24: 900.7655 | G24: 7839.2887 | H24: 60.692971 | I24: =H24/G24 -> 0.0077421528 | J24: 0.025631 | K24: 0.020231 | L24: =(((E24-STDs!$F$13)/STDs!$E$13)*STDs!$G$14)+((1-((E24-STDs!$F$13)/STDs!$E$13)))*STDs!$G$13 -> 3.2833028 | M24: =(((E24-STDs!$F$13)/STDs!$E$13)*STDs!$H$14)+((1-((E24-STDs!$F$13)/STDs!$E$13))*STDs!$H$13) -> 0.034588545 | N24: =I24*L24 -> 0.025419832 | O24: =(M24/L24)*N24 -> 0.0002677898 | P24: =(((E24-STDs!$F$13)/STDs!$E$13)*STDs!$I$14)+((1-((E24-STDs!$F$13)/STDs!$E$13))*STDs!$I$13) -> 0.0053878431 | Q24: =(((E24-STDs!$F$13)/STDs!$E$13)*STDs!$J$14)+((1-((E24-STDs!$F$13)/STDs!$E$13))*STDs!$J$13) -> 0.00038060971 | R24: =N24-P24 -> 0.020031989 | S24: =(O24^2+Q24^2)^0.5 -> 0.00046537633 | T24: =R24+T23 -> 2.644188 | U24: =(S24^2+U23^2)^0.5 -> 0.014125963 | V24: =((E24-E23)*24*3600)-(5*60) -> 3257 | W24: =(0.000304*199000000000000000)*EXP(-(5580-680)/(1.987*(A24+273))) -> 1.4987311e+10 | X24: =1-EXP(-W24*$W$1*$F$1*(A24+273)*V24) -> 0.0047152577 | Y24: =R24/(X24) -> 4.2483338 | Z24: =(((S24/R24)*Y24)^2+(Y24*0.1)^2)^0.5 -> 0.43614707 | AA24: =Y24 -> 4.2483338 | AB24: =Z24 -> 0.43614707 | AE24: =0.2*AA24/($D$89-T24) -> 0.0013817701
A25: 270.3 | B25: Diff Cell | C25: 60 | D25: 270C | E25: 45236.805 | F25: 859.57514 | G25: 7938.4229 | H25: 6078.4767 | I25: =H25/G25 -> 0.76570331 | J25: 2.535141 | K25: 2.529741 | L25: =(((E25-STDs!$F$13)/STDs!$E$13)*STDs!$G$14)+((1-((E25-STDs!$F$13)/STDs!$E$13)))*STDs!$G$13 -> 3.2820384 | M25: =(((E25-STDs!$F$13)/STDs!$E$13)*STDs!$H$14)+((1-((E25-STDs!$F$13)/STDs!$E$13))*STDs!$H$13) -> 0.03580594 | N25: =I25*L25 -> 2.5130677 | O25: =(M25/L25)*N25 -> 0.027416727 | P25: =(((E25-STDs!$F$13)/STDs!$E$13)*STDs!$I$14)+((1-((E25-STDs!$F$13)/STDs!$E$13))*STDs!$I$13) -> 0.0053870674 | Q25: =(((E25-STDs!$F$13)/STDs!$E$13)*STDs!$J$14)+((1-((E25-STDs!$F$13)/STDs!$E$13))*STDs!$J$13) -> 0.0003802013 | R25: =N25-P25 -> 2.5076806 | S25: =(O25^2+Q25^2)^0.5 -> 0.027419363 | T25: =R25+T24 -> 5.1518686 | U25: =(S25^2+U24^2)^0.5 -> 0.030844194 | V25: =((E25-E24)*24*3600)-(5*60) -> 6103 | W25: =(0.000304*199000000000000000)*EXP(-(5580-680)/(1.987*(A25+273))) -> 6.4635574e+11 | AA25: =AA24-R24 -> 4.2283018 | AB25: =(AB24^2+S24^2)^0.5 -> 0.43614732 | AC25: =R25+AA26-AA25 -> 5.2581583 | AD25: =(S25^2+AB25^2+AB26^2)^0.5 -> 0.82875713 | AE25: =0.2*AA25/($D$89-T25) -> 0.0013808861
A26: 33.9 | B26: Diff Cell | C26: 15 | D26: 25C | E26: 45236.846 | F26: 868.20482 | G26: 7895.7965 | H26: 119.18176 | I26: =H26/G26 -> 0.01509433 | J26: 0.049972 | K26: 0.044572 | L26: =(((E26-STDs!$F$13)/STDs!$E$13)*STDs!$G$14)+((1-((E26-STDs!$F$13)/STDs!$E$13)))*STDs!$G$13 -> 3.2813364 | M26: =(((E26-STDs!$F$13)/STDs!$E$13)*STDs!$H$14)+((1-((E26-STDs!$F$13)/STDs!$E$13))*STDs!$H$13) -> 0.036481848 | N26: =I26*L26 -> 0.049529574 | O26: =(M26/L26)*N26 -> 0.00055066905 | P26: =(((E26-STDs!$F$13)/STDs!$E$13)*STDs!$I$14)+((1-((E26-STDs!$F$13)/STDs!$E$13))*STDs!$I$13) -> 0.0053866367 | Q26: =(((E26-STDs!$F$13)/STDs!$E$13)*STDs!$J$14)+((1-((E26-STDs!$F$13)/STDs!$E$13))*STDs!$J$13) -> 0.00037997454 | R26: =N26-P26 -> 0.044142938 | S26: =(O26^2+Q26^2)^0.5 -> 0.0006690419 | T26: =R26+T25 -> 5.1960116 | U26: =(S26^2+U25^2)^0.5 -> 0.030851449 | V26: =((E26-E25)*24*3600)-(5*60) -> 3255 | W26: =(0.000304*199000000000000000)*EXP(-(5580-680)/(1.987*(A26+273))) -> 1.959054e+10 | X26: =1-EXP(-W26*$W$1*$F$1*(A26+273)*V26) -> 0.0063597936 | Y26: =R26/(X26) -> 6.9409387 | Z26: =(((S26/R26)*Y26)^2+(Y26*0.1)^2)^0.5 -> 0.7020207 | AA26: =AA27+R26 -> 6.9787795 | AB26: =(S26^2+AB27^2)^0.5 -> 0.70417474 | AE26: =0.2*AA26/($D$89-T26) -> 0.0022793062
A27: 23.6 | B27: Diff Cell | C27: 15 | D27: 25C | E27: 45236.887 | F27: 857.73407 | G27: 7932.5061 | H27: 91.511554 | I27: =H27/G27 -> 0.011536273 | J27: 0.038191 | K27: 0.032791 | L27: =(((E27-STDs!$F$13)/STDs!$E$13)*STDs!$G$14)+((1-((E27-STDs!$F$13)/STDs!$E$13)))*STDs!$G$13 -> 3.2806306 | M27: =(((E27-STDs!$F$13)/STDs!$E$13)*STDs!$H$14)+((1-((E27-STDs!$F$13)/STDs!$E$13))*STDs!$H$13) -> 0.037161369 | N27: =I27*L27 -> 0.03784625 | O27: =(M27/L27)*N27 -> 0.00042870369 | P27: =(((E27-STDs!$F$13)/STDs!$E$13)*STDs!$I$14)+((1-((E27-STDs!$F$13)/STDs!$E$13))*STDs!$I$13) -> 0.0053862037 | Q27: =(((E27-STDs!$F$13)/STDs!$E$13)*STDs!$J$14)+((1-((E27-STDs!$F$13)/STDs!$E$13))*STDs!$J$13) -> 0.00037974657 | R27: =N27-P27 -> 0.032460046 | S27: =(O27^2+Q27^2)^0.5 -> 0.00057270788 | T27: =R27+T26 -> 5.2284716 | U27: =(S27^2+U26^2)^0.5 -> 0.030856764 | V27: =((E27-E26)*24*3600)-(5*60) -> 3274 | W27: =(0.000304*199000000000000000)*EXP(-(5580-680)/(1.987*(A27+273))) -> 1.4820423e+10 | X27: =1-EXP(-W27*$W$1*$F$1*(A27+273)*V27) -> 0.0046808576 | Y27: =R27/(X27) -> 6.9346365 | Z27: =(((S27/R27)*Y27)^2+(Y27*0.1)^2)^0.5 -> 0.70417443 | AA27: =Y27 -> 6.9346365 | AB27: =Z27 -> 0.70417443 | AE27: =0.2*AA27/($D$89-T27) -> 0.0022650089
A28: 290.3 | B28: Diff Cell | C28: 60 | D28: 290C | E28: 45236.96 | F28: 839.17258 | G28: 8018.0565 | H28: 12186.427 | I28: =H28/G28 -> 1.5198729 | J28: 5.032202 | K28: 5.026802 | L28: =(((E28-STDs!$F$13)/STDs!$E$13)*STDs!$G$14)+((1-((E28-STDs!$F$13)/STDs!$E$13)))*STDs!$G$13 -> 3.2793819 | M28: =(((E28-STDs!$F$13)/STDs!$E$13)*STDs!$H$14)+((1-((E28-STDs!$F$13)/STDs!$E$13))*STDs!$H$13) -> 0.038363743 | N28: =I28*L28 -> 4.9842436 | O28: =(M28/L28)*N28 -> 0.058308014 | P28: =(((E28-STDs!$F$13)/STDs!$E$13)*STDs!$I$14)+((1-((E28-STDs!$F$13)/STDs!$E$13))*STDs!$I$13) -> 0.0053854375 | Q28: =(((E28-STDs!$F$13)/STDs!$E$13)*STDs!$J$14)+((1-((E28-STDs!$F$13)/STDs!$E$13))*STDs!$J$13) -> 0.0003793432 | R28: =N28-P28 -> 4.9788581 | S28: =(O28^2+Q28^2)^0.5 -> 0.058309248 | T28: =R28+T27 -> 10.20733 | U28: =(S28^2+U27^2)^0.5 -> 0.065970511 | V28: =((E28-E27)*24*3600)-(5*60) -> 6024 | W28: =(0.000304*199000000000000000)*EXP(-(5580-680)/(1.987*(A28+273))) -> 7.5938347e+11 | AA28: =AA27-R27 -> 6.9021765 | AB28: =(AB27^2+S27^2)^0.5 -> 0.70417466 | AC28: =R28+AA29-AA28 -> 8.9926264 | AD28: =(S28^2+AB28^2+AB29^2)^0.5 -> 1.305291 | AE28: =0.2*AA28/($D$89-T28) -> 0.0022728877
A29: 33.6 | B29: Diff Cell | C29: 15 | D29: 25C | E29: 45237.001 | F29: 849.53464 | G29: 7918.6852 | H29: 177.63532 | I29: =H29/G29 -> 0.022432426 | J29: 0.074267 | K29: 0.068867 | L29: =(((E29-STDs!$F$13)/STDs!$E$13)*STDs!$G$14)+((1-((E29-STDs!$F$13)/STDs!$E$13)))*STDs!$G$13 -> 3.2786804 | M29: =(((E29-STDs!$F$13)/STDs!$E$13)*STDs!$H$14)+((1-((E29-STDs!$F$13)/STDs!$E$13))*STDs!$H$13) -> 0.039039081 | N29: =I29*L29 -> 0.073548757 | O29: =(M29/L29)*N29 -> 0.00087574131 | P29: =(((E29-STDs!$F$13)/STDs!$E$13)*STDs!$I$14)+((1-((E29-STDs!$F$13)/STDs!$E$13))*STDs!$I$13) -> 0.0053850071 | Q29: =(((E29-STDs!$F$13)/STDs!$E$13)*STDs!$J$14)+((1-((E29-STDs!$F$13)/STDs!$E$13))*STDs!$J$13) -> 0.00037911663 | R29: =N29-P29 -> 0.06816375 | S29: =(O29^2+Q29^2)^0.5 -> 0.00095428102 | T29: =R29+T28 -> 10.275493 | U29: =(S29^2+U28^2)^0.5 -> 0.065977412 | V29: =((E29-E28)*24*3600)-(5*60) -> 3252 | W29: =(0.000304*199000000000000000)*EXP(-(5580-680)/(1.987*(A29+273))) -> 1.9437117e+10 | X29: =1-EXP(-W29*$W$1*$F$1*(A29+273)*V29) -> 0.0062982039 | Y29: =R29/(X29) -> 10.822728 | Z29: =(((S29/R29)*Y29)^2+(Y29*0.1)^2)^0.5 -> 1.0928274 | AA29: =AA30+R29 -> 10.915945 | AB29: =(S29^2+AB30^2)^0.5 -> 1.0975075 | AE29: =0.2*AA29/($D$89-T29) -> 0.0035950256
A30: 23.6 | B30: Diff Cell | C30: 15 | D30: 25C | E30: 45237.043 | F30: 842.61916 | G30: 7935.7331 | H30: 135.2884 | I30: =H30/G30 -> 0.017048002 | J30: 0.05644 | K30: 0.05104 | L30: =(((E30-STDs!$F$13)/STDs!$E$13)*STDs!$G$14)+((1-((E30-STDs!$F$13)/STDs!$E$13)))*STDs!$G$13 -> 3.2779782 | M30: =(((E30-STDs!$F$13)/STDs!$E$13)*STDs!$H$14)+((1-((E30-STDs!$F$13)/STDs!$E$13))*STDs!$H$13) -> 0.039715179 | N30: =I30*L30 -> 0.055882981 | O30: =(M30/L30)*N30 -> 0.00067706447 | P30: =(((E30-STDs!$F$13)/STDs!$E$13)*STDs!$I$14)+((1-((E30-STDs!$F$13)/STDs!$E$13))*STDs!$I$13) -> 0.0053845763 | Q30: =(((E30-STDs!$F$13)/STDs!$E$13)*STDs!$J$14)+((1-((E30-STDs!$F$13)/STDs!$E$13))*STDs!$J$13) -> 0.00037888981 | R30: =N30-P30 -> 0.050498404 | S30: =(O30^2+Q30^2)^0.5 -> 0.0007758697 | T30: =R30+T29 -> 10.325992 | U30: =(S30^2+U29^2)^0.5 -> 0.065981974 | V30: =((E30-E29)*24*3600)-(5*60) -> 3256 | W30: =(0.000304*199000000000000000)*EXP(-(5580-680)/(1.987*(A30+273))) -> 1.4820423e+10 | X30: =1-EXP(-W30*$W$1*$F$1*(A30+273)*V30) -> 0.0046551829 | Y30: =R30/(X30) -> 10.847781 | Z30: =(((S30/R30)*Y30)^2+(Y30*0.1)^2)^0.5 -> 1.097507 | AA30: =Y30 -> 10.847781 | AB30: =Z30 -> 1.097507 | AE30: =0.2*AA30/($D$89-T30) -> 0.0035728738
A31: 300.3 | B31: Diff Cell | C31: 60 | D31: 300C | E31: 45237.116 | F31: 822.72521 | G31: 8049.6073 | H31: 17805.235 | I31: =H31/G31 -> 2.2119383 | J31: 7.323607 | K31: 7.318207 | L31: =(((E31-STDs!$F$13)/STDs!$E$13)*STDs!$G$14)+((1-((E31-STDs!$F$13)/STDs!$E$13)))*STDs!$G$13 -> 3.276731 | M31: =(((E31-STDs!$F$13)/STDs!$E$13)*STDs!$H$14)+((1-((E31-STDs!$F$13)/STDs!$E$13))*STDs!$H$13) -> 0.040916033 | N31: =I31*L31 -> 7.247927 | O31: =(M31/L31)*N31 -> 0.090503742 | P31: =(((E31-STDs!$F$13)/STDs!$E$13)*STDs!$I$14)+((1-((E31-STDs!$F$13)/STDs!$E$13))*STDs!$I$13) -> 0.0053838111 | Q31: =(((E31-STDs!$F$13)/STDs!$E$13)*STDs!$J$14)+((1-((E31-STDs!$F$13)/STDs!$E$13))*STDs!$J$13) -> 0.00037848694 | R31: =N31-P31 -> 7.2425431 | S31: =(O31^2+Q31^2)^0.5 -> 0.090504533 | T31: =R31+T30 -> 17.568535 | U31: =(S31^2+U30^2)^0.5 -> 0.11200309 | V31: =((E31-E30)*24*3600)-(5*60) -> 6016 | W31: =(0.000304*199000000000000000)*EXP(-(5580-680)/(1.987*(A31+273))) -> 8.1964288e+11 | AA31: =AA30-R30 -> 10.797283 | AB31: =(AB30^2+S30^2)^0.5 -> 1.0975073 | AC31: =R31+AA32-AA31 -> 9.508228 | AD31: =(S31^2+AB31^2+AB32^2)^0.5 -> 1.7092683 | AE31: =0.2*AA31/($D$89-T31) -> 0.0035991694
A32: 34.2 | B32: Diff Cell | C32: 15 | D32: 25C | E32: 45237.157 | F32: 822.32302 | G32: 7934.5987 | H32: 217.31538 | I32: =H32/G32 -> 0.027388327 | J32: 0.090673 | K32: 0.085273 | L32: =(((E32-STDs!$F$13)/STDs!$E$13)*STDs!$G$14)+((1-((E32-STDs!$F$13)/STDs!$E$13)))*STDs!$G$13 -> 3.2760302 | M32: =(((E32-STDs!$F$13)/STDs!$E$13)*STDs!$H$14)+((1-((E32-STDs!$F$13)/STDs!$E$13))*STDs!$H$13) -> 0.0415908 | N32: =I32*L32 -> 0.089724987 | O32: =(M32/L32)*N32 -> 0.0011391024 | P32: =(((E32-STDs!$F$13)/STDs!$E$13)*STDs!$I$14)+((1-((E32-STDs!$F$13)/STDs!$E$13))*STDs!$I$13) -> 0.0053833811 | Q32: =(((E32-STDs!$F$13)/STDs!$E$13)*STDs!$J$14)+((1-((E32-STDs!$F$13)/STDs!$E$13))*STDs!$J$13) -> 0.00037826057 | R32: =N32-P32 -> 0.084341606 | S32: =(O32^2+Q32^2)^0.5 -> 0.0012002647 | T32: =R32+T31 -> 17.652877 | U32: =(S32^2+U31^2)^0.5 -> 0.11200952 | V32: =((E32-E31)*24*3600)-(5*60) -> 3249 | W32: =(0.000304*199000000000000000)*EXP(-(5580-680)/(1.987*(A32+273))) -> 1.9744871e+10 | X32: =1-EXP(-W32*$W$1*$F$1*(A32+273)*V32) -> 0.0064041908 | Y32: =R32/(X32) -> 13.169752 | Z32: =(((S32/R32)*Y32)^2+(Y32*0.1)^2)^0.5 -> 1.3302441 | AA32: =AA33+R32 -> 13.062967 | AB32: =(S32^2+AB33^2)^0.5 -> 1.3072432 | AE32: =0.2*AA32/($D$89-T32) -> 0.0043550257
A33: 23.5 | B33: Diff Cell | C33: 15 | D33: 25C | E33: 45237.198 | F33: 813.62278 | G33: 7930.9229 | H33: 162.20303 | I33: =H33/G33 -> 0.020451974 | J33: 0.067711 | K33: 0.062311 | L33: =(((E33-STDs!$F$13)/STDs!$E$13)*STDs!$G$14)+((1-((E33-STDs!$F$13)/STDs!$E$13)))*STDs!$G$13 -> 3.275329 | M33: =(((E33-STDs!$F$13)/STDs!$E$13)*STDs!$H$14)+((1-((E33-STDs!$F$13)/STDs!$E$13))*STDs!$H$13) -> 0.042265948 | N33: =I33*L33 -> 0.066986945 | O33: =(M33/L33)*N33 -> 0.00086442208 | P33: =(((E33-STDs!$F$13)/STDs!$E$13)*STDs!$I$14)+((1-((E33-STDs!$F$13)/STDs!$E$13))*STDs!$I$13) -> 0.0053829509 | Q33: =(((E33-STDs!$F$13)/STDs!$E$13)*STDs!$J$14)+((1-((E33-STDs!$F$13)/STDs!$E$13))*STDs!$J$13) -> 0.00037803407 | R33: =N33-P33 -> 0.061603994 | S33: =(O33^2+Q33^2)^0.5 -> 0.00094346982 | T33: =R33+T32 -> 17.714481 | U33: =(S33^2+U32^2)^0.5 -> 0.11201349 | V33: =((E33-E32)*24*3600)-(5*60) -> 3251 | W33: =(0.000304*199000000000000000)*EXP(-(5580-680)/(1.987*(A33+273))) -> 1.4778923e+10 | X33: =1-EXP(-W33*$W$1*$F$1*(A33+273)*V33) -> 0.0046335064 | Y33: =R33/(X33) -> 13.295329 | Z33: =(((S33/R33)*Y33)^2+(Y33*0.1)^2)^0.5 -> 1.3450348 | AA33: =AA34+R33 -> 12.978626 | AB33: =(S33^2+AB34^2)^0.5 -> 1.3072426 | AE33: =0.2*AA33/($D$89-T33) -> 0.0043273516
A34: 24.1 | B34: Diff Cell | C34: 15 | D34: 25C | E34: 45237.239 | F34: 814.91559 | G34: 7953.0132 | H34: 161.14071 | I34: =H34/G34 -> 0.020261592 | J34: 0.06708 | K34: 0.06168 | L34: =(((E34-STDs!$F$13)/STDs!$E$13)*STDs!$G$14)+((1-((E34-STDs!$F$13)/STDs!$E$13)))*STDs!$G$13 -> 3.274628 | M34: =(((E34-STDs!$F$13)/STDs!$E$13)*STDs!$H$14)+((1-((E34-STDs!$F$13)/STDs!$E$13))*STDs!$H$13) -> 0.042940905 | N34: =I34*L34 -> 0.066349175 | O34: =(M34/L34)*N34 -> 0.00087005109 | P34: =(((E34-STDs!$F$13)/STDs!$E$13)*STDs!$I$14)+((1-((E34-STDs!$F$13)/STDs!$E$13))*STDs!$I$13) -> 0.0053825208 | Q34: =(((E34-STDs!$F$13)/STDs!$E$13)*STDs!$J$14)+((1-((E34-STDs!$F$13)/STDs!$E$13))*STDs!$J$13) -> 0.00037780763 | R34: =N34-P34 -> 0.060966654 | S34: =(O34^2+Q34^2)^0.5 -> 0.00094853967 | T34: =R34+T33 -> 17.775447 | U34: =(S34^2+U33^2)^0.5 -> 0.11201751 | V34: =((E34-E33)*24*3600)-(5*60) -> 3250 | W34: =(0.000304*199000000000000000)*EXP(-(5580-680)/(1.987*(A34+273))) -> 1.5029255e+10 | X34: =1-EXP(-W34*$W$1*$F$1*(A34+273)*V34) -> 0.0047198693 | Y34: =R34/(X34) -> 12.917022 | Z34: =(((S34/R34)*Y34)^2+(Y34*0.1)^2)^0.5 -> 1.3072423 | AA34: =Y34 -> 12.917022 | AB34: =Z34 -> 1.3072423 | AE34: =0.2*AA34/($D$89-T34) -> 0.0043072493
A35: 285.3 | B35: Diff Cell | C35: 60 | D35: 285C | E35: 45237.312 | F35: 764.29577 | G35: 8052.9038 | H35: 14575.307 | I35: =H35/G35 -> 1.8099443 | J35: 5.992601 | K35: 5.987201 | L35: =(((E35-STDs!$F$13)/STDs!$E$13)*STDs!$G$14)+((1-((E35-STDs!$F$13)/STDs!$E$13)))*STDs!$G$13 -> 3.2733806 | M35: =(((E35-STDs!$F$13)/STDs!$E$13)*STDs!$H$14)+((1-((E35-STDs!$F$13)/STDs!$E$13))*STDs!$H$13) -> 0.044141949 | N35: =I35*L35 -> 5.9246365 | O35: =(M35/L35)*N35 -> 0.079894468 | P35: =(((E35-STDs!$F$13)/STDs!$E$13)*STDs!$I$14)+((1-((E35-STDs!$F$13)/STDs!$E$13))*STDs!$I$13) -> 0.0053817555 | Q35: =(((E35-STDs!$F$13)/STDs!$E$13)*STDs!$J$14)+((1-((E35-STDs!$F$13)/STDs!$E$13))*STDs!$J$13) -> 0.0003774047 | R35: =N35-P35 -> 5.9192547 | S35: =(O35^2+Q35^2)^0.5 -> 0.07989536 | T35: =R35+T34 -> 23.694702 | U35: =(S35^2+U34^2)^0.5 -> 0.13759066 | V35: =((E35-E34)*24*3600)-(5*60) -> 6017 | W35: =(0.000304*199000000000000000)*EXP(-(5580-680)/(1.987*(A35+273))) -> 7.301866e+11 | AA35: =AA34-R34 -> 12.856055 | AB35: =(AB34^2+S34^2)^0.5 -> 1.3072426 | AC35: =R35+AA36-AA35 -> 3.5751129 | AD35: =(S35^2+AB35^2+AB36^2)^0.5 -> 1.6845151 | AE35: =0.2*AA35/($D$89-T35) -> 0.0043296491
A36: 36.8 | B36: Diff Cell | C36: 15 | D36: 25C | E36: 45237.353 | F36: 759.74502 | G36: 7974.2256 | H36: 190.74874 | I36: =H36/G36 -> 0.02392066 | J36: 0.079194 | K36: 0.073794 | L36: =(((E36-STDs!$F$13)/STDs!$E$13)*STDs!$G$14)+((1-((E36-STDs!$F$13)/STDs!$E$13)))*STDs!$G$13 -> 3.272681 | M36: =(((E36-STDs!$F$13)/STDs!$E$13)*STDs!$H$14)+((1-((E36-STDs!$F$13)/STDs!$E$13))*STDs!$H$13) -> 0.044815576 | N36: =I36*L36 -> 0.07828469 | O36: =(M36/L36)*N36 -> 0.0010720182 | P36: =(((E36-STDs!$F$13)/STDs!$E$13)*STDs!$I$14)+((1-((E36-STDs!$F$13)/STDs!$E$13))*STDs!$I$13) -> 0.0053813262 | Q36: =(((E36-STDs!$F$13)/STDs!$E$13)*STDs!$J$14)+((1-((E36-STDs!$F$13)/STDs!$E$13))*STDs!$J$13) -> 0.00037717871 | R36: =N36-P36 -> 0.072903363 | S36: =(O36^2+Q36^2)^0.5 -> 0.001136436 | T36: =R36+T35 -> 23.767605 | U36: =(S36^2+U35^2)^0.5 -> 0.13759536 | V36: =((E36-E35)*24*3600)-(5*60) -> 3243 | W36: =(0.000304*199000000000000000)*EXP(-(5580-680)/(1.987*(A36+273))) -> 2.1120922e+10 | X36: =1-EXP(-W36*$W$1*$F$1*(A36+273)*V36) -> 0.0068940324 | Y36: =R36/(X36) -> 10.574851 | Z36: =(((S36/R36)*Y36)^2+(Y36*0.1)^2)^0.5 -> 1.0702561 | AA36: =AA37+R36 -> 10.511913 | AB36: =(S36^2+AB37^2)^0.5 -> 1.0593981 | AE36: =0.2*AA36/($D$89-T36) -> 0.0035406261
A37: 23.6 | B37: Diff Cell | C37: 15 | D37: 25C | E37: 45237.394 | F37: 757.33902 | G37: 7970.4665 | H37: 131.15876 | I37: =H37/G37 -> 0.016455594 | J37: 0.054478 | K37: 0.049078 | L37: =(((E37-STDs!$F$13)/STDs!$E$13)*STDs!$G$14)+((1-((E37-STDs!$F$13)/STDs!$E$13)))*STDs!$G$13 -> 3.2719806 | M37: =(((E37-STDs!$F$13)/STDs!$E$13)*STDs!$H$14)+((1-((E37-STDs!$F$13)/STDs!$E$13))*STDs!$H$13) -> 0.045489963 | N37: =I37*L37 -> 0.053842385 | O37: =(M37/L37)*N37 -> 0.00074856438 | P37: =(((E37-STDs!$F$13)/STDs!$E$13)*STDs!$I$14)+((1-((E37-STDs!$F$13)/STDs!$E$13))*STDs!$I$13) -> 0.0053808965 | Q37: =(((E37-STDs!$F$13)/STDs!$E$13)*STDs!$J$14)+((1-((E37-STDs!$F$13)/STDs!$E$13))*STDs!$J$13) -> 0.00037695247 | R37: =N37-P37 -> 0.048461489 | S37: =(O37^2+Q37^2)^0.5 -> 0.00083811801 | T37: =R37+T36 -> 23.816067 | U37: =(S37^2+U36^2)^0.5 -> 0.13759791 | V37: =((E37-E36)*24*3600)-(5*60) -> 3247 | W37: =(0.000304*199000000000000000)*EXP(-(5580-680)/(1.987*(A37+273))) -> 1.4820423e+10 | X37: =1-EXP(-W37*$W$1*$F$1*(A37+273)*V37) -> 0.0046423453 | Y37: =R37/(X37) -> 10.43901 | Z37: =(((S37/R37)*Y37)^2+(Y37*0.1)^2)^0.5 -> 1.0593975 | AA37: =Y37 -> 10.43901 | AB37: =Z37 -> 1.0593975 | AE37: =0.2*AA37/($D$89-T37) -> 0.0035163577
A38: 275.2 | B38: Diff Cell | C38: 80 | D38: 275C | E38: 45237.481 | F38: 711.21129 | G38: 8000.6568 | H38: 13180.381 | I38: =H38/G38 -> 1.6474123 | J38: 5.287136 | K38: 5.281736 | L38: =(((E38-STDs!$F$13)/STDs!$E$13)*STDs!$G$14)+((1-((E38-STDs!$F$13)/STDs!$E$13)))*STDs!$G$13 -> 3.2704988 | M38: =(((E38-STDs!$F$13)/STDs!$E$13)*STDs!$H$14)+((1-((E38-STDs!$F$13)/STDs!$E$13))*STDs!$H$13) -> 0.04691669 | N38: =I38*L38 -> 5.38786 | O38: =(M38/L38)*N38 -> 0.077291134 | P38: =(((E38-STDs!$F$13)/STDs!$E$13)*STDs!$I$14)+((1-((E38-STDs!$F$13)/STDs!$E$13))*STDs!$I$13) -> 0.0053799873 | Q38: =(((E38-STDs!$F$13)/STDs!$E$13)*STDs!$J$14)+((1-((E38-STDs!$F$13)/STDs!$E$13))*STDs!$J$13) -> 0.00037647382 | R38: =N38-P38 -> 5.38248 | S38: =(O38^2+Q38^2)^0.5 -> 0.077292051 | T38: =R38+T37 -> 29.198547 | U38: =(S38^2+U37^2)^0.5 -> 0.15782029 | V38: =((E38-E37)*24*3600)-(5*60) -> 7204 | W38: =(0.000304*199000000000000000)*EXP(-(5580-680)/(1.987*(A38+273))) -> 6.7311825e+11 | AA38: =AA37-R37 -> 10.390548 | AB38: =(AB37^2+S37^2)^0.5 -> 1.0593979 | AC38: =R38+AA39-AA38 -> 2.5210172 | AD38: =(S38^2+AB38^2+AB39^2)^0.5 -> 1.3076851 | AE38: =0.2*AA38/($D$89-T38) -> 0.003532053
A39: 37 | B39: Diff Cell | C39: 15 | D39: 25C | E39: 45237.522 | F39: 712.23832 | G39: 7963.5705 | H39: 140.78925 | I39: =H39/G39 -> 0.017679161 | J39: 0.05853 | K39: 0.05313 | L39: =(((E39-STDs!$F$13)/STDs!$E$13)*STDs!$G$14)+((1-((E39-STDs!$F$13)/STDs!$E$13)))*STDs!$G$13 -> 3.2697981 | M39: =(((E39-STDs!$F$13)/STDs!$E$13)*STDs!$H$14)+((1-((E39-STDs!$F$13)/STDs!$E$13))*STDs!$H$13) -> 0.047591267 | N39: =I39*L39 -> 0.057807289 | O39: =(M39/L39)*N39 -> 0.00084137368 | P39: =(((E39-STDs!$F$13)/STDs!$E$13)*STDs!$I$14)+((1-((E39-STDs!$F$13)/STDs!$E$13))*STDs!$I$13) -> 0.0053795575 | Q39: =(((E39-STDs!$F$13)/STDs!$E$13)*STDs!$J$14)+((1-((E39-STDs!$F$13)/STDs!$E$13))*STDs!$J$13) -> 0.00037624751 | R39: =N39-P39 -> 0.052427731 | S39: =(O39^2+Q39^2)^0.5 -> 0.00092166798 | T39: =R39+T38 -> 29.250975 | U39: =(S39^2+U38^2)^0.5 -> 0.15782299 | V39: =((E39-E38)*24*3600)-(5*60) -> 3248 | W39: =(0.000304*199000000000000000)*EXP(-(5580-680)/(1.987*(A39+273))) -> 2.1229668e+10 | X39: =1-EXP(-W39*$W$1*$F$1*(A39+273)*V39) -> 0.0069445159 | Y39: =R39/(X39) -> 7.5495156 | Z39: =(((S39/R39)*Y39)^2+(Y39*0.1)^2)^0.5 -> 0.76652863 | AA39: =AA40+R39 -> 7.5290856 | AB39: =(S39^2+AB40^2)^0.5 -> 0.76272036 | AE39: =0.2*AA39/($D$89-T39) -> 0.0025595857
A40: 23.6 | B40: Diff Cell | C40: 15 | D40: 25C | E40: 45237.563 | F40: 708.3918 | G40: 7950.8801 | H40: 97.889359 | I40: =H40/G40 -> 0.012311764 | J40: 0.04076 | K40: 0.03536 | L40: =(((E40-STDs!$F$13)/STDs!$E$13)*STDs!$G$14)+((1-((E40-STDs!$F$13)/STDs!$E$13)))*STDs!$G$13 -> 3.2690948 | M40: =(((E40-STDs!$F$13)/STDs!$E$13)*STDs!$H$14)+((1-((E40-STDs!$F$13)/STDs!$E$13))*STDs!$H$13) -> 0.048268506 | N40: =I40*L40 -> 0.040248323 | O40: =(M40/L40)*N40 -> 0.00059427045 | P40: =(((E40-STDs!$F$13)/STDs!$E$13)*STDs!$I$14)+((1-((E40-STDs!$F$13)/STDs!$E$13))*STDs!$I$13) -> 0.0053791259 | Q40: =(((E40-STDs!$F$13)/STDs!$E$13)*STDs!$J$14)+((1-((E40-STDs!$F$13)/STDs!$E$13))*STDs!$J$13) -> 0.00037602031 | R40: =N40-P40 -> 0.034869197 | S40: =(O40^2+Q40^2)^0.5 -> 0.00070324153 | T40: =R40+T39 -> 29.285844 | U40: =(S40^2+U39^2)^0.5 -> 0.15782455 | V40: =((E40-E39)*24*3600)-(5*60) -> 3262 | W40: =(0.000304*199000000000000000)*EXP(-(5580-680)/(1.987*(A40+273))) -> 1.4820423e+10 | X40: =1-EXP(-W40*$W$1*$F$1*(A40+273)*V40) -> 0.0046637412 | Y40: =R40/(X40) -> 7.4766579 | Z40: =(((S40/R40)*Y40)^2+(Y40*0.1)^2)^0.5 -> 0.7627198 | AA40: =Y40 -> 7.4766579 | AB40: =Z40 -> 0.7627198 | AE40: =0.2*AA40/($D$89-T40) -> 0.002541913
...

Sheet Diffusivities
A1: Corrected | C1: Measurements in grey have corrected yields within 2σ of 0 and are not plotted | G1: Σ 4He | H1: 2σ | I1: Fi+1 | J1: 2σ | L1: D<10% | M1: 2σ | N1: D<90% | O1: 2σ | P1: D>90% | Q1: 2σ | R1: D/a^2 | S1: 2σ | T1: 10000/TK | U1: ln(D/a^2) | V1: 2σ | W1: Log(D/a2) | X1: Regression Reference ln(D/a2) | Y1: Delta Regression | AA1: Derivatives for Error Propagation (signs don't matter, terms are squared)
L2: EQ1 | N2: EQ2 | P2: EQ3 | AA2: dEQ1/dF | AB2: dEQ2/dF | AC2: dEQ3/dF
A3: Step | B3: Temp © | C3: Minutes | D3: 4He Corrected (nccSTP) | F3: Seconds | G3: 0 | H3: 0 | I3: 0 | J3: 0 | AA3: 0 | AB3: 0 | AC3: 0
A4: 1 | B4: 100 | C4: 240 | D4: {='Raw Data and Corrections'!AC9:AD9} -> 0.049585314 | E4: 0.23714865 | F4: =60*C4 -> 14400 | G4: =D4+G3 -> 0.049585314 | H4: =E4+H36 -> 0.23714865 | I4: =G4/$G$29 -> 8.0292822e-05 | J4: =2*(((H4/(2*$G$29))^2+($H$29*G4/(2*($G$29^2)))^2)^0.5) -> 0.00038401157 | L4: =((I4^2-I3^2)*PI())/(36*F4) -> 3.9069543e-14 | M4: =2*((((J4/2)*AA4)^2+((J3/2)*AA3)^2)^0.5) -> 3.7371102e-13 | N4: =(1/(PI()*PI()*F4))*(-(I4-I3)*PI()*PI()/3-2*PI()*(SQRT(1-PI()/3*I4)-SQRT(1-PI()/3*I3))) -> 3.9071183e-14 | O4: =2*((((J4/2)*AB4)^2+((J3/2)*AB3)^2)^0.5) -> 3.7373459e-13 | P4: =(1/(PI()^2*F4))*LN((1-I3)/(1-I4)) -> 5.649785e-10 | Q4: =2*((((J4/2)*AC4)^2+((J3/2)*AC3)^2)^0.5) -> 2.7021966e-09 | R4: =(I4<0.05)*L4+((I4>=0.05)*(I4<0.9))*N4+(I4>=0.9)*P4 -> 3.9069543e-14 | S4: =(I4<0.05)*M4+((I4>=0.05)*(I4<0.9))*O4+(I4>=0.9)*Q4 -> 3.7371102e-13 | T4: =10000/(273+B4) -> 26.809651 | U4: =LN(R4) -> -30.873433 | V4: =S4/R4 -> 9.5652776 | W4: =LOG10(R4) -> -13.408162 | X4: =LN(((10^1.5)/(0.015^2))*EXP(-33000/(1.987*(273+B4)))) -> -32.672052 | Y4: =U4-X4 -> 1.7986187 | AA4: =(I4 * PI()) / (18 * F4) -> 9.7317647e-10 | AB4: =(1 / (PI()^2 * F4)) * (PI()^2 / 3 - PI()^2 / (3 * SQRT(1 - (PI() / 3) * I4))) -> -9.7323784e-10 | AC4: =(-1) / (PI()^2 * F4 * (1 - I4)) -> -7.0367583e-06
A5: 2 | B5: 150 | C5: 240 | D5: {='Raw Data and Corrections'!AC13:AD13} -> 0.011125653 | E5: 0.20543141 | F5: =60*C5 -> 14400 | G5: =D5+G4 -> 0.060710967 | H5: =E5+H37 -> 0.20669812 | I5: =G5/$G$29 -> 9.830844e-05 | J5: =2*(((H5/(2*$G$29))^2+($H$29*G5/(2*($G$29^2)))^2)^0.5) -> 0.00033470345 | L5: =((I5^2-I4^2)*PI())/(36*F5) -> 1.9499279e-14 | M5: =2*((((J5/2)*AA5)^2+((J4/2)*AA4)^2)^0.5) -> 5.4654297e-13 | N5: =(1/(PI()*PI()*F5))*(-(I5-I4)*PI()*PI()/3-2*PI()*(SQRT(1-PI()/3*I5)-SQRT(1-PI()/3*I4))) -> 1.9500656e-14 | O5: =2*((((J5/2)*AB5)^2+((J4/2)*AB4)^2)^0.5) -> 5.4658156e-13 | P5: =(1/(PI()^2*F5))*LN((1-I4)/(1-I5)) -> 1.2677269e-10 | Q5: =2*((((J5/2)*AC5)^2+((J4/2)*AC4)^2)^0.5) -> 3.5845727e-09 | R5: =(I5<0.05)*L5+((I5>=0.05)*(I5<0.9))*N5+(I5>=0.9)*P5 -> 1.9499279e-14 | S5: =(I5<0.05)*M5+((I5>=0.05)*(I5<0.9))*O5+(I5>=0.9)*Q5 -> 5.4654297e-13 | T5: =10000/(273+B5) -> 23.640662 | U5: =LN(R5) -> -31.568399 | V5: =S5/R5 -> 28.028881 | W5: =LOG10(R5) -> -13.709981 | X5: =LN(((10^1.5)/(0.015^2))*EXP(-33000/(1.987*(273+B5)))) -> -27.409009 | Y5: =U5-X5 -> -4.1593896 | AA5: =(I5 * PI()) / (18 * F5) -> 1.1915319e-09 | AB5: =(1 / (PI()^2 * F5)) * (PI()^2 / 3 - PI()^2 / (3 * SQRT(1 - (PI() / 3) * I5))) -> -1.1916239e-09 | AC5: =(-1) / (PI()^2 * F5 * (1 - I5)) -> -7.0368851e-06
A6: 3 | B6: 200.1 | C6: 240 | D6: {='Raw Data and Corrections'!AC17:AD17} -> 1.6418389 | E6: 0.2316491 | F6: =60*C6 -> 14400 | G6: =D6+G5 -> 1.7025499 | H6: =E6+H38 -> 0.23438468 | I6: =G6/$G$29 -> 0.0027569157 | J6: =2*(((H6/(2*$G$29))^2+($H$29*G6/(2*($G$29^2)))^2)^0.5) -> 0.00037953591 | L6: =((I6^2-I5^2)*PI())/(36*F6) -> 4.6002273e-11 | M6: =2*((((J6/2)*AA6)^2+((J5/2)*AA5)^2)^0.5) -> 1.2688371e-11 | N6: =(1/(PI()*PI()*F6))*(-(I6-I5)*PI()*PI()/3-2*PI()*(SQRT(1-PI()/3*I6)-SQRT(1-PI()/3*I5))) -> 4.6068879e-11 | O6: =2*((((J6/2)*AB6)^2+((J5/2)*AB5)^2)^0.5) -> 1.2715885e-11 | P6: =(1/(PI()^2*F6))*LN((1-I5)/(1-I6)) -> 1.873323e-08 | Q6: =2*((((J6/2)*AC6)^2+((J5/2)*AC5)^2)^0.5) -> 3.5662708e-09 | R6: =(I6<0.05)*L6+((I6>=0.05)*(I6<0.9))*N6+(I6>=0.9)*P6 -> 4.6002273e-11 | S6: =(I6<0.05)*M6+((I6>=0.05)*(I6<0.9))*O6+(I6>=0.9)*Q6 -> 1.2688371e-11 | T6: =10000/(273+B6) -> 21.13718 | U6: =LN(R6) -> -23.80233 | V6: =S6/R6 -> 0.27582053 | W6: =LOG10(R6) -> -10.337221 | X6: =LN(((10^1.5)/(0.015^2))*EXP(-33000/(1.987*(273+B6)))) -> -23.251239 | Y6: =U6-X6 -> -0.55109119 | AA6: =(I6 * PI()) / (18 * F6) -> 3.3414762e-08 | AB6: =(1 / (PI()^2 * F6)) * (PI()^2 / 3 - PI()^2 / (3 * SQRT(1 - (PI() / 3) * I6))) -> -3.3487288e-08 | AC6: =(-1) / (PI()^2 * F6 * (1 - I6)) -> -7.0556451e-06
A7: 4 | B7: 250.2 | C7: 60 | D7: {='Raw Data and Corrections'!AC21:AD21} -> 3.6974788 | E7: 0.47601417 | F7: =60*C7 -> 3600 | G7: =D7+G6 -> 5.4000287 | H7: =E7+H39 -> 0.48492735 | I7: =G7/$G$29 -> 0.0087441927 | J7: =2*(((H7/(2*$G$29))^2+($H$29*G7/(2*($G$29^2)))^2)^0.5) -> 0.00078523624 | L7: =((I7^2-I6^2)*PI())/(36*F7) -> 1.6692213e-09 | M7: =2*((((J7/2)*AA7)^2+((J6/2)*AA6)^2)^0.5) -> 3.3312703e-10 | N7: =(1/(PI()*PI()*F7))*(-(I7-I6)*PI()*PI()/3-2*PI()*(SQRT(1-PI()/3*I7)-SQRT(1-PI()/3*I6))) -> 1.6774897e-09 | O7: =2*((((J7/2)*AB7)^2+((J6/2)*AB6)^2)^0.5) -> 3.3543014e-10 | P7: =(1/(PI()^2*F7))*LN((1-I6)/(1-I7)) -> 1.694857e-07 | Q7: =2*((((J7/2)*AC7)^2+((J6/2)*AC6)^2)^0.5) -> 2.2455493e-08 | R7: =(I7<0.05)*L7+((I7>=0.05)*(I7<0.9))*N7+(I7>=0.9)*P7 -> 1.6692213e-09 | S7: =(I7<0.05)*M7+((I7>=0.05)*(I7<0.9))*O7+(I7>=0.9)*Q7 -> 3.3312703e-10 | T7: =10000/(273+B7) -> 19.11315 | U7: =LN(R7) -> -20.210909 | V7: =S7/R7 -> 0.19957032 | W7: =LOG10(R7) -> -8.7774861 | X7: =LN(((10^1.5)/(0.015^2))*EXP(-33000/(1.987*(273+B7)))) -> -19.889739 | Y7: =U7-X7 -> -0.32116948 | AA7: =(I7 * PI()) / (18 * F7) -> 4.2393043e-07 | AB7: =(1 / (PI()^2 * F7)) * (PI()^2 / 3 - PI()^2 / (3 * SQRT(1 - (PI() / 3) * I7))) -> -4.2686424e-07 | AC7: =(-1) / (PI()^2 * F7 * (1 - I7)) -> -2.8393048e-05
A8: 5 | B8: 270.3 | C8: 60 | D8: {='Raw Data and Corrections'!AC25:AD25} -> 5.2581583 | E8: 0.82875713 | F8: =60*C8 -> 3600 | G8: =D8+G7 -> 10.658187 | H8: =E8+H40 -> 0.84288309 | I8: =G8/$G$29 -> 0.017258657 | J8: =2*(((H8/(2*$G$29))^2+($H$29*G8/(2*($G$29^2)))^2)^0.5) -> 0.0013648691 | L8: =((I8^2-I7^2)*PI())/(36*F8) -> 5.3668953e-09 | M8: =2*((((J8/2)*AA8)^2+((J7/2)*AA7)^2)^0.5) -> 1.189545e-09 | N8: =(1/(PI()*PI()*F8))*(-(I8-I7)*PI()*PI()/3-2*PI()*(SQRT(1-PI()/3*I8)-SQRT(1-PI()/3*I7))) -> 5.4243545e-09 | O8: =2*((((J8/2)*AB8)^2+((J7/2)*AB7)^2)^0.5) -> 1.2052806e-09 | P8: =(1/(PI()^2*F8))*LN((1-I7)/(1-I8)) -> 2.4279584e-07 | Q8: =2*((((J8/2)*AC8)^2+((J7/2)*AC7)^2)^0.5) -> 4.4999918e-08 | R8: =(I8<0.05)*L8+((I8>=0.05)*(I8<0.9))*N8+(I8>=0.9)*P8 -> 5.3668953e-09 | S8: =(I8<0.05)*M8+((I8>=0.05)*(I8<0.9))*O8+(I8>=0.9)*Q8 -> 1.189545e-09 | T8: =10000/(273+B8) -> 18.406037 | U8: =LN(R8) -> -19.043016 | V8: =S8/R8 -> 0.2216449 | W8: =LOG10(R8) -> -8.2702769 | X8: =LN(((10^1.5)/(0.015^2))*EXP(-33000/(1.987*(273+B8)))) -> -18.71537 | Y8: =U8-X8 -> -0.32764642 | AA8: =(I8 * PI()) / (18 * F8) -> 8.3672329e-07 | AB8: =(1 / (PI()^2 * F8)) * (PI()^2 / 3 - PI()^2 / (3 * SQRT(1 - (PI() / 3) * I8))) -> -8.4823857e-07 | AC8: =(-1) / (PI()^2 * F8 * (1 - I8)) -> -2.8639045e-05
A9: 6 | B9: 290.3 | C9: 60 | D9: {='Raw Data and Corrections'!AC28:AD28} -> 8.9926264 | E9: 1.305291 | F9: =60*C9 -> 3600 | G9: =D9+G8 -> 19.650813 | H9: =E9+H41 -> 1.3361477 | I9: =G9/$G$29 -> 0.031820294 | J9: =2*(((H9/(2*$G$29))^2+($H$29*G9/(2*($G$29^2)))^2)^0.5) -> 0.0021636058 | L9: =((I9^2-I8^2)*PI())/(36*F9) -> 1.7324086e-08 | M9: =2*((((J9/2)*AA9)^2+((J8/2)*AA8)^2)^0.5) -> 3.5277405e-09 | N9: =(1/(PI()*PI()*F9))*(-(I9-I8)*PI()*PI()/3-2*PI()*(SQRT(1-PI()/3*I9)-SQRT(1-PI()/3*I8))) -> 1.7675749e-08 | O9: =2*((((J9/2)*AB9)^2+((J8/2)*AB8)^2)^0.5) -> 3.6140335e-09 | P9: =(1/(PI()^2*F9))*LN((1-I8)/(1-I9)) -> 4.2015189e-07 | Q9: =2*((((J9/2)*AC9)^2+((J8/2)*AC8)^2)^0.5) -> 7.4052445e-08 | R9: =(I9<0.05)*L9+((I9>=0.05)*(I9<0.9))*N9+(I9>=0.9)*P9 -> 1.7324086e-08 | S9: =(I9<0.05)*M9+((I9>=0.05)*(I9<0.9))*O9+(I9>=0.9)*Q9 -> 3.5277405e-09 | T9: =10000/(273+B9) -> 17.75253 | U9: =LN(R9) -> -17.871168 | V9: =S9/R9 -> 0.20363213 | W9: =LOG10(R9) -> -7.7613497 | X9: =LN(((10^1.5)/(0.015^2))*EXP(-33000/(1.987*(273+B9)))) -> -17.630028 | Y9: =U9-X9 -> -0.24114021 | AA9: =(I9 * PI()) / (18 * F9) -> 1.5426914e-06 | AB9: =(1 / (PI()^2 * F9)) * (PI()^2 / 3 - PI()^2 / (3 * SQRT(1 - (PI() / 3) * I9))) -> -1.5823485e-06 | AC9: =(-1) / (PI()^2 * F9 * (1 - I9)) -> -2.9069782e-05
A10: 7 | B10: 300.3 | C10: 60 | D10: {='Raw Data and Corrections'!AC31:AD31} -> 9.508228 | E10: 1.7092683 | F10: =60*C10 -> 3600 | G10: =D10+G9 -> 29.159041 | H10: =E10+H42 -> 1.7752503 | I10: =G10/$G$29 -> 0.047216838 | J10: =2*(((H10/(2*$G$29))^2+($H$29*G10/(2*($G$29^2)))^2)^0.5) -> 0.0028746385 | L10: =((I10^2-I9^2)*PI())/(36*F10) -> 2.9498456e-08 | M10: =2*((((J10/2)*AA10)^2+((J9/2)*AA9)^2)^0.5) -> 7.3785469e-09 | N10: =(1/(PI()*PI()*F10))*(-(I10-I9)*PI()*PI()/3-2*PI()*(SQRT(1-PI()/3*I10)-SQRT(1-PI()/3*I9))) -> 3.0459658e-08 | O10: =2*((((J10/2)*AB10)^2+((J9/2)*AB9)^2)^0.5) -> 7.6444653e-09 | P10: =(1/(PI()^2*F10))*LN((1-I9)/(1-I10)) -> 4.5117115e-07 | Q10: =2*((((J10/2)*AC10)^2+((J9/2)*AC9)^2)^0.5) -> 1.0567162e-07 | R10: =(I10<0.05)*L10+((I10>=0.05)*(I10<0.9))*N10+(I10>=0.9)*P10 -> 2.9498456e-08 | S10: =(I10<0.05)*M10+((I10>=0.05)*(I10<0.9))*O10+(I10>=0.9)*Q10 -> 7.3785469e-09 | T10: =10000/(273+B10) -> 17.442875 | U10: =LN(R10) -> -17.338928 | V10: =S10/R10 -> 0.25013333 | W10: =LOG10(R10) -> -7.5302007 | X10: =LN(((10^1.5)/(0.015^2))*EXP(-33000/(1.987*(273+B10)))) -> -17.115754 | Y10: =U10-X10 -> -0.22317387 | AA10: =(I10 * PI()) / (18 * F10) -> 2.2891369e-06 | AB10: =(1 / (PI()^2 * F10)) * (PI()^2 / 3 - PI()^2 / (3 * SQRT(1 - (PI() / 3) * I10))) -> -2.3776835e-06 | AC10: =(-1) / (PI()^2 * F10 * (1 - I10)) -> -2.9539537e-05
A11: 8 | B11: 285.3 | C11: 60 | D11: {='Raw Data and Corrections'!AC35:AD35} -> 3.5751129 | E11: 1.6845151 | F11: =60*C11 -> 3600 | G11: =D11+G10 -> 32.734154 | H11: =E11+H43 -> 1.7965326 | I11: =G11/$G$29 -> 0.053005969 | J11: =2*(((H11/(2*$G$29))^2+($H$29*G11/(2*($G$29^2)))^2)^0.5) -> 0.0029091007 | L11: =((I11^2-I10^2)*PI())/(36*F11) -> 1.4064518e-08 | M11: =2*((((J11/2)*AA11)^2+((J10/2)*AA10)^2)^0.5) -> 9.9594165e-09 | N11: =(1/(PI()*PI()*F11))*(-(I11-I10)*PI()*PI()/3-2*PI()*(SQRT(1-PI()/3*I11)-SQRT(1-PI()/3*I10))) -> 1.4644138e-08 | O11: =2*((((J11/2)*AB11)^2+((J10/2)*AB10)^2)^0.5) -> 1.0372598e-08 | P11: =(1/(PI()^2*F11))*LN((1-I10)/(1-I11)) -> 1.715299e-07 | Q11: =2*((((J11/2)*AC11)^2+((J10/2)*AC10)^2)^0.5) -> 1.2118485e-07 | R11: =(I11<0.05)*L11+((I11>=0.05)*(I11<0.9))*N11+(I11>=0.9)*P11 -> 1.4644138e-08 | S11: =(I11<0.05)*M11+((I11>=0.05)*(I11<0.9))*O11+(I11>=0.9)*Q11 -> 1.0372598e-08 | T11: =10000/(273+B11) -> 17.911517 | U11: =LN(R11) -> -18.039226 | V11: =S11/R11 -> 0.70831059 | W11: =LOG10(R11) -> -7.8343362 | X11: =LN(((10^1.5)/(0.015^2))*EXP(-33000/(1.987*(273+B11)))) -> -17.894073 | Y11: =U11-X11 -> -0.14515242 | AA11: =(I11 * PI()) / (18 * F11) -> 2.5698019e-06 | AB11: =(1 / (PI()^2 * F11)) * (PI()^2 / 3 - PI()^2 / (3 * SQRT(1 - (PI() / 3) * I11))) -> -2.6819864e-06 | AC11: =(-1) / (PI()^2 * F11 * (1 - I11)) -> -2.9720117e-05
