Workbook

Sheet DistilledBoundingMethod
A1: Temp © | B1: Minutes | D1: 3He Measured (pccSTP) | E1: Σ 3He (pccSTP) | F1: ntUB 3He (pccSTP) | G1: 3He ωLB (pccSTP) | H1: 3He ωUB (pccSTP) | I1: 3He ln(d/a^2)LB | J1: 3He ln(d/a^2)m | K1: 3He ln(d/a^2)UB | M1: 4He Measured (nccSTP) | N1: Σ 4He (nccSTP) | O1: ntUB 4He (nccSTP) | P1: 4He ωLB (nccSTP) | Q1: 4He ωUB (nccSTP) | R1: 4He ln(d/a^2)LB | S1: 4He ln(d/a^2)m | T1: 4He ln(d/a^2)UB | U1: F 3He | V1: 4/3 HeLB / 4/3 bulk | W1: 4/3 Hem / 4/3 bulk | X1: 4/3HeUB / 4/3 bulk
A2: 170 | B2: 300 | D2: ='Raw Data and Corrections'!Q5 -> 0.96295642 | E2: ='Raw Data and Corrections'!AG8 -> 1.0799346 | F2: -- | G2: -- | H2: -- | I2: -- | J2: -- | K2: -- | M2: ='Raw Data and Corrections'!S5 -> 0.019201958 | N2: ='Raw Data and Corrections'!AI8 -> 0.035498608 | O2: -- | P2: -- | Q2: -- | R2: -- | S2: -- | T2: -- | W2: ='Raw Data and Corrections'!BR5 -> 0.019747132
A3: 180 | B3: 463 | D3: ='Raw Data and Corrections'!Q9 -> 0.54418415 | E3: ='Raw Data and Corrections'!AG12 -> 1.6820294 | F3: -- | G3: -- | H3: -- | I3: -- | J3: -- | K3: -- | M3: ='Raw Data and Corrections'!S9 -> 0.030467213 | N3: ='Raw Data and Corrections'!AI12 -> 0.081744338 | O3: -- | P3: -- | Q3: -- | R3: -- | S3: -- | T3: -- | W3: ='Raw Data and Corrections'!BR9 -> 0.055443672
A4: 190 | B4: 550 | D4: ='Raw Data and Corrections'!Q13 -> 0.52920164 | E4: ='Raw Data and Corrections'!AG16 -> 2.2456606 | F4: ='Raw Data and Corrections'!BB13 -> 0.14264191 | G4: -- | H4: -- | I4: -- | J4: -- | K4: -- | M4: ='Raw Data and Corrections'!S13 -> 0.055770492 | N4: ='Raw Data and Corrections'!AI16 -> 0.14754099 | O4: ='Raw Data and Corrections'!BE13 -> 0.016987916 | P4: -- | Q4: -- | R4: -- | S4: -- | T4: -- | W4: ='Raw Data and Corrections'!BR13 -> 0.10436345
A5: 200 | B5: 500 | D5: ='Raw Data and Corrections'!Q17 -> 0.51895322 | E5: ='Raw Data and Corrections'!AG20 -> 2.802824 | F5: ='Raw Data and Corrections'!BB17 -> 0.1329938 | G5: =D5-F4 -> 0.37631132 | H5: =D5+F5 -> 0.65194703 | I5: {=diffusivitiesHTWin0601bLB!P7:P37} -> -21.950439 | J5: {=diffusivitiesHTWin0601bM!P7:P37} -> -21.682568 | K5: {=diffusivitiesHTWin0601bUB!P7:P37} -> -21.442505 | M5: ='Raw Data and Corrections'!S17 -> 0.10241379 | N5: ='Raw Data and Corrections'!AI20 -> 0.25955013 | O5: ='Raw Data and Corrections'!BE17 -> 0.029669814 | P5: =M5-O4 -> 0.085425877 | Q5: =M5+O5 -> 0.13208361 | R5: {=diffusivitiesHTWin0601bLB!P49:P79} -> -25.92825 | S5: {=diffusivitiesHTWin0601bM!P49:P79} -> -25.804652 | T5: {=diffusivitiesHTWin0601bUB!P49:P79} -> -25.49932 | U5: =(E4)/$E$36 -> 0.015367367 | W5: ='Raw Data and Corrections'!BR17 -> 0.19543187
A6: 210 | B6: 475 | D6: ='Raw Data and Corrections'!Q21 -> 0.57702821 | E6: ='Raw Data and Corrections'!AG24 -> 3.4217968 | F6: ='Raw Data and Corrections'!BB21 -> 0.13406376 | G6: =D6-F5 -> 0.44403441 | H6: =D6+F6 -> 0.71109197 | I6: -21.537403 | J6: -21.316647 | K6: -21.099286 | M6: ='Raw Data and Corrections'!S21 -> 0.1459873 | N6: ='Raw Data and Corrections'!AI24 -> 0.42289759 | O6: ='Raw Data and Corrections'!BE21 -> 0.038308281 | P6: =M6-O5 -> 0.11631749 | Q6: =M6+O6 -> 0.18429558 | R6: -25.017302 | S6: -24.859411 | T6: -24.594114 | U6: =(E5)/$E$36 -> 0.019180113 | V6: {='Raw Data and Corrections'!BQ21:BS21} -> 0.24633562 | W6: 0.25054352 | X6: 0.26532334
A7: 220 | B7: 450 | D7: ='Raw Data and Corrections'!Q25 -> 0.63333256 | E7: ='Raw Data and Corrections'!AG28 -> 4.0986663 | F7: ='Raw Data and Corrections'!BB25 -> 0.13488029 | G7: =D7-F6 -> 0.49926881 | H7: =D7+F7 -> 0.76821286 | I7: -21.187105 | J7: -20.984048 | K7: -20.784558 | M7: ='Raw Data and Corrections'!S25 -> 0.20905016 | N7: ='Raw Data and Corrections'!AI28 -> 0.6555735 | O7: ='Raw Data and Corrections'!BE25 -> 0.050257031 | P7: =M7-O6 -> 0.17074188 | Q7: =M7+O7 -> 0.2593072 | R7: -24.138954 | S7: -23.993963 | T7: -23.752853 | U7: =(E6)/$E$36 -> 0.02341583 | V7: {='Raw Data and Corrections'!BQ25:BS25} -> 0.32361175 | W7: 0.32687661 | X7: 0.34494014
A8: 230 | B8: 425 | D8: ='Raw Data and Corrections'!Q29 -> 0.78987805 | E8: ='Raw Data and Corrections'!AG32 -> 4.9329187 | F8: ='Raw Data and Corrections'!BB29 -> 0.15582339 | G8: =D8-F7 -> 0.65499776 | H8: =D8+F8 -> 0.94570144 | I8: -20.696261 | J8: -20.534732 | K8: -20.34638 | M8: ='Raw Data and Corrections'!S29 -> 0.32434102 | N8: ='Raw Data and Corrections'!AI32 -> 1.000444 | O8: ='Raw Data and Corrections'!BE29 -> 0.072209605 | P8: =M8-O7 -> 0.27408399 | Q8: =M8+O8 -> 0.39655063 | R8: -23.242019 | S8: -23.114411 | T8: -22.881621 | U8: =(E7)/$E$36 -> 0.028047742 | V8: {='Raw Data and Corrections'!BQ29:BS29} -> 0.40038942 | W8: 0.40663708 | X8: 0.42698914
A9: 225 | B9: 908 | D9: ='Raw Data and Corrections'!Q33 -> 0.75127118 | E9: ='Raw Data and Corrections'!AG37 -> 5.7114007 | F9: ='Raw Data and Corrections'!BB33 -> 0.06699477 | G9: =D9-F8 -> 0.59544779 | H9: =D9+F9 -> 0.81826595 | I9: -21.407593 | J9: -21.198779 | K9: -21.10995 | M9: ='Raw Data and Corrections'!S33 -> 0.34826733 | N9: ='Raw Data and Corrections'!AI37 -> 1.3643578 | O9: ='Raw Data and Corrections'!BE33 -> 0.034625206 | P9: =M9-O8 -> 0.27605772 | Q9: =M9+O9 -> 0.38289253 | R9: -23.654638 | S9: -23.46354 | T9: -23.358116 | U9: =(E8)/$E$36 -> 0.033756646 | V9: {='Raw Data and Corrections'!BQ33:BS33} -> 0.43990665 | W9: 0.45907237 | X9: 0.46933288
A10: 215 | B10: 450 | D10: ='Raw Data and Corrections'!Q38 -> 0.14151282 | E10: ='Raw Data and Corrections'!AG42 -> 5.8728625 | F10: ='Raw Data and Corrections'!BB38 -> 0.032510015 | G10: =D10-F9 -> 0.074518052 | H10: =D10+F10 -> 0.17402284 | I10: -22.515489 | J10: -21.985238 | K10: -21.798991 | M10: ='Raw Data and Corrections'!S38 -> 0.071590909 | N10: ='Raw Data and Corrections'!AI42 -> 1.4527785 | O10: ='Raw Data and Corrections'!BE38 -> 0.018584747 | P10: =M10-O9 -> 0.036965703 | Q10: =M10+O10 -> 0.090175656 | R10: -24.486026 | S10: -24.001326 | T10: -23.803978 | U10: =(E9)/$E$36 -> 0.039083907 | V10: {='Raw Data and Corrections'!BQ38:BS38} -> 0.5009879 | W10: 0.5009879 | X10: 0.530225
A11: 205 | B11: 520 | D11: ='Raw Data and Corrections'!Q43 -> 0.076269133 | E11: ='Raw Data and Corrections'!AG46 -> 5.9575573 | F11: ='Raw Data and Corrections'!BB43 -> 0.017161165 | G11: =D11-F10 -> 0.043759118 | H11: =D11+F11 -> 0.093430298 | I11: -23.235526 | J11: -22.754007 | K11: -22.568052 | M11: ='Raw Data and Corrections'!S43 -> 0.038451905 | N11: ='Raw Data and Corrections'!AI46 -> 1.5131326 | O11: ='Raw Data and Corrections'!BE43 -> 0.0097567832 | P11: =M11-O10 -> 0.019867158 | Q11: =M11+O11 -> 0.048208688 | R11: -24.838143 | S11: -24.476323 | T11: -24.323189 | U11: =(E10)/$E$36 -> 0.040188812 | V11: {='Raw Data and Corrections'!BQ43:BS43} -> 0.49926853 | W11: 0.49926853 | X11: 0.52774796
A12: 195 | B12: 1106 | D12: ='Raw Data and Corrections'!Q47 -> 0.067045156 | E12: ='Raw Data and Corrections'!AG50 -> 6.0383537 | F12: ='Raw Data and Corrections'!BB47 -> 0.0073345908 | G12: =D12-F11 -> 0.049883992 | H12: =D12+F12 -> 0.074379747 | I12: -23.779248 | J12: -23.541913 | K12: -23.45441 | M12: ='Raw Data and Corrections'!S47 -> 0.033582645 | N12: ='Raw Data and Corrections'!AI50 -> 1.5941014 | O12: ='Raw Data and Corrections'!BE47 -> 0.0040877758 | P12: =M12-O11 -> 0.023825861 | Q12: =M12+O12 -> 0.03767042 | R12: -25.015881 | S12: -24.890614 | T12: -24.840047 | U12: =(E11)/$E$36 -> 0.040768391 | V12: {='Raw Data and Corrections'!BQ47:BS47} -> 0.44642246 | W12: 0.49603536 | X12: 0.5096089
A13: 185 | B13: 740 | D13: ='Raw Data and Corrections'!Q51 -> 0.022678534 | E13: ='Raw Data and Corrections'!AG54 -> 6.0633602 | F13: ='Raw Data and Corrections'!BB51 -> 0.0046183251 | G13: =D13-F12 -> 0.015343943 | H13: =D13+F13 -> 0.027296859 | I13: -24.650631 | J13: -24.304076 | K13: -24.134217 | M13: ='Raw Data and Corrections'!S51 -> 0.0079399337 | N13: ='Raw Data and Corrections'!AI54 -> 1.6199227 | O13: ='Raw Data and Corrections'!BE51 -> 0.0018134793 | P13: =M13-O12 -> 0.0038521579 | Q13: =M13+O13 -> 0.009753413 | R13: -25.768907 | S13: -25.597834 | T13: -25.529395 | U13: =(E12)/$E$36 -> 0.041321292 | V13: {='Raw Data and Corrections'!BQ51:BS51} -> 0.23090847 | W13: 0.34671054 | X13: 0.36451263
A14: 175 | B14: 920 | D14: ='Raw Data and Corrections'!Q55 -> 0.018017912 | E14: ='Raw Data and Corrections'!AG58 -> 6.0856701 | F14: ='Raw Data and Corrections'!BB55 -> 0.0033584635 | G14: =D14-F13 -> 0.013399587 | H14: =D14+F14 -> 0.021376375 | I14: -24.86356 | J14: -24.631998 | K14: -24.491494 | M14: ='Raw Data and Corrections'!S55 -> 0.015191837 | N14: ='Raw Data and Corrections'!AI58 -> 1.6440059 | O14: ='Raw Data and Corrections'!BE55 -> 0.0031650678 | P14: =M14-O13 -> 0.013378357 | Q14: =M14+O14 -> 0.018356905 | R14: -25.947568 | S14: -25.869836 | T14: -25.745391 | U14: =(E13)/$E$36 -> 0.041492414 | V14: {='Raw Data and Corrections'!BQ55:BS55} -> 0.87407699 | W14: 0.83497021 | X14: 0.96492251
A15: 200 | B15: 260 | D15: ='Raw Data and Corrections'!Q59 -> 0.022423945 | E15: ='Raw Data and Corrections'!AG60 -> 6.1101518 | F15: ='Raw Data and Corrections'!BB59 -> 0.01360677 | G15: =D15-F14 -> 0.019065481 | H15: =D15+F15 -> 0.036030714 | I15: -23.418848 | J15: -23.271571 | K15: -22.828469 | M15: ='Raw Data and Corrections'!S59 -> 0.010662386 | N15: ='Raw Data and Corrections'!AI60 -> 1.6548136 | O15: ='Raw Data and Corrections'!BE59 -> 0.0076204226 | P15: =M15-O14 -> 0.0074973184 | Q15: =M15+O15 -> 0.018282809 | R15: -25.742315 | S15: -25.396759 | T15: -24.860835 | U15: =(E14)/$E$36 -> 0.041645084 | V15: {='Raw Data and Corrections'!BQ59:BS59} -> 0.37795257 | W15: 0.47087707 | X15: 0.54396774
A16: 210 | B16: 520 | D16: ='Raw Data and Corrections'!Q61 -> 0.081207065 | E16: ='Raw Data and Corrections'!AG64 -> 6.2030277 | F16: ='Raw Data and Corrections'!BB61 -> 0.01689741 | G16: =D16-F15 -> 0.067600295 | H16: =D16+F16 -> 0.098104474 | I16: -22.779112 | J16: -22.621801 | K16: -22.453276 | M16: ='Raw Data and Corrections'!S61 -> 0.21658617 | N16: ='Raw Data and Corrections'!AI64 -> 2.357893 | O16: ='Raw Data and Corrections'!BE61 -> 0.050770861 | P16: =M16-O15 -> 0.20896575 | Q16: =M16+O16 -> 0.26735703 | R16: -21.7278 | S16: -21.7188 | T16: -21.636502 | U16: =(E15)/$E$36 -> 0.041812616 | V16: {='Raw Data and Corrections'!BQ61:BS61} -> 2.6412047 | W16: 2.6412047 | X16: 2.7803903
A17: 220 | B17: 1167 | D17: ='Raw Data and Corrections'!Q65 -> 0.57662012 | E17: ='Raw Data and Corrections'!AG68 -> 6.7985877 | F17: ='Raw Data and Corrections'!BB65 -> 0.041885015 | G17: =D17-F16 -> 0.55972271 | H17: =D17+F17 -> 0.61850513 | I17: -21.545006 | J17: -21.517522 | K17: -21.44634 | M17: ='Raw Data and Corrections'!S65 -> 0.31868729 | N17: ='Raw Data and Corrections'!AI68 -> 2.9503223 | O17: ='Raw Data and Corrections'!BE65 -> 0.025747603 | P17: =M17-O16 -> 0.26791643 | Q17: =M17+O17 -> 0.34443489 | R17: -22.498688 | S17: -22.418611 | T17: -22.371229 | U17: =(E16)/$E$36 -> 0.042448178 | V17: {='Raw Data and Corrections'!BQ65:BS65} -> 0.47158837 | W17: 0.54731847 | X17: 0.55725925
A18: 230 | B18: 370 | D18: ='Raw Data and Corrections'!Q69 -> 0.35768644 | E18: ='Raw Data and Corrections'!AG72 -> 7.1814697 | F18: ='Raw Data and Corrections'!BB69 -> 0.083512558 | G18: =D18-F17 -> 0.31580143 | H18: =D18+F18 -> 0.441199 | I18: -20.850912 | J18: -20.738051 | K18: -20.53479 | M18: ='Raw Data and Corrections'!S69 -> 0.21132607 | N18: ='Raw Data and Corrections'!AI72 -> 3.2144133 | O18: ='Raw Data and Corrections'!BE69 -> 0.055900247 | P18: =M18-O17 -> 0.18557847 | Q18: =M18+O18 -> 0.26722632 | R18: -22.026684 | S18: -21.92827 | T18: -21.727244 | U18: =(E17)/$E$36 -> 0.046523678 | V18: {='Raw Data and Corrections'!BQ69:BS69} -> 0.57035381 | W18: 0.58508067 | X18: 0.61987309
A19: 240 | B19: 320 | D19: ='Raw Data and Corrections'!Q73 -> 0.67668226 | E19: ='Raw Data and Corrections'!AG76 -> 7.9194198 | F19: ='Raw Data and Corrections'!BB73 -> 0.16370415 | G19: =D19-F18 -> 0.5931697 | H19: =D19+F19 -> 0.84038642 | I19: -19.932296 | J19: -19.817939 | K19: -19.606322 | M19: ='Raw Data and Corrections'!S73 -> 0.42862848 | N19: ='Raw Data and Corrections'!AI76 -> 3.8370569 | O19: ='Raw Data and Corrections'!BE73 -> 0.1177548 | P19: =M19-O18 -> 0.37272823 | Q19: =M19+O19 -> 0.54638327 | R19: -20.877189 | S19: -20.791017 | T19: -20.601241 | U19: =(E18)/$E$36 -> 0.049143793 | V19: {='Raw Data and Corrections'!BQ73:BS73} -> 0.60763723 | W19: 0.62727991 | X19: 0.66602059
A20: 245 | B20: 250 | D20: ='Raw Data and Corrections'!Q77 -> 0.55490965 | E20: ='Raw Data and Corrections'!AG80 -> 8.5151292 | F20: ='Raw Data and Corrections'!BB77 -> 0.17093539 | G20: =D20-F19 -> 0.3912055 | H20: =D20+F20 -> 0.72584504 | I20: -20.007753 | J20: -19.696804 | K20: -19.433687 | M20: ='Raw Data and Corrections'!S77 -> 0.3988199 | N20: ='Raw Data and Corrections'!AI80 -> 4.2823757 | O20: ='Raw Data and Corrections'!BE77 -> 0.14022142 | P20: =M20-O19 -> 0.2810651 | Q20: =M20+O20 -> 0.53904132 | R20: -21.031025 | S20: -20.738317 | T20: -20.44745 | U20: =(E19)/$E$36 -> 0.054193687 | V20: {='Raw Data and Corrections'!BQ77:BS77} -> 0.66400113 | W20: 0.71173724 | X20: 0.76752356
A21: 250 | B21: 210 | D21: ='Raw Data and Corrections'!Q81 -> 0.69344251 | E21: ='Raw Data and Corrections'!AG84 -> 9.2547748 | F21: ='Raw Data and Corrections'!BB81 -> 0.24861074 | G21: =D21-F20 -> 0.52250712 | H21: =D21+F21 -> 0.94205325 | I21: -19.476852 | J21: -19.2241 | K21: -18.919702 | M21: ='Raw Data and Corrections'!S81 -> 0.44395973 | N21: ='Raw Data and Corrections'!AI84 -> 4.7722386 | O21: ='Raw Data and Corrections'!BE81 -> 0.1832817 | P21: =M21-O20 -> 0.30373831 | Q21: =M21+O21 -> 0.62724143 | R21: -20.681464 | S21: -20.359614 | T21: -20.02174 | U21: =(E20)/$E$36 -> 0.05827021 | V21: {='Raw Data and Corrections'!BQ81:BS81} -> 0.54406857 | W21: 0.63401315 | X21: 0.69230761
A22: 245 | B22: 270 | D22: ='Raw Data and Corrections'!Q85 -> 0.46587234 | E22: ='Raw Data and Corrections'!AG88 -> 9.7499793 | F22: ='Raw Data and Corrections'!BB85 -> 0.13015996 | G22: =D22-F21 -> 0.2172616 | H22: =D22+F22 -> 0.5960323 | I22: -20.489446 | J22: -19.805917 | K22: -19.565347 | M22: ='Raw Data and Corrections'!S85 -> 0.31233757 | N22: ='Raw Data and Corrections'!AI88 -> 5.1104463 | O22: ='Raw Data and Corrections'!BE85 -> 0.099572914 | P22: =M22-O21 -> 0.12905587 | Q22: =M22+O22 -> 0.41191049 | R22: -21.65622 | S22: -20.893884 | T22: -20.625801 | U22: =(E21)/$E$36 -> 0.063331707 | V22: {='Raw Data and Corrections'!BQ85:BS85} -> 0.48763032 | W22: 0.66393024 | X22: 0.71151279
A23: 240 | B23: 320 | D23: ='Raw Data and Corrections'!Q89 -> 0.28572751 | E23: ='Raw Data and Corrections'!AG92 -> 10.053633 | F23: ='Raw Data and Corrections'!BB89 -> 0.069133509 | G23: =D23-F22 -> 0.15556755 | H23: =D23+F23 -> 0.35486102 | I23: -20.974266 | J23: -20.42144 | K23: -20.212634 | M23: ='Raw Data and Corrections'!S89 -> 0.19266525 | N23: ='Raw Data and Corrections'!AI92 -> 5.319743 | O23: ='Raw Data and Corrections'!BE89 -> 0.052937525 | P23: =M23-O22 -> 0.093092332 | Q23: =M23+O23 -> 0.24560277 | R23: -22.126055 | S23: -21.48977 | T23: -21.259222 | U23: =(E22)/$E$36 -> 0.06672046 | V23: {='Raw Data and Corrections'!BQ89:BS89} -> 0.51705748 | W23: 0.66775397 | X23: 0.70900027
A24: 235 | B24: 370 | D24: ='Raw Data and Corrections'!Q93 -> 0.21993533 | E24: ='Raw Data and Corrections'!AG96 -> 10.287914 | F24: ='Raw Data and Corrections'!BB93 -> 0.047779571 | G24: =D24-F23 -> 0.15080182 | H24: =D24+F24 -> 0.2677149 | I24: -21.143732 | J24: -20.797641 | K24: -20.609555 | M24: ='Raw Data and Corrections'!S93 -> 0.15167647 | N24: ='Raw Data and Corrections'!AI96 -> 5.4843901 | O24: ='Raw Data and Corrections'!BE93 -> 0.037292522 | P24: =M24-O23 -> 0.098738945 | Q24: =M24+O24 -> 0.18896899 | R24: -22.222691 | S24: -21.839677 | T24: -21.632066 | U24: =(E23)/$E$36 -> 0.068798402 | V24: {='Raw Data and Corrections'!BQ93:BS93} -> 0.6012947 | W24: 0.68294913 | X24: 0.72069767
A25: 230 | B25: 420 | D25: ='Raw Data and Corrections'!Q97 -> 0.14002473 | E25: ='Raw Data and Corrections'!AG100 -> 10.441446 | F25: ='Raw Data and Corrections'!BB97 -> 0.028018066 | G25: =D25-F24 -> 0.092245164 | H25: =D25+F25 -> 0.1680428 | I25: -21.697369 | J25: -21.327001 | K25: -21.157947 | M25: ='Raw Data and Corrections'!S97 -> 0.099129484 | N25: ='Raw Data and Corrections'!AI100 -> 5.5973108 | O25: ='Raw Data and Corrections'!BE97 -> 0.022391757 | P25: =M25-O24 -> 0.061836962 | Q25: =M25+O25 -> 0.12152124 | R25: -22.715677 | S25: -22.31818 | T25: -22.13526 | U25: =(E24)/$E$36 -> 0.07040162 | V25: {='Raw Data and Corrections'!BQ97:BS97} -> 0.6105281 | W25: 0.70107299 | X25: 0.73667355
A26: 225 | B26: 652 | D26: ='Raw Data and Corrections'!Q101 -> 0.14936733 | E26: ='Raw Data and Corrections'!AG104 -> 10.603175 | F26: ='Raw Data and Corrections'!BB101 -> 0.019222809 | G26: =D26-F25 -> 0.12134927 | H26: =D26+F26 -> 0.16859014 | I26: -21.887605 | J26: -21.698774 | K26: -21.585497 | M26: ='Raw Data and Corrections'!S101 -> 0.099545905 | N26: ='Raw Data and Corrections'!AI104 -> 5.7200358 | O26: ='Raw Data and Corrections'!BE101 -> 0.014342816 | P26: =M26-O25 -> 0.077154148 | Q26: =M26+O26 -> 0.11388872 | R26: -22.853142 | S26: -22.653669 | T26: -22.541873 | U26: =(E25)/$E$36 -> 0.071452263 | V26: {='Raw Data and Corrections'!BQ101:BS101} -> 0.60623203 | W26: 0.65998325 | X26: 0.68136052
A27: 230 | B27: 500 | D27: ='Raw Data and Corrections'!Q105 -> 0.15497827 | E27: ='Raw Data and Corrections'!AG108 -> 10.768686 | F27: ='Raw Data and Corrections'!BB105 -> 0.025240473 | G27: =D27-F26 -> 0.13575546 | H27: =D27+F27 -> 0.18021875 | I27: -21.516357 | J27: -21.393852 | K27: -21.250664 | M27: ='Raw Data and Corrections'!S105 -> 0.10508868 | N27: ='Raw Data and Corrections'!AI108 -> 5.8393198 | O27: ='Raw Data and Corrections'!BE105 -> 0.019244273 | P27: =M27-O26 -> 0.090745866 | Q27: =M27+O27 -> 0.12433296 | R27: -22.522379 | S27: -22.395512 | T27: -22.244281 | U27: =(E26)/$E$36 -> 0.072558998 | V27: {='Raw Data and Corrections'!BQ105:BS105} -> 0.64735778 | W27: 0.67150658 | X27: 0.69915079
A28: 235 | B28: 450 | D28: ='Raw Data and Corrections'!Q109 -> 0.19512872 | E28: ='Raw Data and Corrections'!AG112 -> 10.990307 | F28: ='Raw Data and Corrections'!BB109 -> 0.033604148 | G28: =D28-F27 -> 0.16988824 | H28: =D28+F28 -> 0.22873286 | I28: -21.097166 | J28: -20.977484 | K28: -20.834665 | M28: ='Raw Data and Corrections'!S109 -> 0.13692172 | N28: ='Raw Data and Corrections'!AI112 -> 6.0025981 | O28: ='Raw Data and Corrections'!BE109 -> 0.026557236 | P28: =M28-O27 -> 0.11767745 | Q28: =M28+O28 -> 0.16347896 | R28: -22.075835 | S28: -21.952052 | T28: -21.79911 | U28: =(E27)/$E$36 -> 0.073691608 | V28: {='Raw Data and Corrections'!BQ109:BS109} -> 0.66975066 | W28: 0.6948904 | X28: 0.72518988
A29: 240 | B29: 400 | D29: ='Raw Data and Corrections'!Q113 -> 0.2424571 | E29: ='Raw Data and Corrections'!AG116 -> 11.253943 | F29: ='Raw Data and Corrections'!BB113 -> 0.044758886 | G29: =D29-F28 -> 0.20885295 | H29: =D29+F29 -> 0.28721599 | I29: -20.79738 | J29: -20.662635 | K29: -20.503683 | M29: ='Raw Data and Corrections'!S113 -> 0.17809765 | N29: ='Raw Data and Corrections'!AI116 -> 6.2079236 | O29: ='Raw Data and Corrections'!BE113 -> 0.037103594 | P29: =M29-O28 -> 0.15154042 | Q29: =M29+O29 -> 0.21520124 | R29: -21.71081 | S29: -21.574476 | T29: -21.40533 | U29: =(E28)/$E$36 -> 0.075208192 | V29: {='Raw Data and Corrections'!BQ113:BS113} -> 0.70013534 | W29: 0.72742535 | X29: 0.76149396
A30: 245 | B30: 350 | D30: ='Raw Data and Corrections'!Q117 -> 0.31499558 | E30: ='Raw Data and Corrections'!AG120 -> 11.591043 | F30: ='Raw Data and Corrections'!BB117 -> 0.06373796 | G30: =D30-F29 -> 0.2702367 | H30: =D30+F30 -> 0.37873354 | I30: -20.395275 | J30: -20.254902 | K30: -20.078751 | M30: ='Raw Data and Corrections'!S117 -> 0.23053963 | N30: ='Raw Data and Corrections'!AI120 -> 6.4597159 | O30: ='Raw Data and Corrections'!BE117 -> 0.052780989 | P30: =M30-O29 -> 0.19343604 | Q30: =M30+O30 -> 0.28332062 | R30: -21.356675 | S30: -21.200184 | T30: -21.005719 | U30: =(E29)/$E$36 -> 0.077012292 | V30: {='Raw Data and Corrections'!BQ117:BS117} -> 0.69007638 | W30: 0.72478012 | X30: 0.76208336
A31: 250 | B31: 300 | D31: ='Raw Data and Corrections'!Q121 -> 0.37161532 | E31: ='Raw Data and Corrections'!AG125 -> 11.98501 | F31: ='Raw Data and Corrections'!BB121 -> 0.084753868 | G31: =D31-F30 -> 0.30787736 | H31: =D31+F31 -> 0.45636919 | I31: -20.084831 | J31: -19.911234 | K31: -19.712545 | M31: ='Raw Data and Corrections'!S121 -> 0.27770578 | N31: ='Raw Data and Corrections'!AI125 -> 6.7576612 | O31: ='Raw Data and Corrections'!BE121 -> 0.07191205 | P31: =M31-O30 -> 0.22492479 | Q31: =M31+O31 -> 0.34961783 | R31: -21.026243 | S31: -20.835247 | T31: -20.613613 | U31: =(E30)/$E$36 -> 0.079319111 | V31: {='Raw Data and Corrections'!BQ121:BS121} -> 0.69946326 | W31: 0.74004216 | X31: 0.78312273
A32: 250 | B32: 300 | D32: ='Raw Data and Corrections'!Q126 -> 0.36397907 | E32: ='Raw Data and Corrections'!AG129 -> 12.371548 | F32: ='Raw Data and Corrections'!BB126 -> 0.083046028 | G32: =D32-F31 -> 0.2792252 | H32: =D32+F32 -> 0.4470251 | I32: -20.139223 | J32: -19.895424 | K32: -19.697157 | M32: ='Raw Data and Corrections'!S126 -> 0.26541781 | N32: ='Raw Data and Corrections'!AI129 -> 7.0412129 | O32: ='Raw Data and Corrections'!BE126 -> 0.068758449 | P32: =M32-O31 -> 0.19350576 | Q32: =M32+O32 -> 0.33417626 | R32: -21.129019 | S32: -20.841707 | T32: -20.619619 | U32: =(E31)/$E$36 -> 0.082015083 | V32: {='Raw Data and Corrections'!BQ126:BS126} -> 0.72213568 | W32: 0.72213568 | X32: 0.76419121
A33: 250 | B33: 300 | D33: ='Raw Data and Corrections'!Q130 -> 0.34519115 | E33: ='Raw Data and Corrections'!AG132 -> 12.735821 | F33: ='Raw Data and Corrections'!BB130 -> 0.078748676 | G33: =D33-F32 -> 0.26214512 | H33: =D33+F33 -> 0.42393982 | I33: -20.177392 | J33: -19.922194 | K33: -19.723114 | M33: ='Raw Data and Corrections'!S130 -> 0.2488978 | N33: ='Raw Data and Corrections'!AI132 -> 7.3113385 | O33: ='Raw Data and Corrections'!BE130 -> 0.064469947 | P33: =M33-O32 -> 0.18013935 | Q33: =M33+O33 -> 0.31336775 | R33: -21.100146 | S33: -20.81136 | T33: -20.592658 | U33: =(E32)/$E$36 -> 0.084660218 | V33: {='Raw Data and Corrections'!BQ130:BS130} -> 0.64606555 | W33: 0.71404661 | X33: 0.75562533
A34: 250 | B34: 10250 | D34: ='Raw Data and Corrections'!Q133 -> 8.4829081 | E34: ='Raw Data and Corrections'!AG134 -> 21.33526 | F34: ='Raw Data and Corrections'!BB133 -> 0.04636096 | G34: =D34-F33 -> 8.4041594 | H34: =D34+F34 -> 8.5292691 | I34: -19.964179 | J34: -19.957478 | K34: -19.950577 | M34: ='Raw Data and Corrections'!S133 -> 6.8042169 | N34: ='Raw Data and Corrections'!AI134 -> 14.159048 | O34: ='Raw Data and Corrections'!BE133 -> 0.041210325 | P34: =M34-O33 -> 6.7397469 | Q34: =M34+O34 -> 6.8454272 | R34: -20.690831 | S34: -20.684509 | T34: -20.676449 | U34: =(E33)/$E$36 -> 0.087152992 | V34: {='Raw Data and Corrections'!BQ133:BS133} -> 0.79432555 | W34: 0.79432555 | X34: 0.79540707
A35: 240 | B35: 785 | D35: ='Raw Data and Corrections'!Q135 -> 0.22612523 | E35: ='Raw Data and Corrections'!AG137 -> 21.590989 | F35: ='Raw Data and Corrections'!BB135 -> 0.019504847 | G35: =D35-F34 -> 0.17976427 | H35: =D35+F35 -> 0.24563008 | I35: -20.846403 | J35: -20.647603 | K35: -20.573584 | M35: ='Raw Data and Corrections'!S135 -> 0.18528316 | N35: ='Raw Data and Corrections'!AI137 -> 14.379339 | O35: ='Raw Data and Corrections'!BE135 -> 0.017845681 | P35: =M35-O34 -> 0.14407284 | Q35: =M35+O35 -> 0.20312885 | R35: -21.454401 | S35: -21.248852 | T35: -21.170278 | U35: =(E34)/$E$36 -> 0.14600014 | V35: {='Raw Data and Corrections'!BQ135:BS135} -> 0.81143192 | W35: 0.81143192 | X35: 0.82900134
A36: Total | E36: ='Raw Data and Corrections'!AE139 -> 146.13178 | N36: ='Raw Data and Corrections'!AG139 -> 147.56369

Sheet DistilledPermeationMethod
A1: Temp © | B1: Minutes | D1: 3He Measured (pccSTP) | E1: n0 3He (pccSTP) | F1: ± 2σ | G1: nt 3He (pccSTP) | H1: ± 2σ | I1: 3He ω (pccSTP) | J1: ± 2σ | K1: 3He ln(d/a^2) | L1: ± 2σ
A2: 170 | B2: 300 | D2: 0.96295642 | E2: 0 | F2: 0 | G2: 0.19677479 | H2: 0.022175267 | I2: =D2+G2-E2 -> 1.1597312 | J2: 0.026265117 | K2: -21.909784 | L2: 0.045295181
A3: 180 | B3: 463 | D3: 0.54418415 | E3: 0.072623003 | F3: 0.012879228 | G3: 0.078160263 | H3: 0.004929285 | I3: =D3+G3-E3 -> 0.54972141 | J3: 0.016048764 | K3: -22.184421 | L3: 0.089470864
A4: 190 | B4: 550 | D4: 0.52920164 | E4: 0.01945138 | F4: 0.0025358499 | G4: 0.067948183 | H4: 0.0081959612 | I4: =D4+G4-E4 -> 0.57769844 | J4: 0.012950251 | K4: -21.975555 | L4: 0.085490762
A5: 200 | B5: 500 | D5: 0.51895322 | E5: 0.03277502 | F5: 0.0054235857 | G5: 0.05318328 | H5: 0.0057734014 | I5: =D5+G5-E5 -> 0.53936148 | J5: 0.011455178 | K5: -21.702439 | L5: 0.088151327
A6: 210 | B6: 475 | D6: 0.57702821 | E6: 0.014061491 | F6: 0.002110601 | G6: 0.055214986 | H6: 0.0057108534 | I6: =D6+G6-E6 -> 0.61818171 | J6: 0.011701238 | K6: -21.310697 | L6: 0.082220743
A7: 220 | B7: 450 | D7: 0.63333256 | E7: 0.011048429 | F7: 0.001795669 | G7: 0.046933864 | H7: 0.0045756477 | I7: =D7+G7-E7 -> 0.669218 | J7: 0.012436423 | K7: -20.990584 | L7: 0.079824635
A8: 230 | B8: 425 | D8: 0.78987805 | E8: 0.0058701709 | F8: 0.0018638899 | G8: 0.063852973 | H8: 0.0034783534 | I8: =D8+G8-E8 -> 0.84786085 | J8: 0.012467123 | K8: -20.513907 | L8: 0.066216779
A9: 225 | B9: 908 | D9: 0.75127118 | E9: 0.019478638 | F9: 0.0024538493 | G9: 0.042015245 | H9: 0.0049388402 | I9: =D9+G9-E9 -> 0.77380779 | J9: 0.014174905 | K9: -21.200058 | L9: 0.12143479
A10: 215 | B10: 450 | D10: 0.14151282 | E10: 0.013097528 | F10: 0.00185248 | G10: 0.027835423 | H10: 0.0035378591 | I10: =D10+G10-E10 -> 0.15625072 | J10: 0.0064784414 | K10: -22.014553 | L10: 0.31623194
A11: 205 | B11: 520 | D11: 0.076269133 | E11: 0.0071789466 | F11: 0.0012252107 | G11: 0.012527671 | H11: 0.0016251793 | I11: =D11+G11-E11 -> 0.081617858 | J11: 0.0080957867 | K11: -22.788297 | L11: 0.82913174
A12: 195 | B12: 1106 | D12: 0.067045156 | E12: 0.0021161707 | F12: 0.00040220993 | G12: 0.030718163 | H12: 0.0028583371 | I12: =D12+G12-E12 -> 0.095647148 | J12: 0.0032294417 | K12: -23.369527 | L12: 1.0943842
A13: 185 | B13: 740 | D13: 0.022678534 | E13: 0.012547164 | F13: 0.0016424098 | G13: 0.0090187931 | H13: 0.0010554908 | I13: =D13+G13-E13 -> 0.019150164 | J13: 0.0019966671 | K13: -24.566539 | L13: 2.8220158
... A35: 240 | B35: 785 | D35: 0.22612523 | E35: 2.896825e-09 | F35: 6.8481814e-09 | G35: 0.026337426 | H35: 0.0029223985 | I35: =D35+G35-E35 -> 0.25246265 | J35: 0.022088877 | K35: -20.659737 | L35: 0.57969712
A36: Total | F36: 6.8481814e-09

Sheet Raw Data and Corrections
N1: Abundances, 4He Blank Corrections, Measured 4He/3He | AL1: Directly Quantifying Permeation Lag with Permeation Steps | AZ1: Bounding Permeation Lag with Steady State Assumption
A2: Notes | B2: Time (Pump out) | C2: Temperature (C) | D2: Nominal (Heated) Time (Minutes) | E2: Type | F2: 3He cps | G2: 4He Overspray cps | H2: 4He fA | I2: Nominal (Heated) Time (seconds) | J2: Watlow Time (seconds) | K2: Total Time (seconds) | L2: Cooling Time (seconds) | N2: Sensitivity 3He (pccSTP/cps) | O2: Sensitivity 4He (nccSTP/cps) | Q2: 3He measured (pccSTP) | R2: 2σ | S2: 4He measured (nccSTP) | T2: 2σ | V2: R/Rbulk no 4He Blank Correction | X2: 4He Blank Corrected (nccSTP) | Y2: 2σ | AA2: Blank Corrected 4He/3He | AB2: 2σ | AC2: Blank Corrected R/Rbulk | AD2: 2σ | AE2: 3He Cumulative, Corrected | AF2: 2σ | AG2: 3He Cumulative Measured | AH2: 2σ | AI2: 4He Cumulative Measured | AJ2: 2σ | AL2: 3He ln(K) Apparent Permeability (atoms/(atm*cm*s)) | AM2: 1σ | AN2: 3He K Apparent Permeability (atoms/(atm*cm*s)) | AO2: 1σ | AP2: λ = (KGRT) | AQ2: GRT | AR2: 3He n0 calc (pccSTP) (m/(1-e^-λt)) | AS2: 2σ | AT2: 3He n0 (pccSTP) | AU2: 2σ | AV2: 3He Corrected (pccSTP) | AW2: 2σ | AX2: 3He Correction % | AZ2: K 4He Swets | BA2: K 3He Jones and Swets | BB2: 3He ntUB | BC2: lambdat 3He | BD2: ntUB/m | BE2: 4He ntUB | BF2: lambdat 4He | BG2: 4He ntUB/m | BH2: 3He ωLB | BI2: 3He ωUB | BJ2: 4He ωLB | BK2: 4He ωUB | BL2: lambdat 3He maxR | BM2: 3He ntUB (for ratios) | BN2: R/R_bulk nt extreme | BO2: R/R_bulk n0 extreme | BP2: R/R_bulk Both extreme | BQ2: R/R_bulk LB | BR2: 4/3 R measured | BS2: R/R_bulk UB
B3: 45322.724
B4: 45322.783 | C4: 28.45 | D4: =I4/60 -> 60 | E4: Blank (experimental) | F4: -0.00395 | G4: 0 | H4: 0.0484 | I4: 3600 | J4: 3729.804 | K4: =(B4-B3)*24*3600 -> 5160 | L4: =K4-I4 -> 1560 | N4: 0.0062528858 | O4: 0.025735294 | Q4: -2.4698899e-05 | R4: -3.6340364e-07 | S4: 0.0012455882 | T4: 6.2576911e-06 | AL4: ='Fit Lambdas'!$U$2*(10000/(C4+273))+'Fit Lambdas'!$V$2 -> 22.195671 | AM4: ='Fit Lambdas'!$V$4 -> 0.067480704 | AN4: =EXP(AL4) -> 4.3597082e+09 | AO4: =AM4*AN4 -> 2.9419618e+08 | AP4: =AN4*(C4+273)*$C$145*$E$144 -> 1.2523685e-06 | AQ4: =(C4+273)*$C$145*$E$144 -> 2.8725972e-16
B5: 45323.01 | C5: 170 | D5: =I5/60 -> 300 | E5: Experimental Step | F5: 154 | G5: 0 | H5: 0.745 | I5: 18000 | J5: 18061.083 | K5: =(B5-B4)*24*3600 -> 19560 | L5: =K5-I5 -> 1560 | N5: 0.0062529637 | O5: 0.02577444 | Q5: 0.96295642 | R5: 0.014075295 | S5: 0.019201958 | T5: 8.1384482e-05 | V5: =(1000*S5/Q5)/$AE$140 -> 0.019747132 | X5: =S5-AVERAGE(S6:S8) -> 0.013769741 | Y5: =T5+AVERAGE(S6:S8) -> 0.0055136015 | AA5: =(X5*1000)/Q5 -> 14.299443 | AB5: =2*((1000*Y5/(2*Q5))^2+((R5/2)*1000*X5/(Q5^2))^2)^0.5 -> 5.7295156 | AC5: =AA5/$AE$140 -> 0.014160685 | AD5: =2*(($AF$140*AA5/(2*$AE$140^2))^2+(AB5/($AE$140*2))^2)^0.5 -> 0.0056758858 | AE5: =SUM(AV$5:$AV5) -> 1.1597312 | AF5: {=2*SQRT(SUM((AW$5:$AW5/2)^2))} -> 0.026265117 | AG5: =Q5 -> 0.96295642 | AH5: {=2*SQRT(SUM((R$5:$R5/2)^2))} -> 0.014075295 | AI5: =S5 -> 0.019201958 | AJ5: {=2*SQRT(SUM((T$5:$T5/2)^2))} -> 8.1384482e-05 | AQ5: =(C5+273)*$C$145*$E$144 -> 4.2214648e-16 | AV5: =Q5+AT6-AT5 -> 1.1597312 | AW5: =2*(((AU5/2)^2+(AU6/2)^2+(R5/2)^2)^(0.5)) -> 0.026265117 | AX5: =100*(AV5-Q5)/Q5 -> 20.434444 | AZ5: =IF((273+C5)>=600, 0.00074*EXP(-6613/(1.987*(273+C5)))*128000000000000000*EXP(1174/(1.987*(273+C5))), 0.000304*EXP(-5580/(1.987*(273+C5)))*199000000000000000*EXP(680/(1.987*(273+C5)))) -> 2.3129067e+11 | BA5: =AZ5 * 1.17*EXP(-57/(1.987*(273+C5))) -> 2.5364204e+11 | BB5: =Q5*BD5 -> 1.0384142 | BC5: =AQ5*BA5*I5 -> 1.9273337 | BD5: =1/(BC5-1) -> 1.0783605 | BE5: =BG5*S5 -> 0.025349329 | BF5: =AQ5*AZ5*I5 -> 1.7574937 | BG5: =1/(BF5-1) -> 1.320143 | BL5: =BF5*1.29 -> 2.2671669 | BR5: =((1000*S5/Q5))/$AE$140 -> 0.019747132
B6: 45323.132 | C6: 100 | D6: =I6/60 -> 150 | E6: Permeation Step | F6: 9.62 | G6: 0 | H6: 0.129 | I6: 9000 | J6: 9035.296 | K6: =(B6-B5)*24*3600 -> 10560 | L6: =K6-I6 -> 1560 | N6: 0.0062521891 | O6: 0.025777414 | Q6: 0.06014606 | R6: 0.00083352383 | S6: 0.0033252864 | T6: 1.4783904e-05 | AE6: =SUM(AV$5:$AV6) -> 1.1597312 | AF6: {=2*SQRT(SUM((AW$5:$AW6/2)^2))} -> 0.026265117 | AG6: =AG5+Q6 -> 1.0231025 | AH6: {=2*SQRT(SUM((R$5:$R6/2)^2))} -> 0.014099953 | AI6: =AI5+S6 -> 0.022527244 | AJ6: {=2*SQRT(SUM((T$5:$T6/2)^2))} -> 8.2716369e-05 | AL6: ='Fit Lambdas'!$U$2*(10000/(C6+273))+'Fit Lambdas'!$V$2 -> 25.459765 | AM6: ='Fit Lambdas'!$V$4 -> 0.067480704 | AN6: =EXP(AL6) -> 1.1403424e+11 | AO6: =AM6*AN6 -> 7.6951106e+09 | AP6: =AN6*(C6+273)*$C$145*$E$144 -> 4.0532513e-05 | AQ6: =(C6+273)*$C$145*$E$144 -> 3.5544161e-16 | AR6: =Q6/(1-EXP(-D6*60*AP6)) -> 0.19677479 | AS6: =2*SQRT( ((R6/2) * (1 / (1 - EXP(-D6 * 60 * AN6 * AQ6))))^2 + (AO6 * (-Q6 * 60 * D6 * AQ6 * EXP(-D6 * 60 * AN6 * AQ6) / (1 - EXP(-D6 * 60 * AN6 * AQ6))^2))^2 ) -> 0.022175267 | AT6: =AR6 -> 0.19677479 | AU6: =AS6 -> 0.022175267 | AZ6: =IF((273+C6)>=600, 0.00074*EXP(-6613/(1.987*(273+C6)))*128000000000000000*EXP(1174/(1.987*(273+C6))), 0.000304*EXP(-5580/(1.987*(273+C6)))*199000000000000000*EXP(680/(1.987*(273+C6)))) -> 8.1368988e+10 | BA6: =AZ6 * 1.17*EXP(-57/(1.987*(273+C6))) -> 8.8154465e+10
B7: 45323.254 | C7: 99.99 | D7: =I7/60 -> 150 | F7: 5.53 | G7: 0 | H7: 0.0402 | I7: 9000 | J7: 9026.505 | K7: =(B7-B6)*24*3600 -> 10560 | L7: =K7-I7 -> 1560 | N7: 0.0062521891 | O7: 0.025777414 | Q7: 0.034574606 | R7: 0.0004688042 | S7: 0.001036252 | T7: 4.6042688e-06 | AE7: =SUM(AV$5:$AV7) -> 1.1597312 | AF7: {=2*SQRT(SUM((AW$5:$AW7/2)^2))} -> 0.026265117 | AG7: =AG6+Q7 -> 1.0576771 | AH7: {=2*SQRT(SUM((R$5:$R7/2)^2))} -> 0.014107745 | AI7: =AI6+S7 -> 0.023563496 | AJ7: {=2*SQRT(SUM((T$5:$T7/2)^2))} -> 8.2844415e-05 | AL7: ='Fit Lambdas'!$U$2*(10000/(C7+273))+'Fit Lambdas'!$V$2 -> 25.459396 | AM7: ='Fit Lambdas'!$V$4 -> 0.067480704 | AN7: =EXP(AL7) -> 1.139922e+11 | AO7: =AM7*AN7 -> 7.692274e+09 | AP7: =AN7*(C7+273)*$C$145*$E$144 -> 4.0516486e-05 | AQ7: =(C7+273)*$C$145*$E$144 -> 3.5543209e-16 | AR7: =Q7/(1-EXP(-D7*60*AP7)) -> 0.1131519 | AS7: =2*SQRT( ((R7/2) * (1 / (1 - EXP(-D7 * 60 * AN7 * AQ7))))^2 + (AO7 * (-Q7 * 60 * D7 * AQ7 * EXP(-D7 * 60 * AN7 * AQ7) / (1 - EXP(-D7 * 60 * AN7 * AQ7))^2))^2 ) -> 0.012748343 | AT7: =AT6*EXP(-AP6*D6*60) -> 0.13662873 | AU7: =2*((((AU6/2)*EXP(-AP6*D6*60))^2+(AT6*EXP(-AP6*D6*60)*D6*60*AO6*AP6/AN6)^2)^0.5) -> 0.016802411 | AZ7: =IF((273+C7)>=600, 0.00074*EXP(-6613/(1.987*(273+C7)))*128000000000000000*EXP(1174/(1.987*(273+C7))), 0.000304*EXP(-5580/(1.987*(273+C7)))*199000000000000000*EXP(680/(1.987*(273+C7)))) -> 8.1354566e+10 | BA7: =AZ7 * 1.17*EXP(-57/(1.987*(273+C7))) -> 8.8138659e+10
B8: 45323.382 | C8: 99.99 | D8: =I8/60 -> 150 | F8: 3.56 | G8: 0 | H8: 0.463 | I8: 9000 | J8: 9018.104 | K8: =(B8-B7)*24*3600 -> 11040 | L8: =K8-I8 -> 2040 | N8: 0.0062521243 | O8: 0.025777781 | Q8: 0.022257563 | R8: 0.00031133036 | S8: 0.011935112 | T8: 4.9936245e-05 | AE8: =SUM(AV$5:$AV8) -> 1.1597312 | AF8: {=2*SQRT(SUM((AW$5:$AW8/2)^2))} -> 0.026265117 | AG8: =AG7+Q8 -> 1.0799346 | AH8: {=2*SQRT(SUM((R$5:$R8/2)^2))} -> 0.01411118 | AI8: =AI7+S8 -> 0.035498608 | AJ8: {=2*SQRT(SUM((T$5:$T8/2)^2))} -> 9.6730686e-05 | AL8: ='Fit Lambdas'!$U$2*(10000/(C8+273))+'Fit Lambdas'!$V$2 -> 25.459396 | AM8: ='Fit Lambdas'!$V$4 -> 0.067480704 | AN8: =EXP(AL8) -> 1.139922e+11 | AO8: =AM8*AN8 -> 7.692274e+09 | AP8: =AN8*(C8+273)*$C$145*$E$144 -> 4.0516486e-05 | AQ8: =(C8+273)*$C$145*$E$144 -> 3.5543209e-16 | AR8: =Q8/(1-EXP(-D8*60*AP8)) -> 0.072842062 | AS8: =2*SQRT( ((R8/2) * (1 / (1 - EXP(-D8 * 60 * AN8 * AQ8))))^2 + (AO8 * (-Q8 * 60 * D8 * AQ8 * EXP(-D8 * 60 * AN8 * AQ8) / (1 - EXP(-D8 * 60 * AN8 * AQ8))^2))^2 ) -> 0.0082106187 | AT8: =AT7*EXP(-AP7*D7*60) -> 0.094880566 | AU8: =2*((((AU7/2)*EXP(-AP7*D7*60))^2+(AT7*EXP(-AP7*D7*60)*D7*60*AO7*AP7/AN7)^2)^0.5) -> 0.012567897 | AZ8: =IF((273+C8)>=600, 0.00074*EXP(-6613/(1.987*(273+C8)))*128000000000000000*EXP(1174/(1.987*(273+C8))), 0.000304*EXP(-5580/(1.987*(273+C8)))*199000000000000000*EXP(680/(1.987*(273+C8)))) -> 8.1354566e+10 | BA8: =AZ8 * 1.17*EXP(-57/(1.987*(273+C8))) -> 8.8138659e+10
B9: 45323.818 | C9: 180 | D9: =I9/60 -> 463 | E9: Experimental Step | F9: 87.3 | G9: 0 | H9: 1.18 | I9: 27780 | J9: 27819.784 | K9: =(B9-B8)*24*3600 -> 37680 | L9: =K9-I9 -> 9900 | N9: 0.0062334954 | O9: 0.025819672 | Q9: 0.54418415 | R9: 0.00820917 | S9: 0.030467213 | T9: 0.00012198189 | V9: =(1000*S9/Q9)/$AE$140 -> 0.055443672 | X9: =S9-AVERAGE(S10:S12) -> 0.025207708 | Y9: =T9+AVERAGE(S10:S12) -> 0.0053814874 | AA9: =(X9*1000)/Q9 -> 46.322017 | AB9: =2*((1000*Y9/(2*Q9))^2+((R9/2)*1000*X9/(Q9^2))^2)^0.5 -> 9.9137503 | AC9: =AA9/$AE$140 -> 0.045872521 | AD9: =2*(($AF$140*AA9/(2*$AE$140^2))^2+(AB9/($AE$140*2))^2)^0.5 -> 0.0098294794 | AE9: =SUM(AV$5:$AV9) -> 1.7094526 | AF9: {=2*SQRT(SUM((AW$5:$AW9/2)^2))} -> 0.030780176 | AG9: =AG8+Q9 -> 1.6241188 | AH9: {=2*SQRT(SUM((R$5:$R9/2)^2))} -> 0.016325314 | AI9: =AI8+S9 -> 0.065965822 | AJ9: {=2*SQRT(SUM((T$5:$T9/2)^2))} -> 0.00015568047 | AQ9: =(C9+273)*$C$145*$E$144 -> 4.3167574e-16 | AT9: =AT8-Q8 -> 0.072623003 | AU9: =AU8+R8 -> 0.012879228 | AV9: =Q9+AT10-AT9 -> 0.54972141 | AW9: =2*(((AU9/2)^2+(AU10/2)^2+(R9/2)^2)^(0.5)) -> 0.016048764 | AX9: =100*(AV9-Q9)/Q9 -> 1.0175343 | AZ9: =IF((273+C9)>=600, 0.00074*EXP(-6613/(1.987*(273+C9)))*128000000000000000*EXP(1174/(1.987*(273+C9))), 0.000304*EXP(-5580/(1.987*(273+C9)))*199000000000000000*EXP(680/(1.987*(273+C9)))) -> 2.6153274e+11 | BA9: =AZ9 * 1.17*EXP(-57/(1.987*(273+C9))) -> 2.8721691e+11 | BB9: =Q9*BD9 -> 0.22263473 | BC9: =AQ9*BA9*I9 -> 3.4442914 | BD9: =1/(BC9-1) -> 0.40911652 | BE9: =BG9*S9 -> 0.014261753 | BF9: =AQ9*AZ9*I9 -> 3.1362881 | BG9: =1/(BF9-1) -> 0.46810166 | BL9: =BF9*1.29 -> 4.0458117 | BR9: =((1000*S9/Q9))/$AE$140 -> 0.055443672
B10: 45324.597 | C10: 95.39 | D10: =I10/60 -> 150 | F10: 6.87 | G10: 0 | H10: 0.326 | I10: 9000 | J10: 65932.549 | K10: =(B10-B9)*24*3600 -> 67320 | L10: =K10-I10 -> 58320 | N10: 0.0062327767 | O10: 0.025824355 | Q10: 0.042819176 | R10: 0.00078537599 | S10: 0.0084187396 | T10: 3.2756365e-05 | AE10: =SUM(AV$5:$AV10) -> 1.7094526 | AF10: {=2*SQRT(SUM((AW$5:$AW10/2)^2))} -> 0.030780176 | AG10: =AG9+Q10 -> 1.666938 | AH10: {=2*SQRT(SUM((R$5:$R10/2)^2))} -> 0.016344194 | AI10: =AI9+S10 -> 0.074384561 | AJ10: {=2*SQRT(SUM((T$5:$T10/2)^2))} -> 0.00015908924 | AL10: ='Fit Lambdas'!$U$2*(10000/(C10+273))+'Fit Lambdas'!$V$2 -> 25.287672 | AM10: ='Fit Lambdas'!$V$4 -> 0.067480704 | AN10: =EXP(AL10) -> 9.6005595e+10 | AO10: =AM10*AN10 -> 6.4785251e+09 | AP10: =AN10*(C10+273)*$C$145*$E$144 -> 3.3702632e-05 | AQ10: =(C10+273)*$C$145*$E$144 -> 3.5104862e-16 | AR10: =Q10/(1-EXP(-D10*60*AP10)) -> 0.16365688 | AS10: =2*SQRT( ((R10/2) * (1 / (1 - EXP(-D10 * 60 * AN10 * AQ10))))^2 + (AO10 * (-Q10 * 60 * D10 * AQ10 * EXP(-D10 * 60 * AN10 * AQ10) / (1 - EXP(-D10 * 60 * AN10 * AQ10))^2))^2 ) -> 0.019143445 | AT10: =AT11+Q10 -> 0.078160263 | AU10: =AU11+R10 -> 0.004929285 | AZ10: =IF((273+C10)>=600, 0.00074*EXP(-6613/(1.987*(273+C10)))*128000000000000000*EXP(1174/(1.987*(273+C10))), 0.000304*EXP(-5580/(1.987*(273+C10)))*199000000000000000*EXP(680/(1.987*(273+C10)))) -> 7.4907986e+10 | BA10: =AZ10 * 1.17*EXP(-57/(1.987*(273+C10))) -> 8.1076604e+10
B11: 45324.719 | C11: 95 | D11: =I11/60 -> 150 | E11: Permeation Step | F11: 1.46 | G11: 0 | H11: 0.0296 | I11: 9000 | J11: 9038.848 | K11: =(B11-B10)*24*3600 -> 10560 | L11: =K11-I11 -> 1560 | N11: 0.0062480449 | O11: 0.025854018 | Q11: 0.0091221455 | R11: 0.00016709173 | S11: 0.00076527892 | T11: 2.9757551e-06 | AE11: =SUM(AV$5:$AV11) -> 1.7094526 | AF11: {=2*SQRT(SUM((AW$5:$AW11/2)^2))} -> 0.030780176 | AG11: =AG10+Q11 -> 1.6760601 | AH11: {=2*SQRT(SUM((R$5:$R11/2)^2))} -> 0.016345048 | AI11: =AI10+S11 -> 0.07514984 | AJ11: {=2*SQRT(SUM((T$5:$T11/2)^2))} -> 0.00015911707 | AL11: ='Fit Lambdas'!$U$2*(10000/(C11+273))+'Fit Lambdas'!$V$2 -> 25.272916 | AM11: ='Fit Lambdas'!$V$4 -> 0.067480704 | AN11: =EXP(AL11) -> 9.4599281e+10 | AO11: =AM11*AN11 -> 6.3836261e+09 | AP11: =AN11*(C11+273)*$C$145*$E$144 -> 3.317379e-05 | AQ11: =(C11+273)*$C$145*$E$144 -> 3.5067698e-16 | AR11: =Q11/(1-EXP(-D11*60*AP11)) -> 0.035341088 | AS11: =2*SQRT( ((R11/2) * (1 / (1 - EXP(-D11 * 60 * AN11 * AQ11))))^2 + (AO11 * (-Q11 * 60 * D11 * AQ11 * EXP(-D11 * 60 * AN11 * AQ11) / (1 - EXP(-D11 * 60 * AN11 * AQ11))^2))^2 ) -> 0.004143909 | AT11: =AR11 -> 0.035341088 | AU11: =AS11 -> 0.004143909 | AZ11: =IF((273+C11)>=600, 0.00074*EXP(-6613/(1.987*(273+C11)))*128000000000000000*EXP(1174/(1.987*(273+C11))), 0.000304*EXP(-5580/(1.987*(273+C11)))*199000000000000000*EXP(680/(1.987*(273+C11)))) -> 7.437845e+10 | BA11: =AZ11 * 1.17*EXP(-57/(1.987*(273+C11))) -> 8.0496818e+10
B12: 45324.842 | C12: 95 | D12: =I12/60 -> 150 | F12: 0.955 | G12: 0 | H12: 0.255 | I12: 9000 | J12: 9037.724 | K12: =(B12-B11)*24*3600 -> 10620 | L12: =K12-I12 -> 1620 | N12: 0.0062505352 | O12: 0.025860777 | Q12: 0.0059692611 | R12: 0.00010929331 | S12: 0.0065944981 | T12: 2.5712037e-05 | AE12: =SUM(AV$5:$AV12) -> 1.7094526 | AF12: {=2*SQRT(SUM((AW$5:$AW12/2)^2))} -> 0.030780176 | AG12: =AG11+Q12 -> 1.6820294 | AH12: {=2*SQRT(SUM((R$5:$R12/2)^2))} -> 0.016345414 | AI12: =AI11+S12 -> 0.081744338 | AJ12: {=2*SQRT(SUM((T$5:$T12/2)^2))} -> 0.00016118111 | AL12: ='Fit Lambdas'!$U$2*(10000/(C12+273))+'Fit Lambdas'!$V$2 -> 25.272916 | AM12: ='Fit Lambdas'!$V$4 -> 0.067480704 | AN12: =EXP(AL12) -> 9.4599281e+10 | AO12: =AM12*AN12 -> 6.3836261e+09 | AP12: =AN12*(C12+273)*$C$145*$E$144 -> 3.317379e-05 | AQ12: =(C12+273)*$C$145*$E$144 -> 3.5067698e-16 | AR12: =Q12/(1-EXP(-D12*60*AP12)) -> 0.023126158 | AS12: =2*SQRT( ((R12/2) * (1 / (1 - EXP(-D12 * 60 * AN12 * AQ12))))^2 + (AO12 * (-Q12 * 60 * D12 * AQ12 * EXP(-D12 * 60 * AN12 * AQ12) / (1 - EXP(-D12 * 60 * AN12 * AQ12))^2))^2 ) -> 0.0027116228 | AT12: =AT11*EXP(-AP11*D11*60) -> 0.026218942 | AU12: =2*((((AU11/2)*EXP(-AP11*D11*60))^2+(AT11*EXP(-AP11*D11*60)*D11*60*AO11*AP11/AN11)^2)^0.5) -> 0.0032507602 | AZ12: =IF((273+C12)>=600, 0.00074*EXP(-6613/(1.987*(273+C12)))*128000000000000000*EXP(1174/(1.987*(273+C12))), 0.000304*EXP(-5580/(1.987*(273+C12)))*199000000000000000*EXP(680/(1.987*(273+C12)))) -> 7.437845e+10 | BA12: =AZ12 * 1.17*EXP(-57/(1.987*(273+C12))) -> 8.0496818e+10
B13: 45325.242 | C13: 190 | D13: =I13/60 -> 550 | E13: Experimental Step | F13: 85.1 | G13: 0 | H13: 2.16 | I13: 33000 | J13: 33053.236 | K13: =(B13-B12)*24*3600 -> 34560 | L13: =K13-I13 -> 1560 | N13: 0.0062185856 | O13: 0.025819672 | Q13: 0.52920164 | R13: 0.009700757 | S13: 0.055770492 | T13: 0.00023349086 | V13: =(1000*S13/Q13)/$AE$140 -> 0.10436345 | X13: =S13-AVERAGE(S14:S16) -> 0.052428438 | Y13: =T13+AVERAGE(S14:S16) -> 0.0035755443 | AA13: =(X13*1000)/Q13 -> 99.070816 | AB13: =2*((1000*Y13/(2*Q13))^2+((R13/2)*1000*X13/(Q13^2))^2)^0.5 -> 6.9962988 | AC13: =AA13/$AE$140 -> 0.098109461 | AD13: =2*(($AF$140*AA13/(2*$AE$140^2))^2+(AB13/($AE$140*2))^2)^0.5 -> 0.0070053504 | AE13: =SUM(AV$5:$AV13) -> 2.2871511 | AF13: {=2*SQRT(SUM((AW$5:$AW13/2)^2))} -> 0.033393536 | AG13: =AG12+Q13 -> 2.211231 | AH13: {=2*SQRT(SUM((R$5:$R13/2)^2))} -> 0.019007294 | AI13: =AI12+S13 -> 0.13751483 | AJ13: {=2*SQRT(SUM((T$5:$T13/2)^2))} -> 0.00028372052 | AQ13: =(C13+273)*$C$145*$E$144 -> 4.4120501e-16 | AT13: =AT12*EXP(-AP12*D12*60) -> 0.01945138 | AU13: =2*((((AU12/2)*EXP(-AP12*D12*60))^2+(AT12*EXP(-AP12*D12*60)*D12*60*AO12*AP12/AN12)^2)^0.5) -> 0.0025358499 | AV13: =Q13+AT14-AT13 -> 0.57769844 | AW13: =2*(((AU13/2)^2+(AU14/2)^2+(R13/2)^2)^(0.5)) -> 0.012950251 | AX13: =100*(AV13-Q13)/Q13 -> 9.1641445 | AZ13: =IF((273+C13)>=600, 0.00074*EXP(-6613/(1.987*(273+C13)))*128000000000000000*EXP(1174/(1.987*(273+C13))), 0.000304*EXP(-5580/(1.987*(273+C13)))*199000000000000000*EXP(680/(1.987*(273+C13)))) -> 2.9416345e+11 | BA13: =AZ13 * 1.17*EXP(-57/(1.987*(273+C13))) -> 3.2349431e+11 | BB13: =Q13*BD13 -> 0.14264191 | BC13: =AQ13*BA13*I13 -> 4.7100012 | BD13: =1/(BC13-1) -> 0.26954169 | BE13: =BG13*S13 -> 0.016987916 | BF13: =AQ13*AZ13*I13 -> 4.2829508 | BG13: =1/(BF13-1) -> 0.30460402 | BL13: =BF13*1.29 -> 5.5250065 | BR13: =((1000*S13/Q13))/$AE$140 -> 0.10436345
B14: 45325.364 | C14: 90 | D14: =I14/60 -> 150 | E14: Permeation Step | F14: 2.35 | G14: 0 | H14: 0.079 | I14: 9000 | J14: 9125.085 | K14: =(B14-B13)*24*3600 -> 10500 | L14: =K14-I14 -> 1500 | N14: 0.0062389603 | O14: 0.025819672 | Q14: 0.014661557 | R14: 0.00026841604 | S14: 0.0020397541 | T14: 8.5397121e-06 | AE14: =SUM(AV$5:$AV14) -> 2.2871511 | AF14: {=2*SQRT(SUM((AW$5:$AW14/2)^2))} -> 0.033393536 | AG14: =AG13+Q14 -> 2.2258926 | AH14: {=2*SQRT(SUM((R$5:$R14/2)^2))} -> 0.019009189 | AI14: =AI13+S14 -> 0.13955458 | AJ14: {=2*SQRT(SUM((T$5:$T14/2)^2))} -> 0.00028384901 | AL14: ='Fit Lambdas'!$U$2*(10000/(C14+273))+'Fit Lambdas'!$V$2 -> 25.08092 | AM14: ='Fit Lambdas'!$V$4 -> 0.067480704 | AN14: =EXP(AL14) -> 7.8073733e+10 | AO14: =AM14*AN14 -> 5.2684704e+09 | AP14: =AN14*(C14+273)*$C$145*$E$144 -> 2.7006668e-05 | AQ14: =(C14+273)*$C$145*$E$144 -> 3.4591235e-16 | AR14: =Q14/(1-EXP(-D14*60*AP14)) -> 0.067948183 | AS14: =2*SQRT( ((R14/2) * (1 / (1 - EXP(-D14 * 60 * AN14 * AQ14))))^2 + (AO14 * (-Q14 * 60 * D14 * AQ14 * EXP(-D14 * 60 * AN14 * AQ14) / (1 - EXP(-D14 * 60 * AN14 * AQ14))^2))^2 ) -> 0.0081959612 | AT14: =AR14 -> 0.067948183 | AU14: =AS14 -> 0.0081959612 | AZ14: =IF((273+C14)>=600, 0.00074*EXP(-6613/(1.987*(273+C14)))*128000000000000000*EXP(1174/(1.987*(273+C14))), 0.000304*EXP(-5580/(1.987*(273+C14)))*199000000000000000*EXP(680/(1.987*(273+C14)))) -> 6.7820444e+10 | BA14: =AZ14 * 1.17*EXP(-57/(1.987*(273+C14))) -> 7.3320582e+10
B15: 45325.504 | C15: 89.99 | D15: =I15/60 -> 150 | F15: 1.84 | H15: 0.157 | I15: 9000 | J15: 9127.493 | K15: =(B15-B14)*24*3600 -> 12120 | L15: =K15-I15 -> 3120 | N15: 0.00622826 | O15: 0.025832387 | Q15: 0.011459998 | R15: 0.00020545162 | S15: 0.0040556848 | T15: 1.6973617e-05 | AE15: =SUM(AV$5:$AV15) -> 2.2871511 | AF15: {=2*SQRT(SUM((AW$5:$AW15/2)^2))} -> 0.033393536 | AG15: =AG14+Q15 -> 2.2373526 | AH15: {=2*SQRT(SUM((R$5:$R15/2)^2))} -> 0.019010299 | AI15: =AI14+S15 -> 0.14361027 | AJ15: {=2*SQRT(SUM((T$5:$T15/2)^2))} -> 0.00028435605 | AL15: ='Fit Lambdas'!$U$2*(10000/(C15+273))+'Fit Lambdas'!$V$2 -> 25.08053 | AM15: ='Fit Lambdas'!$V$4 -> 0.067480704 | AN15: =EXP(AL15) -> 7.8043345e+10 | AO15: =AM15*AN15 -> 5.2664199e+09 | AP15: =AN15*(C15+273)*$C$145*$E$144 -> 2.6995413e-05 | AQ15: =(C15+273)*$C$145*$E$144 -> 3.4590282e-16 | AR15: =Q15/(1-EXP(-D15*60*AP15)) -> 0.053130298 | AS15: =2*SQRT( ((R15/2) * (1 / (1 - EXP(-D15 * 60 * AN15 * AQ15))))^2 + (AO15 * (-Q15 * 60 * D15 * AQ15 * EXP(-D15 * 60 * AN15 * AQ15) / (1 - EXP(-D15 * 60 * AN15 * AQ15))^2))^2 ) -> 0.0064059155 | AT15: =AT14-Q14 -> 0.053286626 | AU15: =AU14+R14 -> 0.0084643772 | AZ15: =IF((273+C15)>=600, 0.00074*EXP(-6613/(1.987*(273+C15)))*128000000000000000*EXP(1174/(1.987*(273+C15))), 0.000304*EXP(-5580/(1.987*(273+C15)))*199000000000000000*EXP(680/(1.987*(273+C15)))) -> 6.7807752e+10 | BA15: =AZ15 * 1.17*EXP(-57/(1.987*(273+C15))) -> 7.3306702e+10
B16: 45325.626 | C16: 90 | D16: =I16/60 -> 150 | F16: 1.34 | G16: 0 | H16: 0.152 | I16: 9000 | J16: 9130.299 | K16: =(B16-B15)*24*3600 -> 10560 | L16: =K16-I16 -> 1560 | N16: 0.0062000229 | O16: 0.025860009 | Q16: 0.0083080307 | R16: 0.00014060465 | S16: 0.0039307213 | T16: 1.6443347e-05 | AE16: =SUM(AV$5:$AV16) -> 2.2871511 | AF16: {=2*SQRT(SUM((AW$5:$AW16/2)^2))} -> 0.033393536 | AG16: =AG15+Q16 -> 2.2456606 | AH16: {=2*SQRT(SUM((R$5:$R16/2)^2))} -> 0.019010819 | AI16: =AI15+S16 -> 0.14754099 | AJ16: {=2*SQRT(SUM((T$5:$T16/2)^2))} -> 0.00028483109 | AL16: ='Fit Lambdas'!$U$2*(10000/(C16+273))+'Fit Lambdas'!$V$2 -> 25.08092 | AM16: ='Fit Lambdas'!$V$4 -> 0.067480704 | AN16: =EXP(AL16) -> 7.8073733e+10 | AO16: =AM16*AN16 -> 5.2684704e+09 | AP16: =AN16*(C16+273)*$C$145*$E$144 -> 2.7006668e-05 | AQ16: =(C16+273)*$C$145*$E$144 -> 3.4591235e-16 | AR16: =Q16/(1-EXP(-D16*60*AP16)) -> 0.038503114 | AS16: =2*SQRT( ((R16/2) * (1 / (1 - EXP(-D16 * 60 * AN16 * AQ16))))^2 + (AO16 * (-Q16 * 60 * D16 * AQ16 * EXP(-D16 * 60 * AN16 * AQ16) / (1 - EXP(-D16 * 60 * AN16 * AQ16))^2))^2 ) -> 0.0046364885 | AT16: =AT15*EXP(-AP15*D15*60) -> 0.041792908 | AU16: =2*((((AU15/2)*EXP(-AP15*D15*60))^2+(AT15*EXP(-AP15*D15*60)*D15*60*AO15*AP15/AN15)^2)^0.5) -> 0.006778611 | AZ16: =IF((273+C16)>=600, 0.00074*EXP(-6613/(1.987*(273+C16)))*128000000000000000*EXP(1174/(1.987*(273+C16))), 0.000304*EXP(-5580/(1.987*(273+C16)))*199000000000000000*EXP(680/(1.987*(273+C16)))) -> 6.7820444e+10 | BA16: =AZ16 * 1.17*EXP(-57/(1.987*(273+C16))) -> 7.3320582e+10
B17: 45325.999 | C17: 200 | D17: =I17/60 -> 500 | E17: Experimental Step | F17: 83.3 | G17: 0.00176 | H17: 3.96 | I17: 30000 | J17: 30127.625 | K17: =(B17-B16)*24*3600 -> 32220 | L17: =K17-I17 -> 2220 | N17: 0.0062299307 | O17: 0.025862069 | Q17: 0.51895322 | R17: 0.0082748805 | S17: 0.10241379 | T17: 0.00047358684 | V17: =(1000*S17/Q17)/$AE$140 -> 0.19543187 | X17: =S17-AVERAGE(S18:S20) -> 0.099215344 | Y17: =T17+AVERAGE(S18:S20) -> 0.0036720364 | AA17: =(X17*1000)/Q17 -> 191.1836 | AB17: =2*((1000*Y17/(2*Q17))^2+((R17/2)*1000*X17/(Q17^2))^2)^0.5 -> 7.7046059 | AC17: =AA17/$AE$140 -> 0.1893284 | AD17: =2*(($AF$140*AA17/(2*$AE$140^2))^2+(AB17/($AE$140*2))^2)^0.5 -> 0.0078871383 | AE17: =SUM(AV$5:$AV17) -> 2.8265125 | AF17: {=2*SQRT(SUM((AW$5:$AW17/2)^2))} -> 0.035303673 | AG17: =AG16+Q17 -> 2.7646138 | AH17: {=2*SQRT(SUM((R$5:$R17/2)^2))} -> 0.020733666 | AI17: =AI16+S17 -> 0.24995478 | AJ17: {=2*SQRT(SUM((T$5:$T17/2)^2))} -> 0.00055264206 | AQ17: =(C17+273)*$C$145*$E$144 -> 4.5073427e-16 | AT17: =AT16*EXP(-AP16*D16*60) -> 0.03277502 | AU17: =2*((((AU16/2)*EXP(-AP16*D16*60))^2+(AT16*EXP(-AP16*D16*60)*D16*60*AO16*AP16/AN16)^2)^0.5) -> 0.0054235857 | AV17: =Q17+AT18-AT17 -> 0.53936148 | AW17: =2*(((AU17/2)^2+(AU18/2)^2+(R17/2)^2)^(0.5)) -> 0.011455178 | AX17: =100*(AV17-Q17)/Q17 -> 3.9325816 | AZ17: =IF((273+C17)>=600, 0.00074*EXP(-6613/(1.987*(273+C17)))*128000000000000000*EXP(1174/(1.987*(273+C17))), 0.000304*EXP(-5580/(1.987*(273+C17)))*199000000000000000*EXP(680/(1.987*(273+C17)))) -> 3.2922459e+11 | BA17: =AZ17 * 1.17*EXP(-57/(1.987*(273+C17))) -> 3.6252593e+11 | BB17: =Q17*BD17 -> 0.1329938 | BC17: =AQ17*BA17*I17 -> 4.9020858 | BD17: =1/(BC17-1) -> 0.2562732 | BE17: =BG17*S17 -> 0.029669814 | BF17: =AQ17*AZ17*I17 -> 4.4517842 | BG17: =1/(BF17-1) -> 0.28970525 | BH17: =Q17-BB13 -> 0.37631132 | BI17: =Q17+BB17 -> 0.65194703 | BJ17: =X17-BE13 -> 0.082227428 | BK17: =X17+BE17 -> 0.12888516 | BL17: =BF17*1.29 -> 5.7428016 | BM17: =Q17 / (BL17-1) -> 0.10941913 | BR17: =((1000*S17/Q17))/$AE$140 -> 0.19543187
B18: 45326.122 | C18: 105 | D18: =I18/60 -> 150 | E18: Permeation Step; Lambda Fit | F18: 3.06 | G18: 0 | H18: 0.144 | I18: 9000 | J18: 9129.026 | K18: =(B18-B17)*24*3600 -> 10560 | L18: =K18-I18 -> 1560 | N18: 0.0062250831 | O18: 0.025862069 | Q18: 0.019048754 | R18: 0.00032080198 | S18: 0.0037241379 | T18: 1.595522e-05 | AE18: =SUM(AV$5:$AV18) -> 2.8265125 | AF18: {=2*SQRT(SUM((AW$5:$AW18/2)^2))} -> 0.035303673 | AG18: =AG17+Q18 -> 2.7836626 | AH18: {=2*SQRT(SUM((R$5:$R18/2)^2))} -> 0.020736148 | AI18: =AI17+S18 -> 0.25367892 | AJ18: {=2*SQRT(SUM((T$5:$T18/2)^2))} -> 0.00055287233 | AL18: ='Fit Lambdas'!$U$2*(10000/(C18+273))+'Fit Lambdas'!$V$2 -> 25.64167 | AM18: ='Fit Lambdas'!$V$4 -> 0.067480704 | AN18: =EXP(AL18) -> 1.367842e+11 | AO18: =AM18*AN18 -> 9.2302941e+09 | AP18: =AN18*(C18+273)*$C$145*$E$144 -> 4.9270523e-05 | AQ18: =(C18+273)*$C$145*$E$144 -> 3.6020625e-16 | AR18: =Q18/(1-EXP(-D18*60*AP18)) -> 0.05318328 | AS18: =2*SQRT( ((R18/2) * (1 / (1 - EXP(-D18 * 60 * AN18 * AQ18))))^2 + (AO18 * (-Q18 * 60 * D18 * AQ18 * EXP(-D18 * 60 * AN18 * AQ18) / (1 - EXP(-D18 * 60 * AN18 * AQ18))^2))^2 ) -> 0.0057734014 | AT18: {=AR18:AS18} -> 0.05318328 | AU18: 0.0057734014 | AZ18: =IF((273+C18)>=600, 0.00074*EXP(-6613/(1.987*(273+C18)))*128000000000000000*EXP(1174/(1.987*(273+C18))), 0.000304*EXP(-5580/(1.987*(273+C18)))*199000000000000000*EXP(680/(1.987*(273+C18)))) -> 8.8805251e+10 | BA18: =AZ18 * 1.17*EXP(-57/(1.987*(273+C18))) -> 9.6308773e+10
B19: 45326.244 | C19: 105 | D19: =I19/60 -> 150 | E19: Lambda Fit | F19: 1.79 | G19: 0 | H19: 0.187 | I19: 9000 | J19: 9127.555 | K19: =(B19-B18)*24*3600 -> 10560 | L19: =K19-I19 -> 1560 | N19: 0.0062200776 | O19: 0.025862069 | Q19: 0.011133939 | R19: 0.00019782239 | S19: 0.0048362069 | T19: 1.9021875e-05 | AE19: =SUM(AV$5:$AV19) -> 2.8265125 | AF19: {=2*SQRT(SUM((AW$5:$AW19/2)^2))} -> 0.035303673 | AG19: =AG18+Q19 -> 2.7947965 | AH19: {=2*SQRT(SUM((R$5:$R19/2)^2))} -> 0.020737091 | AI19: =AI18+S19 -> 0.25851513 | AJ19: {=2*SQRT(SUM((T$5:$T19/2)^2))} -> 0.00055319946 | AL19: ='Fit Lambdas'!$U$2*(10000/(C19+273))+'Fit Lambdas'!$V$2 -> 25.64167 | AM19: ='Fit Lambdas'!$V$4 -> 0.067480704 | AN19: =EXP(AL19) -> 1.367842e+11 | AO19: =AM19*AN19 -> 9.2302941e+09 | AP19: =AN19*(C19+273)*$C$145*$E$144 -> 4.9270523e-05 | AQ19: =(C19+273)*$C$145*$E$144 -> 3.6020625e-16 | AR19: =Q19/(1-EXP(-D19*60*AP19)) -> 0.031085465 | AS19: =2*SQRT( ((R19/2) * (1 / (1 - EXP(-D19 * 60 * AN19 * AQ19))))^2 + (AO19 * (-Q19 * 60 * D19 * AQ19 * EXP(-D19 * 60 * AN19 * AQ19) / (1 - EXP(-D19 * 60 * AN19 * AQ19))^2))^2 ) -> 0.003379123 | AT19: =AT18*EXP(-AP18*D18*60) -> 0.034134525 | AU19: =2*((((AU18/2)*EXP(-AP18*D18*60))^2+(AT18*EXP(-AP18*D18*60)*D18*60*AO18*AP18/AN18)^2)^0.5) -> 0.0042313279 | AZ19: =IF((273+C19)>=600, 0.00074*EXP(-6613/(1.987*(273+C19)))*128000000000000000*EXP(1174/(1.987*(273+C19))), 0.000304*EXP(-5580/(1.987*(273+C19)))*199000000000000000*EXP(680/(1.987*(273+C19)))) -> 8.8805251e+10 | BA19: =AZ19 * 1.17*EXP(-57/(1.987*(273+C19))) -> 9.6308773e+10
B20: 45326.366 | C20: 105 | D20: =I20/60 -> 150 | E20: Lambda Fit | F20: 1.29 | G20: 0 | H20: 0.04 | I20: 9000 | J20: 9129.528 | K20: =(B20-B19)*24*3600 -> 10560 | L20: =K20-I20 -> 1560 | N20: 0.006222837 | O20: 0.025875098 | Q20: 0.0080274597 | R20: 0.00014295915 | S20: 0.0010350039 | T20: 4.1228765e-06 | AE20: =SUM(AV$5:$AV20) -> 2.8265125 | AF20: {=2*SQRT(SUM((AW$5:$AW20/2)^2))} -> 0.035303673 | AG20: =AG19+Q20 -> 2.802824 | AH20: {=2*SQRT(SUM((R$5:$R20/2)^2))} -> 0.020737584 | AI20: =AI19+S20 -> 0.25955013 | AJ20: {=2*SQRT(SUM((T$5:$T20/2)^2))} -> 0.00055321483 | AL20: ='Fit Lambdas'!$U$2*(10000/(C20+273))+'Fit Lambdas'!$V$2 -> 25.64167 | AM20: ='Fit Lambdas'!$V$4 -> 0.067480704 | AN20: =EXP(AL20) -> 1.367842e+11 | AO20: =AM20*AN20 -> 9.2302941e+09 | AP20: =AN20*(C20+273)*$C$145*$E$144 -> 4.9270523e-05 | AQ20: =(C20+273)*$C$145*$E$144 -> 3.6020625e-16 | AR20: =Q20/(1-EXP(-D20*60*AP20)) -> 0.022412313 | AS20: =2*SQRT( ((R20/2) * (1 / (1 - EXP(-D20 * 60 * AN20 * AQ20))))^2 + (AO20 * (-Q20 * 60 * D20 * AQ20 * EXP(-D20 * 60 * AN20 * AQ20) / (1 - EXP(-D20 * 60 * AN20 * AQ20))^2))^2 ) -> 0.0024364655 | AT20: =AT19*EXP(-AP19*D19*60) -> 0.021908499 | AU20: =2*((((AU19/2)*EXP(-AP19*D19*60))^2+(AT19*EXP(-AP19*D19*60)*D19*60*AO19*AP19/AN19)^2)^0.5) -> 0.0030157255 | AZ20: =IF((273+C20)>=600, 0.00074*EXP(-6613/(1.987*(273+C20)))*128000000000000000*EXP(1174/(1.987*(273+C20))), 0.000304*EXP(-5580/(1.987*(273+C20)))*199000000000000000*EXP(680/(1.987*(273+C20)))) -> 8.8805251e+10 | BA20: =AZ20 * 1.17*EXP(-57/(1.987*(273+C20))) -> 9.6308773e+10
B21: 45326.714 | C21: 210 | D21: =I21/60 -> 475 | E21: Experimental Step | F21: 93 | G21: 0 | H21: 5.64 | I21: 28500 | J21: 28626.295 | K21: =(B21-B20)*24*3600 -> 30060 | L21: =K21-I21 -> 1560 | N21: 0.0062046044 | O21: 0.025884273 | Q21: 0.57702821 | R21: 0.0099925221 | S21: 0.1459873 | T21: 0.00061153078 | V21: =(1000*S21/Q21)/$AE$140 -> 0.25054352 | X21: =S21-AVERAGE(S22:S24) -> 0.14020058 | Y21: =T21+AVERAGE(S22:S24) -> 0.0063982505 | AA21: =(X21*1000)/Q21 -> 242.97006 | AB21: =2*((1000*Y21/(2*Q21))^2+((R21/2)*1000*X21/(Q21^2))^2)^0.5 -> 11.859745 | AC21: =AA21/$AE$140 -> 0.24061235 | AD21: =2*(($AF$140*AA21/(2*$AE$140^2))^2+(AB21/($AE$140*2))^2)^0.5 -> 0.012016046 | AE21: =SUM(AV$5:$AV21) -> 3.4446943 | AF21: {=2*SQRT(SUM((AW$5:$AW21/2)^2))} -> 0.037192315 | AG21: =AG20+Q21 -> 3.3798522 | AH21: {=2*SQRT(SUM((R$5:$R21/2)^2))} -> 0.023019511 | AI21: =AI20+S21 -> 0.40553743 | AJ21: {=2*SQRT(SUM((T$5:$T21/2)^2))} -> 0.00082463115 | AQ21: =(C21+273)*$C$145*$E$144 -> 4.6026354e-16 | AT21: =AT20*EXP(-AP20*D20*60) -> 0.014061491 | AU21: =2*((((AU20/2)*EXP(-AP20*D20*60))^2+(AT20*EXP(-AP20*D20*60)*D20*60*AO20*AP20/AN20)^2)^0.5) -> 0.002110601 | AV21: =Q21+AT22-AT21 -> 0.61818171 | AW21: =2*(((AU21/2)^2+(AU22/2)^2+(R21/2)^2)^(0.5)) -> 0.011701238 | AX21: =100*(AV21-Q21)/Q21 -> 7.1319727 | AZ21: =IF((273+C21)>=600, 0.00074*EXP(-6613/(1.987*(273+C21)))*128000000000000000*EXP(1174/(1.987*(273+C21))), 0.000304*EXP(-5580/(1.987*(273+C21)))*199000000000000000*EXP(680/(1.987*(273+C21)))) -> 3.6675059e+11 | BA21: =AZ21 * 1.17*EXP(-57/(1.987*(273+C21))) -> 4.0435513e+11 | BB21: =Q21*BD21 -> 0.13406376 | BC21: =AQ21*BA21*I21 -> 5.3041328 | BD21: =1/(BC21-1) -> 0.23233484 | BE21: =BG21*S21 -> 0.038308281 | BF21: =AQ21*AZ21*I21 -> 4.8108549 | BG21: =1/(BF21-1) -> 0.26240831 | BH21: =Q21-BB17 -> 0.44403441 | BI21: =Q21+BB21 -> 0.71109197 | BJ21: =X21-BE17 -> 0.11053077 | BK21: =X21+BE21 -> 0.17850886 | BL21: =BF21*1.29 -> 6.2060028 | BM21: =Q21 / (BL21-1) -> 0.11083901 | BN21: =(1000*(S21+BE21)/(Q21+BM21))/$AE$140 -> 0.26532334 | BO21: =(1000*(S21-BE17)/(Q21-BM17))/$AE$140 -> 0.24633562 | BP21: =(1000*(S21+BE21-BE17)/(Q21+BM21-BM17))/$AE$140 -> 0.26471748 | BQ21: =MIN(BN21:BP21) -> 0.24633562 | BR21: =((1000*S21/Q21))/$AE$140 -> 0.25054352 | BS21: =MAX(BN21:BP21) -> 0.26532334
B22: 45326.836 | C22: 109.99 | D22: =I22/60 -> 150 | E22: Permeation Step; Lambda Fit | F22: 3.71 | G22: 0 | H22: 0.374 | I22: 9000 | J22: 9128.359 | K22: =(B22-B21)*24*3600 -> 10560 | L22: =K22-I22 -> 1560 | N22: 0.0061766666 | O22: 0.025862224 | Q22: 0.022915433 | R22: 0.0003930218 | S22: 0.0096724716 | T22: 4.0523336e-05 | AE22: =SUM(AV$5:$AV22) -> 3.4446943 | AF22: {=2*SQRT(SUM((AW$5:$AW22/2)^2))} -> 0.037192315 | AG22: =AG21+Q22 -> 3.4027676 | AH22: {=2*SQRT(SUM((R$5:$R22/2)^2))} -> 0.023022866 | AI22: =AI21+S22 -> 0.4152099 | AJ22: {=2*SQRT(SUM((T$5:$T22/2)^2))} -> 0.00082562624 | AL22: ='Fit Lambdas'!$U$2*(10000/(C22+273))+'Fit Lambdas'!$V$2 -> 25.818477 | AM22: ='Fit Lambdas'!$V$4 -> 0.067480704 | AN22: =EXP(AL22) -> 1.6323829e+11 | AO22: =AM22*AN22 -> 1.1015435e+10 | AP22: =AN22*(C22+273)*$C$145*$E$144 -> 5.9575669e-05 | AQ22: =(C22+273)*$C$145*$E$144 -> 3.6496135e-16 | AR22: =Q22/(1-EXP(-D22*60*AP22)) -> 0.055214986 | AS22: =2*SQRT( ((R22/2) * (1 / (1 - EXP(-D22 * 60 * AN22 * AQ22))))^2 + (AO22 * (-Q22 * 60 * D22 * AQ22 * EXP(-D22 * 60 * AN22 * AQ22) / (1 - EXP(-D22 * 60 * AN22 * AQ22))^2))^2 ) -> 0.0057108534 | AT22: {=AR22:AS22} -> 0.055214986 | AU22: 0.0057108534 | AZ22: =IF((273+C22)>=600, 0.00074*EXP(-6613/(1.987*(273+C22)))*128000000000000000*EXP(1174/(1.987*(273+C22))), 0.000304*EXP(-5580/(1.987*(273+C22)))*199000000000000000*EXP(680/(1.987*(273+C22)))) -> 9.6683804e+10 | BA22: =AZ22 * 1.17*EXP(-57/(1.987*(273+C22))) -> 1.0495674e+11
B23: 45326.958 | C23: 110 | D23: =I23/60 -> 150 | E23: Lambda Fit | F23: 1.86 | G23: 0 | H23: 0.171 | I23: 9000 | J23: 9129.162 | K23: =(B23-B22)*24*3600 -> 10560 | L23: =K23-I23 -> 1560 | N23: 0.0061889977 | O23: 0.025874449 | Q23: 0.011511536 | R23: 0.00020127919 | S23: 0.0044245308 | T23: 1.8146535e-05 | AE23: =SUM(AV$5:$AV23) -> 3.4446943 | AF23: {=2*SQRT(SUM((AW$5:$AW23/2)^2))} -> 0.037192315 | AG23: =AG22+Q23 -> 3.4142792 | AH23: {=2*SQRT(SUM((R$5:$R23/2)^2))} -> 0.023023746 | AI23: =AI22+S23 -> 0.41963443 | AJ23: {=2*SQRT(SUM((T$5:$T23/2)^2))} -> 0.00082582563 | AL23: ='Fit Lambdas'!$U$2*(10000/(C23+273))+'Fit Lambdas'!$V$2 -> 25.818827 | AM23: ='Fit Lambdas'!$V$4 -> 0.067480704 | AN23: =EXP(AL23) -> 1.6329539e+11 | AO23: =AM23*AN23 -> 1.1019288e+10 | AP23: =AN23*(C23+273)*$C$145*$E$144 -> 5.9598062e-05 | AQ23: =(C23+273)*$C$145*$E$144 -> 3.6497088e-16 | AR23: =Q23/(1-EXP(-D23*60*AP23)) -> 0.027729294 | AS23: =2*SQRT( ((R23/2) * (1 / (1 - EXP(-D23 * 60 * AN23 * AQ23))))^2 + (AO23 * (-Q23 * 60 * D23 * AQ23 * EXP(-D23 * 60 * AN23 * AQ23) / (1 - EXP(-D23 * 60 * AN23 * AQ23))^2))^2 ) -> 0.0028692692 | AT23: =AT22*EXP(-AP22*D22*60) -> 0.032299553 | AU23: =2*((((AU22/2)*EXP(-AP22*D22*60))^2+(AT22*EXP(-AP22*D22*60)*D22*60*AO22*AP22/AN22)^2)^0.5) -> 0.0040771907 | AZ23: =IF((273+C23)>=600, 0.00074*EXP(-6613/(1.987*(273+C23)))*128000000000000000*EXP(1174/(1.987*(273+C23))), 0.000304*EXP(-5580/(1.987*(273+C23)))*199000000000000000*EXP(680/(1.987*(273+C23)))) -> 9.6700059e+10 | BA23: =AZ23 * 1.17*EXP(-57/(1.987*(273+C23))) -> 1.049746e+11
