Workbook

Sheet Raw Data and Corrections
A1: Raw Data | O1: Abundances, 4He Blank Corrections, Measured 4He/3He | AG1: Permeation Lag Corrected 4He, 3He: Cumulative and Ratios | AZ1: Naïve Permeation Lag Corrections | CA1: Permeation Lag as Uncertainty
A2: HeRefNo | B2: Name | C2: Time (Pump out) | D2: Temperature (C) | E2: Nominal (Heated) Time (Minutes) | F2: Type | G2: 3He cps | H2: 4He Overspray cps | I2: 4He fA | J2: Nominal (Heated) Time (seconds) | K2: Watlow Time (seconds) | L2: Total Time (seconds) | M2: Cooling Time (seconds) | O2: Sensitivity 3He (pccSTP/cps) | P2: Sensitivity 4He (nccSTP/cps) | R2: 3He measured (pccSTP) | S2: 2σ | T2: 4He measured (nccSTP) | U2: 2σ | W2: R/Rbulk no 4He Blank Correction | Y2: 4He Blank Corrected (nccSTP) | Z2: 2σ | AB2: Blank Corrected 4He/3He | AC2: 2σ | AD2: Blank Corrected R/Rbulk | AE2: 2σ | AG2: 3He pccSTP Bracketing Corrected | AH2: 2σ | AI2: 4He nccSTP Bracketing Corrected | AJ2: 2σ | AL2: R 4He/3He | AM2: 2σ | AN2: R/Rbulk | AO2: 2σ | AQ2: 3He Cumulative Naïve Corrected | AR2: 2σ | AS2: 4He Cumulative Naïve Corrected | AT2: 2σ | AU2: 3He Cumulative Measured | AW2: 4He Cumulative Measured | AZ2: 3He ln(K) Apparent Permeability (atoms/(atm*cm*s)) | BA2: 1σ | BB2: 3He K Apparent Permeability (atoms/(atm*cm*s)) | BC2: 1σ | BD2: λ = (KGRT) | BF2: K 4He Swets | BG2: K 3He Jones and Swets | BH2: GRT | BJ2: 3He n0 calc (pccSTP) (m/(1-e^-λt)) | BK2: 2σ | BL2: 3He n0 calc long cool | BM2: 2σ | BN2: 3He n0 (pccSTP) | BO2: 2σ | BP2: 3He Corrected (pccSTP) | BQ2: 2σ | BR2: 3He Correction % | BT2: 4He n0 by ratio (nccSTP) | BU2: 2σ | BV2: 4He n0 (nccSTP)) | BW2: 2σ | BX2: 4He Corrected (nccSTP) | BY2: 2σ | BZ2: 4He Correction % | CA2: 3He ntUB | CB2: lambdat 3He | CC2: ntUB/m | CD2: 4He ntUB | CE2: lambdat 4He | CF2: 4He ntUB/m | CG2: 3He ωLB | CH2: 3He ωUB | CI2: 4He ωLB | CJ2: 4He ωUB | CK2: lambdat 3He maxR | CL2: 3He ntUB (for ratios) | CM2: 4/3 R m | CN2: R nt extreme | CO2: R n0 extreme | CP2: R Both extreme | CQ2: R UB | CR2: R LB | CS2: 26°C Permeability Solution
C3: 45322.724
A4: He30238.txt | B4: IrrWin0601bTube012624: 6305_60.0_21.0 28.45 (Blank) | C4: 45322.783 | D4: 28.45 | E4: =J4/60 -> 60 | F4: Blank | G4: -0.00395 | H4: 0 | I4: 0.0484 | J4: 3600 | K4: 3729.804 | L4: =(C4-C3)*24*3600 -> 5160 | M4: =L4-J4 -> 1560 | O4: 0.0062528858 | P4: 0.025735294 | R4: -2.4698899e-05 | S4: -3.6340364e-07 | T4: 0.0012455882 | U4: 6.2576911e-06 | AZ4: ='Naive Apparent Lambdas'!$U$2*(10000/(D4+273))+'Naive Apparent Lambdas'!$V$2 -> 22.195671 | BA4: ='Naive Apparent Lambdas'!$V$4 -> 0.067480704 | BB4: =EXP(AZ4) -> 4.3597082e+09 | BC4: =BA4*BB4 -> 2.9419618e+08 | BD4: =BB4*(D4+273)*$D$145*$F$144 -> 1.2523685e-06 | BH4: =(D4+273)*$D$145*$F$144 -> 2.8725972e-16
A5: He30241.txt | B5: IrrWin0601bTube012624: 8305_300.0_170.0 170.00 | C5: 45323.01 | D5: 170 | E5: =J5/60 -> 300 | F5: Experimental | G5: 154 | H5: 0 | I5: 0.745 | J5: 18000 | K5: 18061.083 | L5: =(C5-C4)*24*3600 -> 19560 | M5: =L5-J5 -> 1560 | O5: 0.0062529637 | P5: 0.02577444 | R5: 0.96295642 | S5: 0.014075295 | T5: 0.019201958 | U5: 8.1384482e-05 | W5: =(1000*T5/R5)/$AG$140 -> 0.019986198 | Y5: =T5-AVERAGE(T6:T8) -> 0.013769741 | Z5: =U5+AVERAGE(T6:T8) -> 0.0055136015 | AB5: =(Y5*1000)/R5 -> 14.299443 | AC5: =2*((1000*Z5/(2*R5))^2+((S5/2)*1000*Y5/(R5^2))^2)^0.5 -> 5.7295156 | AD5: =AB5/$AG$140 -> 0.01433212 | AE5: =2*(($AH$140*AB5/(2*$AG$140^2))^2+(AC5/($AG$140*2))^2)^0.5 -> 0.005744651 | AG5: {=BP5:BQ5} -> 1.1597312 | AH5: 0.026265117 | AI5: {=BX5:BY5} -> 0.016870654 | AJ5: 0.0056870596 | AL5: =1000*AI5/AG5 -> 14.547038 | AM5: =2*((AH5*1000*AI5/(2*AG5^2))^2+(1000*AJ5/(AG5*2))^2)^0.5 -> 4.9148285 | AN5: =AL5/$AG$140 -> 0.014580281 | AO5: =2*(($AH$140*AL5/(2*$AG$140^2))^2+(AM5/($AG$140*2))^2)^0.5 -> 0.0049285237 | AQ5: =SUM(BP$5:$BP5) -> 1.1597312 | AR5: {=2*SQRT(SUM((BQ$5:$BQ5/2)^2))} -> 0.026265117 | AS5: =SUM($BX$5:BX5) -> 0.016870654 | AT5: {=2*SQRT(SUM(($BY$5:BY5/2)^2))} -> 0.0056870596 | AU5: =R5 -> 0.96295642 | AW5: =T5 -> 0.019201958 | BF5: =IF((273+D5)>=600, 0.00074*EXP(-6613/(1.987*(273+D5)))*128000000000000000*EXP(1174/(1.987*(273+D5))), 0.000304*EXP(-5580/(1.987*(273+D5)))*199000000000000000*EXP(680/(1.987*(273+D5)))) -> 2.3129067e+11 | BG5: =BF5 * 1.17*EXP(-57/(1.987*(273+D5))) -> 2.5364204e+11 | BH5: =(D5+273)*$D$145*$F$144 -> 4.2214648e-16 | BP5: =R5+BN6-BN5 -> 1.1597312 | BQ5: =2*(((BO5/2)^2+(BO6/2)^2+(S5/2)^2)^(0.5)) -> 0.026265117 | BR5: =100*(BP5-R5)/R5 -> 20.434444 | BV5: 0 | BW5: 0 | BX5: =Y5+BV6-BV5 -> 0.016870654 | BY5: =2*(((BW5/2)^2+(BW6/2)^2+(Z5/2)^2)^(0.5)) -> 0.0056870596 | BZ5: =100*(BX5-Y5)/Y5 -> 22.519764 | CA5: =R5*CC5 -> 1.0384142 | CB5: =BH5*BG5*J5 -> 1.9273337 | CC5: =1/(CB5-1) -> 1.0783605 | CD5: =CF5*T5 -> 0.025349329 | CE5: =BH5*BF5*J5 -> 1.7574937 | CF5: =1/(CE5-1) -> 1.320143 | CK5: =CE5*1.29 -> 2.2671669 | CM5: =1000*T5/R5 -> 19.94063
A6: He30244.txt | B6: IrrWin0601bTube012624: 1005_150.0_100.0 100.00 | C6: 45323.132 | D6: 100 | E6: =J6/60 -> 150 | F6: Informed Bracket | G6: 9.62 | H6: 0 | I6: 0.129 | J6: 9000 | K6: 9035.296 | L6: =(C6-C5)*24*3600 -> 10560 | M6: =L6-J6 -> 1560 | O6: 0.0062521891 | P6: 0.025777414 | R6: 0.06014606 | S6: 0.00083352383 | T6: 0.0033252864 | U6: 1.4783904e-05 | AQ6: =SUM(BP$5:$BP6) -> 1.1597312 | AR6: {=2*SQRT(SUM((BQ$5:$BQ6/2)^2))} -> 0.026265117 | AS6: =SUM($BX$5:BX6) -> 0.016870654 | AT6: {=2*SQRT(SUM(($BY$5:BY6/2)^2))} -> 0.0056870596 | AU6: =AU5+R6 -> 1.0231025 | AW6: =AW5+T6 -> 0.022527244 | AZ6: ='Naive Apparent Lambdas'!$U$2*(10000/(D6+273))+'Naive Apparent Lambdas'!$V$2 -> 25.459765 | BA6: ='Naive Apparent Lambdas'!$V$4 -> 0.067480704 | BB6: =EXP(AZ6) -> 1.1403424e+11 | BC6: =BA6*BB6 -> 7.6951106e+09 | BD6: =BB6*(D6+273)*$D$145*$F$144 -> 4.0532513e-05 | BF6: =IF((273+D6)>=600, 0.00074*EXP(-6613/(1.987*(273+D6)))*128000000000000000*EXP(1174/(1.987*(273+D6))), 0.000304*EXP(-5580/(1.987*(273+D6)))*199000000000000000*EXP(680/(1.987*(273+D6)))) -> 8.1368988e+10 | BG6: =BF6 * 1.17*EXP(-57/(1.987*(273+D6))) -> 8.8154465e+10 | BH6: =(D6+273)*$D$145*$F$144 -> 3.5544161e-16 | BJ6: =R6/(1-EXP(-E6*60*BD6)) -> 0.19677479 | BK6: =2*SQRT( ((S6/2) * (1 / (1 - EXP(-E6 * 60 * BB6 * BH6))))^2 + (BC6 * (-R6 * 60 * E6 * BH6 * EXP(-E6 * 60 * BB6 * BH6) / (1 - EXP(-E6 * 60 * BB6 * BH6))^2))^2 ) -> 0.022175267 | BL6: =R6/(1-EXP(-E6*60*BB6*BH6)*EXP(-(M6-1560)*$CW$126*$BH$122)) -> 0.19677479 | BM6: =2*SQRT( ((S6/2) * (1 / (1 - EXP(-E6 * 60 * BB6 * BH6) * EXP(-(M6 - 1560) * $CW$126 * $BH$48))))^2 + (BC6 * (-R6 * 60 * E6 * BH6 * EXP(-E6 * 60 * BB6 * BH6) / ((1 - EXP(-E6 * 60 * BB6 * BH6) * EXP(-(M6 - 1560) * $CW$126 * $BH$48))^2)))^2 + ($CX$126 * (-R6 * (M6 - 1560) * $BH$48 * EXP(-(M6 - 1560) * $CW$126 * $BH$48) / ((1 - EXP(-E6 * 60 * BB6 * BH6) * EXP(-(M6 - 1560) * $CW$126 * $BH$48))^2)))^2 ) -> 0.022175267 | BN6: =BJ6 -> 0.19677479 | BO6: =BK6 -> 0.022175267 | BT6: =BN6*(Y5/R5)*1.10204926384627 -> 0.0031009131 | BU6: =2*(((BO6/2)*1.10204926384627*(AB5/(1000)))^2+((AC5/2000)*1.10204926384627*BN6)^2+((0.187040260207234/2)*BN6*(AB5/(1000)))^2)^0.5 -> 0.0013938601 | BV6: =BT6 -> 0.0031009131 | BW6: =BU6 -> 0.0013938601 | CA6: =CA5*(EXP(-BH6*BG6*E6))*(EXP(-$BG$140*$F$144*D145*(24+273)*M6)) -> 1.0263056 | CD6: =CD5*(EXP(-BH6*BF6*E6))*(EXP(-$BF$140*$F$144*D145*(24+273)*M6)) -> 0.025073135
A7: He30247.txt | B7: IrrWin0601bTube012624: 1205_150.0_100.0 99.99 | C7: 45323.254 | D7: 99.99 | E7: =J7/60 -> 150 | G7: 5.53 | H7: 0 | I7: 0.0402 | J7: 9000 | K7: 9026.505 | L7: =(C7-C6)*24*3600 -> 10560 | M7: =L7-J7 -> 1560 | O7: 0.0062521891 | P7: 0.025777414 | R7: 0.034574606 | S7: 0.0004688042 | T7: 0.001036252 | U7: 4.6042688e-06 | AQ7: =SUM(BP$5:$BP7) -> 1.1597312 | AR7: {=2*SQRT(SUM((BQ$5:$BQ7/2)^2))} -> 0.026265117 | AS7: =SUM($BX$5:BX7) -> 0.016870654 | AT7: {=2*SQRT(SUM(($BY$5:BY7/2)^2))} -> 0.0056870596 | AU7: =AU6+R7 -> 1.0576771 | AW7: =AW6+T7 -> 0.023563496 | AZ7: ='Naive Apparent Lambdas'!$U$2*(10000/(D7+273))+'Naive Apparent Lambdas'!$V$2 -> 25.459396 | BA7: ='Naive Apparent Lambdas'!$V$4 -> 0.067480704 | BB7: =EXP(AZ7) -> 1.139922e+11 | BC7: =BA7*BB7 -> 7.692274e+09 | BD7: =BB7*(D7+273)*$D$145*$F$144 -> 4.0516486e-05 | BF7: =IF((273+D7)>=600, 0.00074*EXP(-6613/(1.987*(273+D7)))*128000000000000000*EXP(1174/(1.987*(273+D7))), 0.000304*EXP(-5580/(1.987*(273+D7)))*199000000000000000*EXP(680/(1.987*(273+D7)))) -> 8.1354566e+10 | BG7: =BF7 * 1.17*EXP(-57/(1.987*(273+D7))) -> 8.8138659e+10 | BH7: =(D7+273)*$D$145*$F$144 -> 3.5543209e-16 | BJ7: =R7/(1-EXP(-E7*60*BD7)) -> 0.1131519 | BK7: =2*SQRT( ((S7/2) * (1 / (1 - EXP(-E7 * 60 * BB7 * BH7))))^2 + (BC7 * (-R7 * 60 * E7 * BH7 * EXP(-E7 * 60 * BB7 * BH7) / (1 - EXP(-E7 * 60 * BB7 * BH7))^2))^2 ) -> 0.012748343 | BL7: =R7/(1-EXP(-E7*60*BB7*BH7)*EXP(-(M7-1560)*$CW$126*$BH$122)) -> 0.1131519 | BM7: =2*SQRT( ((S7/2) * (1 / (1 - EXP(-E7 * 60 * BB7 * BH7) * EXP(-(M7 - 1560) * $CW$126 * $BH$48))))^2 + (BC7 * (-R7 * 60 * E7 * BH7 * EXP(-E7 * 60 * BB7 * BH7) / ((1 - EXP(-E7 * 60 * BB7 * BH7) * EXP(-(M7 - 1560) * $CW$126 * $BH$48))^2)))^2 + ($CX$126 * (-R7 * (M7 - 1560) * $BH$48 * EXP(-(M7 - 1560) * $CW$126 * $BH$48) / ((1 - EXP(-E7 * 60 * BB7 * BH7) * EXP(-(M7 - 1560) * $CW$126 * $BH$48))^2)))^2 ) -> 0.012748343 | BN7: =BN6*EXP(-BD6*E6*60) -> 0.13662873 | BO7: =2*((((BO6/2)*EXP(-BD6*E6*60))^2+(BN6*EXP(-BD6*E6*60)*E6*60*BC6*BD6/BB6)^2)^0.5) -> 0.016802411 | BV7: =BV6*EXP(-BB6*BH6*E6*60*0.91357457380209)*EXP(-(M6-1560)*$CW$126*$BH$48*0.91357457380209) -> 0.0022220526 | BW7: =2*SQRT( ((BW6/2) * EXP(-BB6 * BH6 * E6 * 60 * 0.91357457380209) * EXP(-(M6 - 1560) * $CW$126 * $BH$48 * 0.91357457380209))^2 + (BC6 * (-BV6 * BH6 * E6 * 60 * 0.91357457380209 * EXP(-BB6 * BH6 * E6 * 60 * 0.91357457380209) * EXP(-(M6 - 1560) * $CW$126 * $BH$48 * 0.91357457380209)))^2 + ((0.146030972937065 / 2) * BV6 * (-BB6 * BH6 * E6 * 60 - (M6 - 1560) * $CW$126 * $BH$48) * EXP(-BB6 * BH6 * E6 * 60 * 0.91357457380209) * EXP(-(M6 - 1560) * $CW$126 * $BH$48 * 0.91357457380209))^2 + -(M6-1560)*$BH$48*0.91357457380209*BV6*EXP(-BB6*BH6*E6*60*0.91357457380209)*EXP(-(M6-1560)*$CW$126*$BH$48*0.91357457380209)) -> 0.0010107555 | CA7: =CA6*(EXP(-BH7*BG7*E7))*(EXP(-$BG$140*$F$144*D146*(24+273)*M7)) -> 1.0214942 | CD7: =CD6*(EXP(-BH7*BF7*E7))*(EXP(-$BF$140*$F$144*D146*(24+273)*M7)) -> 0.024964618
A8: He30250.txt | B8: IrrWin0601bTube012624: 1405_150.0_100.0 99.99 | C8: 45323.382 | D8: 99.99 | E8: =J8/60 -> 150 | G8: 3.56 | H8: 0 | I8: 0.463 | J8: 9000 | K8: 9018.104 | L8: =(C8-C7)*24*3600 -> 11040 | M8: =L8-J8 -> 2040 | O8: 0.0062521243 | P8: 0.025777781 | R8: 0.022257563 | S8: 0.00031133036 | T8: 0.011935112 | U8: 4.9936245e-05 | AQ8: =SUM(BP$5:$BP8) -> 1.1597312 | AR8: {=2*SQRT(SUM((BQ$5:$BQ8/2)^2))} -> 0.026265117 | AS8: =SUM($BX$5:BX8) -> 0.016870654 | AT8: {=2*SQRT(SUM(($BY$5:BY8/2)^2))} -> 0.0056870596 | AU8: =AU7+R8 -> 1.0799346 | AW8: =AW7+T8 -> 0.035498608 | AZ8: ='Naive Apparent Lambdas'!$U$2*(10000/(D8+273))+'Naive Apparent Lambdas'!$V$2 -> 25.459396 | BA8: ='Naive Apparent Lambdas'!$V$4 -> 0.067480704 | BB8: =EXP(AZ8) -> 1.139922e+11 | BC8: =BA8*BB8 -> 7.692274e+09 | BD8: =BB8*(D8+273)*$D$145*$F$144 -> 4.0516486e-05 | BF8: =IF((273+D8)>=600, 0.00074*EXP(-6613/(1.987*(273+D8)))*128000000000000000*EXP(1174/(1.987*(273+D8))), 0.000304*EXP(-5580/(1.987*(273+D8)))*199000000000000000*EXP(680/(1.987*(273+D8)))) -> 8.1354566e+10 | BG8: =BF8 * 1.17*EXP(-57/(1.987*(273+D8))) -> 8.8138659e+10 | BH8: =(D8+273)*$D$145*$F$144 -> 3.5543209e-16 | BJ8: =R8/(1-EXP(-E8*60*BD8)) -> 0.072842062 | BK8: =2*SQRT( ((S8/2) * (1 / (1 - EXP(-E8 * 60 * BB8 * BH8))))^2 + (BC8 * (-R8 * 60 * E8 * BH8 * EXP(-E8 * 60 * BB8 * BH8) / (1 - EXP(-E8 * 60 * BB8 * BH8))^2))^2 ) -> 0.0082106187 | BL8: =R8/(1-EXP(-E8*60*BB8*BH8)*EXP(-(M8-1560)*$CW$126*$BH$122)) -> 0.072266942 | BM8: =2*SQRT( ((S8/2) * (1 / (1 - EXP(-E8 * 60 * BB8 * BH8) * EXP(-(M8 - 1560) * $CW$126 * $BH$48))))^2 + (BC8 * (-R8 * 60 * E8 * BH8 * EXP(-E8 * 60 * BB8 * BH8) / ((1 - EXP(-E8 * 60 * BB8 * BH8) * EXP(-(M8 - 1560) * $CW$126 * $BH$48))^2)))^2 + ($CX$126 * (-R8 * (M8 - 1560) * $BH$48 * EXP(-(M8 - 1560) * $CW$126 * $BH$48) / ((1 - EXP(-E8 * 60 * BB8 * BH8) * EXP(-(M8 - 1560) * $CW$126 * $BH$48))^2)))^2 ) -> 0.0080861514 | BN8: =BN7*EXP(-BD7*E7*60) -> 0.094880566 | BO8: =2*((((BO7/2)*EXP(-BD7*E7*60))^2+(BN7*EXP(-BD7*E7*60)*E7*60*BC7*BD7/BB7)^2)^0.5) -> 0.012567897 | BV8: =BV7*EXP(-BB7*BH7*E7*60*0.91357457380209)*EXP(-(M7-1560)*$CW$126*$BH$48*0.91357457380209) -> 0.0015924885 | BW8: =2*SQRT( ((BW7/2) * EXP(-BB7 * BH7 * E7 * 60 * 0.91357457380209) * EXP(-(M7 - 1560) * $CW$126 * $BH$48 * 0.91357457380209))^2 + (BC7 * (-BV7 * BH7 * E7 * 60 * 0.91357457380209 * EXP(-BB7 * BH7 * E7 * 60 * 0.91357457380209) * EXP(-(M7 - 1560) * $CW$126 * $BH$48 * 0.91357457380209)))^2 + ((0.146030972937065 / 2) * BV7 * (-BB7 * BH7 * E7 * 60 - (M7 - 1560) * $CW$126 * $BH$48) * EXP(-BB7 * BH7 * E7 * 60 * 0.91357457380209) * EXP(-(M7 - 1560) * $CW$126 * $BH$48 * 0.91357457380209))^2 + -(M7-1560)*$BH$48*0.91357457380209*BV7*EXP(-BB7*BH7*E7*60*0.91357457380209)*EXP(-(M7-1560)*$CW$126*$BH$48*0.91357457380209)) -> 0.00073283537 | CA8: =CA7*(EXP(-BH8*BG8*E8))*(EXP(-$BG$140*$F$144*D147*(24+273)*M8)) -> 1.0167053 | CD8: =CD7*(EXP(-BH8*BF8*E8))*(EXP(-$BF$140*$F$144*D147*(24+273)*M8)) -> 0.024856571
A9: He30255.txt | B9: IrrWin0601bTube012624: 1605_463.0_180.0 180.0 | C9: 45323.818 | D9: 180 | E9: =J9/60 -> 463 | F9: Experimental | G9: 87.3 | H9: 0 | I9: 1.18 | J9: 27780 | K9: 27819.784 | L9: =(C9-C8)*24*3600 -> 37680 | M9: =L9-J9 -> 9900 | O9: 0.0062334954 | P9: 0.025819672 | R9: 0.54418415 | S9: 0.00820917 | T9: 0.030467213 | U9: 0.00012198189 | W9: =(1000*T9/R9)/$AG$140 -> 0.056114896 | Y9: =T9-AVERAGE(T10:T12) -> 0.025207708 | Z9: =U9+AVERAGE(T10:T12) -> 0.0053814874 | AB9: =(Y9*1000)/R9 -> 46.322017 | AC9: =2*((1000*Z9/(2*R9))^2+((S9/2)*1000*Y9/(R9^2))^2)^0.5 -> 9.9137503 | AD9: =AB9/$AG$140 -> 0.046427873 | AE9: =2*(($AH$140*AB9/(2*$AG$140^2))^2+(AC9/($AG$140*2))^2)^0.5 -> 0.0099487859 | AG9: {=BP9:BQ9} -> 0.54972141 | AH9: 0.016048764 | AI9: {=BX9:BY9} -> 0.028060078 | AJ9: 0.0055219516 | AL9: =1000*AI9/AG9 -> 51.044178 | AM9: =2*((AH9*1000*AI9/(2*AG9^2))^2+(1000*AJ9/(AG9*2))^2)^0.5 -> 10.154936 | AN9: =AL9/$AG$140 -> 0.051160825 | AO9: =2*(($AH$140*AL9/(2*$AG$140^2))^2+(AM9/($AG$140*2))^2)^0.5 -> 0.010192817 | AQ9: =SUM(BP$5:$BP9) -> 1.7094526 | AR9: {=2*SQRT(SUM((BQ$5:$BQ9/2)^2))} -> 0.030780176 | AS9: =SUM($BX$5:BX9) -> 0.044930732 | AT9: {=2*SQRT(SUM(($BY$5:BY9/2)^2))} -> 0.0079268277 | AU9: =AU8+R9 -> 1.6241188 | AW9: =AW8+T9 -> 0.065965822 | BF9: =IF((273+D9)>=600, 0.00074*EXP(-6613/(1.987*(273+D9)))*128000000000000000*EXP(1174/(1.987*(273+D9))), 0.000304*EXP(-5580/(1.987*(273+D9)))*199000000000000000*EXP(680/(1.987*(273+D9)))) -> 2.6153274e+11 | BG9: =BF9 * 1.17*EXP(-57/(1.987*(273+D9))) -> 2.8721691e+11 | BH9: =(D9+273)*$D$145*$F$144 -> 4.3167574e-16 | BN9: =BN8-R8 -> 0.072623003 | BO9: =BO8+S8 -> 0.012879228 | BP9: =R9+BN10-BN9 -> 0.54972141 | BQ9: =2*(((BO9/2)^2+(BO10/2)^2+(S9/2)^2)^(0.5)) -> 0.016048764 | BR9: =100*(BP9-R9)/R9 -> 1.0175343 | BV9: =BV8*EXP(-BB8*BH8*E8*60*0.91357457380209)*EXP(-(M8-1560)*$CW$126*$BH$48*0.91357457380209) -> 0.0011376443 | BW9: =2*SQRT( ((BW8/2) * EXP(-BB8 * BH8 * E8 * 60 * 0.91357457380209) * EXP(-(M8 - 1560) * $CW$126 * $BH$48 * 0.91357457380209))^2 + (BC8 * (-BV8 * BH8 * E8 * 60 * 0.91357457380209 * EXP(-BB8 * BH8 * E8 * 60 * 0.91357457380209) * EXP(-(M8 - 1560) * $CW$126 * $BH$48 * 0.91357457380209)))^2 + ((0.146030972937065 / 2) * BV8 * (-BB8 * BH8 * E8 * 60 - (M8 - 1560) * $CW$126 * $BH$48) * EXP(-BB8 * BH8 * E8 * 60 * 0.91357457380209) * EXP(-(M8 - 1560) * $CW$126 * $BH$48 * 0.91357457380209))^2 + -(M8-1560)*$BH$48*0.91357457380209*BV8*EXP(-BB8*BH8*E8*60*0.91357457380209)*EXP(-(M8-1560)*$CW$126*$BH$48*0.91357457380209)) -> 0.00052956058 | BX9: =Y9+BV10-BV9 -> 0.028060078 | BY9: =2*(((BW9/2)^2+(BW10/2)^2+(Z9/2)^2)^(0.5)) -> 0.0055219516 | BZ9: =100*(BX9-Y9)/Y9 -> 11.315469 | CA9: =R9*CC9 -> 0.22263473 | CB9: =BH9*BG9*J9 -> 3.4442914 | CC9: =1/(CB9-1) -> 0.40911652 | CD9: =CF9*T9 -> 0.014261753 | CE9: =BH9*BF9*J9 -> 3.1362881 | CF9: =1/(CE9-1) -> 0.46810166 | CK9: =CE9*1.29 -> 4.0458117 | CM9: =1000*T9/R9 -> 55.986954
A10: He30264.txt | B10: IrrWin0601bTube012624: 2005_150.0_95.0 95.39 | C10: 45324.597 | D10: 95.39 | E10: =J10/60 -> 150 | G10: 6.87 | H10: 0 | I10: 0.326 | J10: 9000 | K10: 65932.549 | L10: =(C10-C9)*24*3600 -> 67320 | M10: =L10-J10 -> 58320 | O10: 0.0062327767 | P10: 0.025824355 | R10: 0.042819176 | S10: 0.00078537599 | T10: 0.0084187396 | U10: 3.2756365e-05 | AQ10: =SUM(BP$5:$BP10) -> 1.7094526 | AR10: {=2*SQRT(SUM((BQ$5:$BQ10/2)^2))} -> 0.030780176 | AS10: =SUM($BX$5:BX10) -> 0.044930732 | AT10: {=2*SQRT(SUM(($BY$5:BY10/2)^2))} -> 0.0079268277 | AU10: =AU9+R10 -> 1.666938 | AW10: =AW9+T10 -> 0.074384561 | AZ10: ='Naive Apparent Lambdas'!$U$2*(10000/(D10+273))+'Naive Apparent Lambdas'!$V$2 -> 25.287672 | BA10: ='Naive Apparent Lambdas'!$V$4 -> 0.067480704 | BB10: =EXP(AZ10) -> 9.6005595e+10 | BC10: =BA10*BB10 -> 6.4785251e+09 | BD10: =BB10*(D10+273)*$D$145*$F$144 -> 3.3702632e-05 | BF10: =IF((273+D10)>=600, 0.00074*EXP(-6613/(1.987*(273+D10)))*128000000000000000*EXP(1174/(1.987*(273+D10))), 0.000304*EXP(-5580/(1.987*(273+D10)))*199000000000000000*EXP(680/(1.987*(273+D10)))) -> 7.4907986e+10 | BG10: =BF10 * 1.17*EXP(-57/(1.987*(273+D10))) -> 8.1076604e+10 | BH10: =(D10+273)*$D$145*$F$144 -> 3.5104862e-16 | BJ10: =R10/(1-EXP(-E10*60*BD10)) -> 0.16365688 | BK10: =2*SQRT( ((S10/2) * (1 / (1 - EXP(-E10 * 60 * BB10 * BH10))))^2 + (BC10 * (-R10 * 60 * E10 * BH10 * EXP(-E10 * 60 * BB10 * BH10) / (1 - EXP(-E10 * 60 * BB10 * BH10))^2))^2 ) -> 0.019143445 | BL10: =R10/(1-EXP(-E10*60*BB10*BH10)*EXP(-(M10-1560)*$CW$126*$BH$122)) -> 0.083576538 | BM10: =2*SQRT( ((S10/2) * (1 / (1 - EXP(-E10 * 60 * BB10 * BH10) * EXP(-(M10 - 1560) * $CW$126 * $BH$48))))^2 + (BC10 * (-R10 * 60 * E10 * BH10 * EXP(-E10 * 60 * BB10 * BH10) / ((1 - EXP(-E10 * 60 * BB10 * BH10) * EXP(-(M10 - 1560) * $CW$126 * $BH$48))^2)))^2 + ($CX$126 * (-R10 * (M10 - 1560) * $BH$48 * EXP(-(M10 - 1560) * $CW$126 * $BH$48) / ((1 - EXP(-E10 * 60 * BB10 * BH10) * EXP(-(M10 - 1560) * $CW$126 * $BH$48))^2)))^2 ) -> 0.014258045 | BN10: =BN11+R10 -> 0.078160263 | BO10: =BO11+S10 -> 0.004929285 | BT10: =BN10*(Y9/R9)*1.10204926384627 -> 0.0039900146 | BU10: =2*(((BO10/2)*1.10204926384627*(AB9/(1000)))^2+((AC9/2000)*1.10204926384627*BN10)^2+((0.187040260207234/2)*BN10*(AB9/(1000)))^2)^0.5 -> 0.0011185295 | BV10: =BT10 -> 0.0039900146 | BW10: =BU10 -> 0.0011185295 | CA10: =CA9*(EXP(-BH10*BG10*E10))*(EXP(-$BG$140*$F$144*D149*(24+273)*M10)) -> 0.22168627 | CD10: =CD9*(EXP(-BH10*BF10*E10))*(EXP(-$BF$140*$F$144*D149*(24+273)*M10)) -> 0.014205609
A11: He30266.txt | B11: IrrWin0601bTube012624: 2605_150.0_95.0 95.00 | C11: 45324.719 | D11: 95 | E11: =J11/60 -> 150 | F11: Informed Bracket | G11: 1.46 | H11: 0 | I11: 0.0296 | J11: 9000 | K11: 9038.848 | L11: =(C11-C10)*24*3600 -> 10560 | M11: =L11-J11 -> 1560 | O11: 0.0062480449 | P11: 0.025854018 | R11: 0.0091221455 | S11: 0.00016709173 | T11: 0.00076527892 | U11: 2.9757551e-06 | AQ11: =SUM(BP$5:$BP11) -> 1.7094526 | AR11: {=2*SQRT(SUM((BQ$5:$BQ11/2)^2))} -> 0.030780176 | AS11: =SUM($BX$5:BX11) -> 0.044930732 | AT11: {=2*SQRT(SUM(($BY$5:BY11/2)^2))} -> 0.0079268277 | AU11: =AU10+R11 -> 1.6760601 | AW11: =AW10+T11 -> 0.07514984 | AZ11: ='Naive Apparent Lambdas'!$U$2*(10000/(D11+273))+'Naive Apparent Lambdas'!$V$2 -> 25.272916 | BA11: ='Naive Apparent Lambdas'!$V$4 -> 0.067480704 | BB11: =EXP(AZ11) -> 9.4599281e+10 | BC11: =BA11*BB11 -> 6.3836261e+09 | BD11: =BB11*(D11+273)*$D$145*$F$144 -> 3.317379e-05 | BF11: =IF((273+D11)>=600, 0.00074*EXP(-6613/(1.987*(273+D11)))*128000000000000000*EXP(1174/(1.987*(273+D11))), 0.000304*EXP(-5580/(1.987*(273+D11)))*199000000000000000*EXP(680/(1.987*(273+D11)))) -> 7.437845e+10 | BG11: =BF11 * 1.17*EXP(-57/(1.987*(273+D11))) -> 8.0496818e+10 | BH11: =(D11+273)*$D$145*$F$144 -> 3.5067698e-16 | BJ11: =R11/(1-EXP(-E11*60*BD11)) -> 0.035341088 | BK11: =2*SQRT( ((S11/2) * (1 / (1 - EXP(-E11 * 60 * BB11 * BH11))))^2 + (BC11 * (-R11 * 60 * E11 * BH11 * EXP(-E11 * 60 * BB11 * BH11) / (1 - EXP(-E11 * 60 * BB11 * BH11))^2))^2 ) -> 0.004143909 | BL11: =R11/(1-EXP(-E11*60*BB11*BH11)*EXP(-(M11-1560)*$CW$126*$BH$122)) -> 0.035341088 | BM11: =2*SQRT( ((S11/2) * (1 / (1 - EXP(-E11 * 60 * BB11 * BH11) * EXP(-(M11 - 1560) * $CW$126 * $BH$48))))^2 + (BC11 * (-R11 * 60 * E11 * BH11 * EXP(-E11 * 60 * BB11 * BH11) / ((1 - EXP(-E11 * 60 * BB11 * BH11) * EXP(-(M11 - 1560) * $CW$126 * $BH$48))^2)))^2 + ($CX$126 * (-R11 * (M11 - 1560) * $BH$48 * EXP(-(M11 - 1560) * $CW$126 * $BH$48) / ((1 - EXP(-E11 * 60 * BB11 * BH11) * EXP(-(M11 - 1560) * $CW$126 * $BH$48))^2)))^2 ) -> 0.004143909 | BN11: =BJ11 -> 0.035341088 | BO11: =BK11 -> 0.004143909 | BV11: =BV10*EXP(-BB10*BH10*E10*60*0.91357457380209)*EXP(-(M10-1560)*$CW$126*$BH$48*0.91357457380209) -> 0.0020703816 | BW11: =2*SQRT( ((BW10/2) * EXP(-BB10 * BH10 * E10 * 60 * 0.91357457380209) * EXP(-(M10 - 1560) * $CW$126 * $BH$48 * 0.91357457380209))^2 + (BC10 * (-BV10 * BH10 * E10 * 60 * 0.91357457380209 * EXP(-BB10 * BH10 * E10 * 60 * 0.91357457380209) * EXP(-(M10 - 1560) * $CW$126 * $BH$48 * 0.91357457380209)))^2 + ((0.146030972937065 / 2) * BV10 * (-BB10 * BH10 * E10 * 60 - (M10 - 1560) * $CW$126 * $BH$48) * EXP(-BB10 * BH10 * E10 * 60 * 0.91357457380209) * EXP(-(M10 - 1560) * $CW$126 * $BH$48 * 0.91357457380209))^2 + -(M10-1560)*$BH$48*0.91357457380209*BV10*EXP(-BB10*BH10*E10*60*0.91357457380209)*EXP(-(M10-1560)*$CW$126*$BH$48*0.91357457380209)) -> 0.00062449461 | CA11: =CA10*(EXP(-BH11*BG11*E11))*(EXP(-$BG$140*$F$144*D150*(24+273)*M11)) -> 0.22074957 | CD11: =CD10*(EXP(-BH11*BF11*E11))*(EXP(-$BF$140*$F$144*D150*(24+273)*M11)) -> 0.014150139
A12: He30268.txt | B12: IrrWin0601bTube012624: 2805_150.0_95.0 95.00 | C12: 45324.842 | D12: 95 | E12: =J12/60 -> 150 | G12: 0.955 | H12: 0 | I12: 0.255 | J12: 9000 | K12: 9037.724 | L12: =(C12-C11)*24*3600 -> 10620 | M12: =L12-J12 -> 1620 | O12: 0.0062505352 | P12: 0.025860777 | R12: 0.0059692611 | S12: 0.00010929331 | T12: 0.0065944981 | U12: 2.5712037e-05 | AQ12: =SUM(BP$5:$BP12) -> 1.7094526 | AR12: {=2*SQRT(SUM((BQ$5:$BQ12/2)^2))} -> 0.030780176 | AS12: =SUM($BX$5:BX12) -> 0.044930732 | AT12: {=2*SQRT(SUM(($BY$5:BY12/2)^2))} -> 0.0079268277 | AU12: =AU11+R12 -> 1.6820294 | AW12: =AW11+T12 -> 0.081744338 | AZ12: ='Naive Apparent Lambdas'!$U$2*(10000/(D12+273))+'Naive Apparent Lambdas'!$V$2 -> 25.272916 | BA12: ='Naive Apparent Lambdas'!$V$4 -> 0.067480704 | BB12: =EXP(AZ12) -> 9.4599281e+10 | BC12: =BA12*BB12 -> 6.3836261e+09 | BD12: =BB12*(D12+273)*$D$145*$F$144 -> 3.317379e-05 | BF12: =IF((273+D12)>=600, 0.00074*EXP(-6613/(1.987*(273+D12)))*128000000000000000*EXP(1174/(1.987*(273+D12))), 0.000304*EXP(-5580/(1.987*(273+D12)))*199000000000000000*EXP(680/(1.987*(273+D12)))) -> 7.437845e+10 | BG12: =BF12 * 1.17*EXP(-57/(1.987*(273+D12))) -> 8.0496818e+10 | BH12: =(D12+273)*$D$145*$F$144 -> 3.5067698e-16 | BJ12: =R12/(1-EXP(-E12*60*BD12)) -> 0.023126158 | BK12: =2*SQRT( ((S12/2) * (1 / (1 - EXP(-E12 * 60 * BB12 * BH12))))^2 + (BC12 * (-R12 * 60 * E12 * BH12 * EXP(-E12 * 60 * BB12 * BH12) / (1 - EXP(-E12 * 60 * BB12 * BH12))^2))^2 ) -> 0.0027116228 | BL12: =R12/(1-EXP(-E12*60*BB12*BH12)*EXP(-(M12-1560)*$CW$126*$BH$122)) -> 0.023097056 | BM12: =2*SQRT( ((S12/2) * (1 / (1 - EXP(-E12 * 60 * BB12 * BH12) * EXP(-(M12 - 1560) * $CW$126 * $BH$48))))^2 + (BC12 * (-R12 * 60 * E12 * BH12 * EXP(-E12 * 60 * BB12 * BH12) / ((1 - EXP(-E12 * 60 * BB12 * BH12) * EXP(-(M12 - 1560) * $CW$126 * $BH$48))^2)))^2 + ($CX$126 * (-R12 * (M12 - 1560) * $BH$48 * EXP(-(M12 - 1560) * $CW$126 * $BH$48) / ((1 - EXP(-E12 * 60 * BB12 * BH12) * EXP(-(M12 - 1560) * $CW$126 * $BH$48))^2)))^2 ) -> 0.0027049106 | BN12: =BN11*EXP(-BD11*E11*60) -> 0.026218942 | BO12: =2*((((BO11/2)*EXP(-BD11*E11*60))^2+(BN11*EXP(-BD11*E11*60)*E11*60*BC11*BD11/BB11)^2)^0.5) -> 0.0032507602 | BV12: =BV11*EXP(-BB11*BH11*E11*60*0.91357457380209)*EXP(-(M11-1560)*$CW$126*$BH$48*0.91357457380209) -> 0.0015761298 | BW12: =2*SQRT( ((BW11/2) * EXP(-BB11 * BH11 * E11 * 60 * 0.91357457380209) * EXP(-(M11 - 1560) * $CW$126 * $BH$48 * 0.91357457380209))^2 + (BC11 * (-BV11 * BH11 * E11 * 60 * 0.91357457380209 * EXP(-BB11 * BH11 * E11 * 60 * 0.91357457380209) * EXP(-(M11 - 1560) * $CW$126 * $BH$48 * 0.91357457380209)))^2 + ((0.146030972937065 / 2) * BV11 * (-BB11 * BH11 * E11 * 60 - (M11 - 1560) * $CW$126 * $BH$48) * EXP(-BB11 * BH11 * E11 * 60 * 0.91357457380209) * EXP(-(M11 - 1560) * $CW$126 * $BH$48 * 0.91357457380209))^2 + -(M11-1560)*$BH$48*0.91357457380209*BV11*EXP(-BB11*BH11*E11*60*0.91357457380209)*EXP(-(M11-1560)*$CW$126*$BH$48*0.91357457380209)) -> 0.00048384437 | CA12: =CA11*(EXP(-BH12*BG12*E12))*(EXP(-$BG$140*$F$144*D151*(24+273)*M12)) -> 0.21981684 | CD12: =CD11*(EXP(-BH12*BF12*E12))*(EXP(-$BF$140*$F$144*D151*(24+273)*M12)) -> 0.014094886
A13: He30273.txt | B13: IrrWin0601bTube012624: 2905_550.0_190.0 190.00 | C13: 45325.242 | D13: 190 | E13: =J13/60 -> 550 | F13: Experimental | G13: 85.1 | H13: 0 | I13: 2.16 | J13: 33000 | K13: 33053.236 | L13: =(C13-C12)*24*3600 -> 34560 | M13: =L13-J13 -> 1560 | O13: 0.0062185856 | P13: 0.025819672 | R13: 0.52920164 | S13: 0.009700757 | T13: 0.055770492 | U13: 0.00023349086 | W13: =(1000*T13/R13)/$AG$140 -> 0.10562692 | Y13: =T13-AVERAGE(T14:T16) -> 0.052428438 | Z13: =U13+AVERAGE(T14:T16) -> 0.0035755443 | AB13: =(Y13*1000)/R13 -> 99.070816 | AC13: =2*((1000*Z13/(2*R13))^2+((S13/2)*1000*Y13/(R13^2))^2)^0.5 -> 6.9962988 | AD13: =AB13/$AG$140 -> 0.099297214 | AE13: =2*(($AH$140*AB13/(2*$AG$140^2))^2+(AC13/($AG$140*2))^2)^0.5 -> 0.0070921291 | AG13: {=BP13:BQ13} -> 0.57769844 | AH13: 0.012950251 | AI13: {=BX13:BY13} -> 0.058647696 | AJ13: 0.0039478232 | AL13: =1000*AI13/AG13 -> 101.51957 | AM13: =2*((AH13*1000*AI13/(2*AG13^2))^2+(1000*AJ13/(AG13*2))^2)^0.5 -> 7.2026851 | AN13: =AL13/$AG$140 -> 0.10175156 | AO13: =2*(($AH$140*AL13/(2*$AG$140^2))^2+(AM13/($AG$140*2))^2)^0.5 -> 0.0073005847 | AQ13: =SUM(BP$5:$BP13) -> 2.2871511 | AR13: {=2*SQRT(SUM((BQ$5:$BQ13/2)^2))} -> 0.033393536 | AS13: =SUM($BX$5:BX13) -> 0.10357843 | AT13: {=2*SQRT(SUM(($BY$5:BY13/2)^2))} -> 0.0088555014 | AU13: =AU12+R13 -> 2.211231 | AW13: =AW12+T13 -> 0.13751483 | BF13: =IF((273+D13)>=600, 0.00074*EXP(-6613/(1.987*(273+D13)))*128000000000000000*EXP(1174/(1.987*(273+D13))), 0.000304*EXP(-5580/(1.987*(273+D13)))*199000000000000000*EXP(680/(1.987*(273+D13)))) -> 2.9416345e+11 | BG13: =BF13 * 1.17*EXP(-57/(1.987*(273+D13))) -> 3.2349431e+11 | BH13: =(D13+273)*$D$145*$F$144 -> 4.4120501e-16 | BN13: =BN12*EXP(-BD12*E12*60) -> 0.01945138 | BO13: =2*((((BO12/2)*EXP(-BD12*E12*60))^2+(BN12*EXP(-BD12*E12*60)*E12*60*BC12*BD12/BB12)^2)^0.5) -> 0.0025358499 | BP13: =R13+BN14-BN13 -> 0.57769844 | BQ13: =2*(((BO13/2)^2+(BO14/2)^2+(S13/2)^2)^(0.5)) -> 0.012950251 | BR13: =100*(BP13-R13)/R13 -> 9.1641445 | BV13: =BV12*EXP(-BB12*BH12*E12*60*0.91357457380209)*EXP(-(M12-1560)*$CW$126*$BH$48*0.91357457380209) -> 0.0011993877 | BW13: =2*SQRT( ((BW12/2) * EXP(-BB12 * BH12 * E12 * 60 * 0.91357457380209) * EXP(-(M12 - 1560) * $CW$126 * $BH$48 * 0.91357457380209))^2 + (BC12 * (-BV12 * BH12 * E12 * 60 * 0.91357457380209 * EXP(-BB12 * BH12 * E12 * 60 * 0.91357457380209) * EXP(-(M12 - 1560) * $CW$126 * $BH$48 * 0.91357457380209)))^2 + ((0.146030972937065 / 2) * BV12 * (-BB12 * BH12 * E12 * 60 - (M12 - 1560) * $CW$126 * $BH$48) * EXP(-BB12 * BH12 * E12 * 60 * 0.91357457380209) * EXP(-(M12 - 1560) * $CW$126 * $BH$48 * 0.91357457380209))^2 + -(M12-1560)*$BH$48*0.91357457380209*BV12*EXP(-BB12*BH12*E12*60*0.91357457380209)*EXP(-(M12-1560)*$CW$126*$BH$48*0.91357457380209)) -> 0.00037450858 | BX13: =Y13+BV14-BV13 -> 0.058647696 | BY13: =2*(((BW13/2)^2+(BW14/2)^2+(Z13/2)^2)^(0.5)) -> 0.0039478232 | BZ13: =100*(BX13-Y13)/Y13 -> 11.862374 | CA13: =R13*CC13 -> 0.14264191 | CB13: =BH13*BG13*J13 -> 4.7100012 | CC13: =1/(CB13-1) -> 0.26954169 | CD13: =CF13*T13 -> 0.016987916 | CE13: =BH13*BF13*J13 -> 4.2829508 | CF13: =1/(CE13-1) -> 0.30460402 | CK13: =CE13*1.29 -> 5.5250065 | CM13: =1000*T13/R13 -> 105.38609
A14: He30275.txt | B14: IrrWin0601bTube012624: 3305_150.0_90.0 90.00 | C14: 45325.364 | D14: 90 | E14: =J14/60 -> 150 | F14: Informed Bracket | G14: 2.35 | H14: 0 | I14: 0.079 | J14: 9000 | K14: 9125.085 | L14: =(C14-C13)*24*3600 -> 10500 | M14: =L14-J14 -> 1500 | O14: 0.0062389603 | P14: 0.025819672 | R14: 0.014661557 | S14: 0.00026841604 | T14: 0.0020397541 | U14: 8.5397121e-06 | AQ14: =SUM(BP$5:$BP14) -> 2.2871511 | AR14: {=2*SQRT(SUM((BQ$5:$BQ14/2)^2))} -> 0.033393536 | AS14: =SUM($BX$5:BX14) -> 0.10357843 | AT14: {=2*SQRT(SUM(($BY$5:BY14/2)^2))} -> 0.0088555014 | AU14: =AU13+R14 -> 2.2258926 | AW14: =AW13+T14 -> 0.13955458 | AZ14: ='Naive Apparent Lambdas'!$U$2*(10000/(D14+273))+'Naive Apparent Lambdas'!$V$2 -> 25.08092 | BA14: ='Naive Apparent Lambdas'!$V$4 -> 0.067480704 | BB14: =EXP(AZ14) -> 7.8073733e+10 | BC14: =BA14*BB14 -> 5.2684704e+09 | BD14: =BB14*(D14+273)*$D$145*$F$144 -> 2.7006668e-05 | BF14: =IF((273+D14)>=600, 0.00074*EXP(-6613/(1.987*(273+D14)))*128000000000000000*EXP(1174/(1.987*(273+D14))), 0.000304*EXP(-5580/(1.987*(273+D14)))*199000000000000000*EXP(680/(1.987*(273+D14)))) -> 6.7820444e+10 | BG14: =BF14 * 1.17*EXP(-57/(1.987*(273+D14))) -> 7.3320582e+10 | BH14: =(D14+273)*$D$145*$F$144 -> 3.4591235e-16 | BJ14: =R14/(1-EXP(-E14*60*BD14)) -> 0.067948183 | BK14: =2*SQRT( ((S14/2) * (1 / (1 - EXP(-E14 * 60 * BB14 * BH14))))^2 + (BC14 * (-R14 * 60 * E14 * BH14 * EXP(-E14 * 60 * BB14 * BH14) / (1 - EXP(-E14 * 60 * BB14 * BH14))^2))^2 ) -> 0.0081959612 | BL14: =R14/(1-EXP(-E14*60*BB14*BH14)*EXP(-(M14-1560)*$CW$126*$BH$122)) -> 0.068056664 | BM14: =2*SQRT( ((S14/2) * (1 / (1 - EXP(-E14 * 60 * BB14 * BH14) * EXP(-(M14 - 1560) * $CW$126 * $BH$48))))^2 + (BC14 * (-R14 * 60 * E14 * BH14 * EXP(-E14 * 60 * BB14 * BH14) / ((1 - EXP(-E14 * 60 * BB14 * BH14) * EXP(-(M14 - 1560) * $CW$126 * $BH$48))^2)))^2 + ($CX$126 * (-R14 * (M14 - 1560) * $BH$48 * EXP(-(M14 - 1560) * $CW$126 * $BH$48) / ((1 - EXP(-E14 * 60 * BB14 * BH14) * EXP(-(M14 - 1560) * $CW$126 * $BH$48))^2)))^2 ) -> 0.0082219538 | BN14: =BJ14 -> 0.067948183 | BO14: =BK14 -> 0.0081959612 | BT14: =BN14*(Y13/R13)*1.10204926384627 -> 0.0074186451 | BU14: =2*(((BO14/2)*1.10204926384627*(AB13/(1000)))^2+((AC13/2000)*1.10204926384627*BN14)^2+((0.187040260207234/2)*BN14*(AB13/(1000)))^2)^0.5 -> 0.0016311145 | BV14: =BT14 -> 0.0074186451 | BW14: =BU14 -> 0.0016311145 | CA14: =CA13*(EXP(-BH14*BG14*E14))*(EXP(-$BG$140*$F$144*D153*(24+273)*M14)) -> 0.14210027 | CD14: =CD13*(EXP(-BH14*BF14*E14))*(EXP(-$BF$140*$F$144*D153*(24+273)*M14)) -> 0.016928241
A15: He30278.txt | B15: IrrWin0601bTube012624: 3505_150.0_90.0 89.99 | C15: 45325.504 | D15: 89.99 | E15: =J15/60 -> 150 | G15: 1.84 | I15: 0.157 | J15: 9000 | K15: 9127.493 | L15: =(C15-C14)*24*3600 -> 12120 | M15: =L15-J15 -> 3120 | O15: 0.00622826 | P15: 0.025832387 | R15: 0.011459998 | S15: 0.00020545162 | T15: 0.0040556848 | U15: 1.6973617e-05 | AQ15: =SUM(BP$5:$BP15) -> 2.2871511 | AR15: {=2*SQRT(SUM((BQ$5:$BQ15/2)^2))} -> 0.033393536 | AS15: =SUM($BX$5:BX15) -> 0.10357843 | AT15: {=2*SQRT(SUM(($BY$5:BY15/2)^2))} -> 0.0088555014 | AU15: =AU14+R15 -> 2.2373526 | AW15: =AW14+T15 -> 0.14361027 | AZ15: ='Naive Apparent Lambdas'!$U$2*(10000/(D15+273))+'Naive Apparent Lambdas'!$V$2 -> 25.08053 | BA15: ='Naive Apparent Lambdas'!$V$4 -> 0.067480704 | BB15: =EXP(AZ15) -> 7.8043345e+10 | BC15: =BA15*BB15 -> 5.2664199e+09 | BD15: =BB15*(D15+273)*$D$145*$F$144 -> 2.6995413e-05 | BF15: =IF((273+D15)>=600, 0.00074*EXP(-6613/(1.987*(273+D15)))*128000000000000000*EXP(1174/(1.987*(273+D15))), 0.000304*EXP(-5580/(1.987*(273+D15)))*199000000000000000*EXP(680/(1.987*(273+D15)))) -> 6.7807752e+10 | BG15: =BF15 * 1.17*EXP(-57/(1.987*(273+D15))) -> 7.3306702e+10 | BH15: =(D15+273)*$D$145*$F$144 -> 3.4590282e-16 | BJ15: =R15/(1-EXP(-E15*60*BD15)) -> 0.053130298 | BK15: =2*SQRT( ((S15/2) * (1 / (1 - EXP(-E15 * 60 * BB15 * BH15))))^2 + (BC15 * (-R15 * 60 * E15 * BH15 * EXP(-E15 * 60 * BB15 * BH15) / (1 - EXP(-E15 * 60 * BB15 * BH15))^2))^2 ) -> 0.0064059155 | BL15: =R15/(1-EXP(-E15*60*BB15*BH15)*EXP(-(M15-1560)*$CW$126*$BH$122)) -> 0.051027038 | BM15: =2*SQRT( ((S15/2) * (1 / (1 - EXP(-E15 * 60 * BB15 * BH15) * EXP(-(M15 - 1560) * $CW$126 * $BH$48))))^2 + (BC15 * (-R15 * 60 * E15 * BH15 * EXP(-E15 * 60 * BB15 * BH15) / ((1 - EXP(-E15 * 60 * BB15 * BH15) * EXP(-(M15 - 1560) * $CW$126 * $BH$48))^2)))^2 + ($CX$126 * (-R15 * (M15 - 1560) * $BH$48 * EXP(-(M15 - 1560) * $CW$126 * $BH$48) / ((1 - EXP(-E15 * 60 * BB15 * BH15) * EXP(-(M15 - 1560) * $CW$126 * $BH$48))^2)))^2 ) -> 0.0059630958 | BN15: =BN14-R14 -> 0.053286626 | BO15: =BO14+S14 -> 0.0084643772 | BV15: =BV14*EXP(-BB14*BH14*E14*60*0.91357457380209)*EXP(-(M14-1560)*$CW$126*$BH$48*0.91357457380209) -> 0.0059437698 | BW15: =2*SQRT( ((BW14/2) * EXP(-BB14 * BH14 * E14 * 60 * 0.91357457380209) * EXP(-(M14 - 1560) * $CW$126 * $BH$48 * 0.91357457380209))^2 + (BC14 * (-BV14 * BH14 * E14 * 60 * 0.91357457380209 * EXP(-BB14 * BH14 * E14 * 60 * 0.91357457380209) * EXP(-(M14 - 1560) * $CW$126 * $BH$48 * 0.91357457380209)))^2 + ((0.146030972937065 / 2) * BV14 * (-BB14 * BH14 * E14 * 60 - (M14 - 1560) * $CW$126 * $BH$48) * EXP(-BB14 * BH14 * E14 * 60 * 0.91357457380209) * EXP(-(M14 - 1560) * $CW$126 * $BH$48 * 0.91357457380209))^2 + -(M14-1560)*$BH$48*0.91357457380209*BV14*EXP(-BB14*BH14*E14*60*0.91357457380209)*EXP(-(M14-1560)*$CW$126*$BH$48*0.91357457380209)) -> 0.0013356284 | CA15: =CA14*(EXP(-BH15*BG15*E15))*(EXP(-$BG$140*$F$144*D154*(24+273)*M15)) -> 0.14156081 | CD15: =CD14*(EXP(-BH15*BF15*E15))*(EXP(-$BF$140*$F$144*D154*(24+273)*M15)) -> 0.016868788
A16: He30280.txt | B16: IrrWin0601bTube012624: 3705_150.0_90.0 90.00 | C16: 45325.626 | D16: 90 | E16: =J16/60 -> 150 | G16: 1.34 | H16: 0 | I16: 0.152 | J16: 9000 | K16: 9130.299 | L16: =(C16-C15)*24*3600 -> 10560 | M16: =L16-J16 -> 1560 | O16: 0.0062000229 | P16: 0.025860009 | R16: 0.0083080307 | S16: 0.00014060465 | T16: 0.0039307213 | U16: 1.6443347e-05 | AQ16: =SUM(BP$5:$BP16) -> 2.2871511 | AR16: {=2*SQRT(SUM((BQ$5:$BQ16/2)^2))} -> 0.033393536 | AS16: =SUM($BX$5:BX16) -> 0.10357843 | AT16: {=2*SQRT(SUM(($BY$5:BY16/2)^2))} -> 0.0088555014 | AU16: =AU15+R16 -> 2.2456606 | AW16: =AW15+T16 -> 0.14754099 | AZ16: ='Naive Apparent Lambdas'!$U$2*(10000/(D16+273))+'Naive Apparent Lambdas'!$V$2 -> 25.08092 | BA16: ='Naive Apparent Lambdas'!$V$4 -> 0.067480704 | BB16: =EXP(AZ16) -> 7.8073733e+10 | BC16: =BA16*BB16 -> 5.2684704e+09 | BD16: =BB16*(D16+273)*$D$145*$F$144 -> 2.7006668e-05 | BF16: =IF((273+D16)>=600, 0.00074*EXP(-6613/(1.987*(273+D16)))*128000000000000000*EXP(1174/(1.987*(273+D16))), 0.000304*EXP(-5580/(1.987*(273+D16)))*199000000000000000*EXP(680/(1.987*(273+D16)))) -> 6.7820444e+10 | BG16: =BF16 * 1.17*EXP(-57/(1.987*(273+D16))) -> 7.3320582e+10 | BH16: =(D16+273)*$D$145*$F$144 -> 3.4591235e-16 | BJ16: =R16/(1-EXP(-E16*60*BD16)) -> 0.038503114 | BK16: =2*SQRT( ((S16/2) * (1 / (1 - EXP(-E16 * 60 * BB16 * BH16))))^2 + (BC16 * (-R16 * 60 * E16 * BH16 * EXP(-E16 * 60 * BB16 * BH16) / (1 - EXP(-E16 * 60 * BB16 * BH16))^2))^2 ) -> 0.0046364885 | BL16: =R16/(1-EXP(-E16*60*BB16*BH16)*EXP(-(M16-1560)*$CW$126*$BH$122)) -> 0.038503114 | BM16: =2*SQRT( ((S16/2) * (1 / (1 - EXP(-E16 * 60 * BB16 * BH16) * EXP(-(M16 - 1560) * $CW$126 * $BH$48))))^2 + (BC16 * (-R16 * 60 * E16 * BH16 * EXP(-E16 * 60 * BB16 * BH16) / ((1 - EXP(-E16 * 60 * BB16 * BH16) * EXP(-(M16 - 1560) * $CW$126 * $BH$48))^2)))^2 + ($CX$126 * (-R16 * (M16 - 1560) * $BH$48 * EXP(-(M16 - 1560) * $CW$126 * $BH$48) / ((1 - EXP(-E16 * 60 * BB16 * BH16) * EXP(-(M16 - 1560) * $CW$126 * $BH$48))^2)))^2 ) -> 0.0046364885 | BN16: =BN15*EXP(-BD15*E15*60) -> 0.041792908 | BO16: =2*((((BO15/2)*EXP(-BD15*E15*60))^2+(BN15*EXP(-BD15*E15*60)*E15*60*BC15*BD15/BB15)^2)^0.5) -> 0.006778611 | BV16: =BV15*EXP(-BB15*BH15*E15*60*0.91357457380209)*EXP(-(M15-1560)*$CW$126*$BH$48*0.91357457380209) -> 0.0047113169 | BW16: =2*SQRT( ((BW15/2) * EXP(-BB15 * BH15 * E15 * 60 * 0.91357457380209) * EXP(-(M15 - 1560) * $CW$126 * $BH$48 * 0.91357457380209))^2 + (BC15 * (-BV15 * BH15 * E15 * 60 * 0.91357457380209 * EXP(-BB15 * BH15 * E15 * 60 * 0.91357457380209) * EXP(-(M15 - 1560) * $CW$126 * $BH$48 * 0.91357457380209)))^2 + ((0.146030972937065 / 2) * BV15 * (-BB15 * BH15 * E15 * 60 - (M15 - 1560) * $CW$126 * $BH$48) * EXP(-BB15 * BH15 * E15 * 60 * 0.91357457380209) * EXP(-(M15 - 1560) * $CW$126 * $BH$48 * 0.91357457380209))^2 + -(M15-1560)*$BH$48*0.91357457380209*BV15*EXP(-BB15*BH15*E15*60*0.91357457380209)*EXP(-(M15-1560)*$CW$126*$BH$48*0.91357457380209)) -> 0.0010822906 | CA16: =CA15*(EXP(-BH16*BG16*E16))*(EXP(-$BG$140*$F$144*D155*(24+273)*M16)) -> 0.14102329 | CD16: =CD15*(EXP(-BH16*BF16*E16))*(EXP(-$BF$140*$F$144*D155*(24+273)*M16)) -> 0.016809531
A17: He30285.txt | B17: IrrWin0601bTube012624: 3905_500.0_200.0 200.00 | C17: 45325.999 | D17: 200 | E17: =J17/60 -> 500 | F17: Experimental | G17: 83.3 | H17: 0.00176 | I17: 3.96 | J17: 30000 | K17: 30127.625 | L17: =(C17-C16)*24*3600 -> 32220 | M17: =L17-J17 -> 2220 | O17: 0.0062299307 | P17: 0.025862069 | R17: 0.51895322 | S17: 0.0082748805 | T17: 0.10241379 | U17: 0.00047358684 | W17: =(1000*T17/R17)/$AG$140 -> 0.19779785 | Y17: =T17-AVERAGE(T18:T20) -> 0.099215344 | Z17: =U17+AVERAGE(T18:T20) -> 0.0036720364 | AB17: =(Y17*1000)/R17 -> 191.1836 | AC17: =2*((1000*Z17/(2*R17))^2+((S17/2)*1000*Y17/(R17^2))^2)^0.5 -> 7.7046059 | AD17: =AB17/$AG$140 -> 0.19162049 | AE17: =2*(($AH$140*AB17/(2*$AG$140^2))^2+(AC17/($AG$140*2))^2)^0.5 -> 0.0079891346 | AG17: {=BP17:BQ17} -> 0.53936148 | AH17: 0.011455178 | AI17: {=BX17:BY17} -> 0.10664756 | AJ17: 0.004423375 | AL17: =1000*AI17/AG17 -> 197.72929 | AM17: =2*((AH17*1000*AI17/(2*AG17^2))^2+(1000*AJ17/(AG17*2))^2)^0.5 -> 9.2137936 | AN17: =AL17/$AG$140 -> 0.19818114 | AO17: =2*(($AH$140*AL17/(2*$AG$140^2))^2+(AM17/($AG$140*2))^2)^0.5 -> 0.0094746095 | AQ17: =SUM(BP$5:$BP17) -> 2.8265125 | AR17: {=2*SQRT(SUM((BQ$5:$BQ17/2)^2))} -> 0.035303673 | AS17: =SUM($BX$5:BX17) -> 0.21022599 | AT17: {=2*SQRT(SUM(($BY$5:BY17/2)^2))} -> 0.0098987954 | AU17: =AU16+R17 -> 2.7646138 | AW17: =AW16+T17 -> 0.24995478 | BF17: =IF((273+D17)>=600, 0.00074*EXP(-6613/(1.987*(273+D17)))*128000000000000000*EXP(1174/(1.987*(273+D17))), 0.000304*EXP(-5580/(1.987*(273+D17)))*199000000000000000*EXP(680/(1.987*(273+D17)))) -> 3.2922459e+11 | BG17: =BF17 * 1.17*EXP(-57/(1.987*(273+D17))) -> 3.6252593e+11 | BH17: =(D17+273)*$D$145*$F$144 -> 4.5073427e-16 | BN17: =BN16*EXP(-BD16*E16*60) -> 0.03277502 | BO17: =2*((((BO16/2)*EXP(-BD16*E16*60))^2+(BN16*EXP(-BD16*E16*60)*E16*60*BC16*BD16/BB16)^2)^0.5) -> 0.0054235857 | BP17: =R17+BN18-BN17 -> 0.53936148 | BQ17: =2*(((BO17/2)^2+(BO18/2)^2+(S17/2)^2)^(0.5)) -> 0.011455178 | BR17: =100*(BP17-R17)/R17 -> 3.9325816 | BV17: =BV16*EXP(-BB16*BH16*E16*60*0.91357457380209)*EXP(-(M16-1560)*$CW$126*$BH$48*0.91357457380209) -> 0.0037731644 | BW17: =2*SQRT( ((BW16/2) * EXP(-BB16 * BH16 * E16 * 60 * 0.91357457380209) * EXP(-(M16 - 1560) * $CW$126 * $BH$48 * 0.91357457380209))^2 + (BC16 * (-BV16 * BH16 * E16 * 60 * 0.91357457380209 * EXP(-BB16 * BH16 * E16 * 60 * 0.91357457380209) * EXP(-(M16 - 1560) * $CW$126 * $BH$48 * 0.91357457380209)))^2 + ((0.146030972937065 / 2) * BV16 * (-BB16 * BH16 * E16 * 60 - (M16 - 1560) * $CW$126 * $BH$48) * EXP(-BB16 * BH16 * E16 * 60 * 0.91357457380209) * EXP(-(M16 - 1560) * $CW$126 * $BH$48 * 0.91357457380209))^2 + -(M16-1560)*$BH$48*0.91357457380209*BV16*EXP(-BB16*BH16*E16*60*0.91357457380209)*EXP(-(M16-1560)*$CW$126*$BH$48*0.91357457380209)) -> 0.00088432151 | BX17: =Y17+BV18-BV17 -> 0.10664756 | BY17: =2*(((BW17/2)^2+(BW18/2)^2+(Z17/2)^2)^(0.5)) -> 0.004423375 | BZ17: =100*(BX17-Y17)/Y17 -> 7.4909983 | CA17: =R17*CC17 -> 0.1329938 | CB17: =BH17*BG17*J17 -> 4.9020858 | CC17: =1/(CB17-1) -> 0.2562732 | CD17: =CF17*T17 -> 0.029669814 | CE17: =BH17*BF17*J17 -> 4.4517842 | CF17: =1/(CE17-1) -> 0.28970525 | CG17: =R17-CA13 -> 0.37631132 | CH17: =R17+CA17 -> 0.65194703 | CI17: =T17-CD13 -> 0.085425877 | CJ17: =T17+CD17 -> 0.13208361 | CK17: =CE17*1.29 -> 5.7428016 | CL17: =R17 / (CK17-1) -> 0.10941913 | CM17: =1000*T17/R17 -> 197.34687
A18: He30287.txt | B18: IrrWin0601bTube012624: 4205_150.0_105.0 105.00 | C18: 45326.122 | D18: 105 | E18: =J18/60 -> 150 | F18: Informed/Naïve Bracket | G18: 3.06 | H18: 0 | I18: 0.144 | J18: 9000 | K18: 9129.026 | L18: =(C18-C17)*24*3600 -> 10560 | M18: =L18-J18 -> 1560 | O18: 0.0062250831 | P18: 0.025862069 | R18: 0.019048754 | S18: 0.00032080198 | T18: 0.0037241379 | U18: 1.595522e-05 | AQ18: =SUM(BP$5:$BP18) -> 2.8265125 | AR18: {=2*SQRT(SUM((BQ$5:$BQ18/2)^2))} -> 0.035303673 | AS18: =SUM($BX$5:BX18) -> 0.21022599 | AT18: {=2*SQRT(SUM(($BY$5:BY18/2)^2))} -> 0.0098987954 | AU18: =AU17+R18 -> 2.7836626 | AW18: =AW17+T18 -> 0.25367892 | AZ18: ='Naive Apparent Lambdas'!$U$2*(10000/(D18+273))+'Naive Apparent Lambdas'!$V$2 -> 25.64167 | BA18: ='Naive Apparent Lambdas'!$V$4 -> 0.067480704 | BB18: =EXP(AZ18) -> 1.367842e+11 | BC18: =BA18*BB18 -> 9.2302941e+09 | BD18: =BB18*(D18+273)*$D$145*$F$144 -> 4.9270523e-05 | BF18: =IF((273+D18)>=600, 0.00074*EXP(-6613/(1.987*(273+D18)))*128000000000000000*EXP(1174/(1.987*(273+D18))), 0.000304*EXP(-5580/(1.987*(273+D18)))*199000000000000000*EXP(680/(1.987*(273+D18)))) -> 8.8805251e+10 | BG18: =BF18 * 1.17*EXP(-57/(1.987*(273+D18))) -> 9.6308773e+10 | BH18: =(D18+273)*$D$145*$F$144 -> 3.6020625e-16 | BJ18: =R18/(1-EXP(-E18*60*BD18)) -> 0.05318328 | BK18: =2*SQRT( ((S18/2) * (1 / (1 - EXP(-E18 * 60 * BB18 * BH18))))^2 + (BC18 * (-R18 * 60 * E18 * BH18 * EXP(-E18 * 60 * BB18 * BH18) / (1 - EXP(-E18 * 60 * BB18 * BH18))^2))^2 ) -> 0.0057734014 | BL18: =R18/(1-EXP(-E18*60*BB18*BH18)*EXP(-(M18-1560)*$CW$126*$BH$122)) -> 0.05318328 | BM18: =2*SQRT( ((S18/2) * (1 / (1 - EXP(-E18 * 60 * BB18 * BH18) * EXP(-(M18 - 1560) * $CW$126 * $BH$48))))^2 + (BC18 * (-R18 * 60 * E18 * BH18 * EXP(-E18 * 60 * BB18 * BH18) / ((1 - EXP(-E18 * 60 * BB18 * BH18) * EXP(-(M18 - 1560) * $CW$126 * $BH$48))^2)))^2 + ($CX$126 * (-R18 * (M18 - 1560) * $BH$48 * EXP(-(M18 - 1560) * $CW$126 * $BH$48) / ((1 - EXP(-E18 * 60 * BB18 * BH18) * EXP(-(M18 - 1560) * $CW$126 * $BH$48))^2)))^2 ) -> 0.0057734014 | BN18: {=BJ18:BK18} -> 0.05318328 | BO18: 0.0057734014 | BT18: =BN18*(Y17/R17)*1.10204926384627 -> 0.011205384 | BU18: =2*(((BO18/2)*1.10204926384627*(AB17/(1000)))^2+((AC17/2000)*1.10204926384627*BN18)^2+((0.187040260207234/2)*BN18*(AB17/(1000)))^2)^0.5 -> 0.0023022532 | BV18: =BT18 -> 0.011205384 | BW18: =BU18 -> 0.0023022532 | CA18: =CA17*(EXP(-BH18*BG18*E18))*(EXP(-$BG$140*$F$144*D157*(24+273)*M18)) -> 0.13230354 | CD18: =CD17*(EXP(-BH18*BF18*E18))*(EXP(-$BF$140*$F$144*D157*(24+273)*M18)) -> 0.029527792
A19: He30289.txt | B19: IrrWin0601bTube012624: 4405_150.0_105.0 105.00 | C19: 45326.244 | D19: 105 | E19: =J19/60 -> 150 | F19: Naïve Bracket | G19: 1.79 | H19: 0 | I19: 0.187 | J19: 9000 | K19: 9127.555 | L19: =(C19-C18)*24*3600 -> 10560 | M19: =L19-J19 -> 1560 | O19: 0.0062200776 | P19: 0.025862069 | R19: 0.011133939 | S19: 0.00019782239 | T19: 0.0048362069 | U19: 1.9021875e-05 | AQ19: =SUM(BP$5:$BP19) -> 2.8265125 | AR19: {=2*SQRT(SUM((BQ$5:$BQ19/2)^2))} -> 0.035303673 | AS19: =SUM($BX$5:BX19) -> 0.21022599 | AT19: {=2*SQRT(SUM(($BY$5:BY19/2)^2))} -> 0.0098987954 | AU19: =AU18+R19 -> 2.7947965 | AW19: =AW18+T19 -> 0.25851513 | AZ19: ='Naive Apparent Lambdas'!$U$2*(10000/(D19+273))+'Naive Apparent Lambdas'!$V$2 -> 25.64167 | BA19: ='Naive Apparent Lambdas'!$V$4 -> 0.067480704 | BB19: =EXP(AZ19) -> 1.367842e+11 | BC19: =BA19*BB19 -> 9.2302941e+09 | BD19: =BB19*(D19+273)*$D$145*$F$144 -> 4.9270523e-05 | BF19: =IF((273+D19)>=600, 0.00074*EXP(-6613/(1.987*(273+D19)))*128000000000000000*EXP(1174/(1.987*(273+D19))), 0.000304*EXP(-5580/(1.987*(273+D19)))*199000000000000000*EXP(680/(1.987*(273+D19)))) -> 8.8805251e+10 | BG19: =BF19 * 1.17*EXP(-57/(1.987*(273+D19))) -> 9.6308773e+10 | BH19: =(D19+273)*$D$145*$F$144 -> 3.6020625e-16 | BJ19: =R19/(1-EXP(-E19*60*BD19)) -> 0.031085465 | BK19: =2*SQRT( ((S19/2) * (1 / (1 - EXP(-E19 * 60 * BB19 * BH19))))^2 + (BC19 * (-R19 * 60 * E19 * BH19 * EXP(-E19 * 60 * BB19 * BH19) / (1 - EXP(-E19 * 60 * BB19 * BH19))^2))^2 ) -> 0.003379123 | BL19: =R19/(1-EXP(-E19*60*BB19*BH19)*EXP(-(M19-1560)*$CW$126*$BH$122)) -> 0.031085465 | BM19: =2*SQRT( ((S19/2) * (1 / (1 - EXP(-E19 * 60 * BB19 * BH19) * EXP(-(M19 - 1560) * $CW$126 * $BH$48))))^2 + (BC19 * (-R19 * 60 * E19 * BH19 * EXP(-E19 * 60 * BB19 * BH19) / ((1 - EXP(-E19 * 60 * BB19 * BH19) * EXP(-(M19 - 1560) * $CW$126 * $BH$48))^2)))^2 + ($CX$126 * (-R19 * (M19 - 1560) * $BH$48 * EXP(-(M19 - 1560) * $CW$126 * $BH$48) / ((1 - EXP(-E19 * 60 * BB19 * BH19) * EXP(-(M19 - 1560) * $CW$126 * $BH$48))^2)))^2 ) -> 0.003379123 | BN19: =BN18*EXP(-BD18*E18*60) -> 0.034134525 | BO19: =2*((((BO18/2)*EXP(-BD18*E18*60))^2+(BN18*EXP(-BD18*E18*60)*E18*60*BC18*BD18/BB18)^2)^0.5) -> 0.0042313279 | BV19: =BV18*EXP(-BB18*BH18*E18*60*0.91357457380209)*EXP(-(M18-1560)*$CW$126*$BH$48*0.91357457380209) -> 0.0074729043 | BW19: =2*SQRT( ((BW18/2) * EXP(-BB18 * BH18 * E18 * 60 * 0.91357457380209) * EXP(-(M18 - 1560) * $CW$126 * $BH$48 * 0.91357457380209))^2 + (BC18 * (-BV18 * BH18 * E18 * 60 * 0.91357457380209 * EXP(-BB18 * BH18 * E18 * 60 * 0.91357457380209) * EXP(-(M18 - 1560) * $CW$126 * $BH$48 * 0.91357457380209)))^2 + ((0.146030972937065 / 2) * BV18 * (-BB18 * BH18 * E18 * 60 - (M18 - 1560) * $CW$126 * $BH$48) * EXP(-BB18 * BH18 * E18 * 60 * 0.91357457380209) * EXP(-(M18 - 1560) * $CW$126 * $BH$48 * 0.91357457380209))^2 + -(M18-1560)*$BH$48*0.91357457380209*BV18*EXP(-BB18*BH18*E18*60*0.91357457380209)*EXP(-(M18-1560)*$CW$126*$BH$48*0.91357457380209)) -> 0.0016608712 | CA19: =CA18*(EXP(-BH19*BG19*E19))*(EXP(-$BG$140*$F$144*D158*(24+273)*M19)) -> 0.13161687 | CD19: =CD18*(EXP(-BH19*BF19*E19))*(EXP(-$BF$140*$F$144*D158*(24+273)*M19)) -> 0.02938645
A20: He30292.txt | B20: IrrWin0601bTube012624: 4605_150.0_105.0 105.00 | C20: 45326.366 | D20: 105 | E20: =J20/60 -> 150 | F20: Naïve Bracket | G20: 1.29 | H20: 0 | I20: 0.04 | J20: 9000 | K20: 9129.528 | L20: =(C20-C19)*24*3600 -> 10560 | M20: =L20-J20 -> 1560 | O20: 0.006222837 | P20: 0.025875098 | R20: 0.0080274597 | S20: 0.00014295915 | T20: 0.0010350039 | U20: 4.1228765e-06 | AQ20: =SUM(BP$5:$BP20) -> 2.8265125 | AR20: {=2*SQRT(SUM((BQ$5:$BQ20/2)^2))} -> 0.035303673 | AS20: =SUM($BX$5:BX20) -> 0.21022599 | AT20: {=2*SQRT(SUM(($BY$5:BY20/2)^2))} -> 0.0098987954 | AU20: =AU19+R20 -> 2.802824 | AW20: =AW19+T20 -> 0.25955013 | AZ20: ='Naive Apparent Lambdas'!$U$2*(10000/(D20+273))+'Naive Apparent Lambdas'!$V$2 -> 25.64167 | BA20: ='Naive Apparent Lambdas'!$V$4 -> 0.067480704 | BB20: =EXP(AZ20) -> 1.367842e+11 | BC20: =BA20*BB20 -> 9.2302941e+09 | BD20: =BB20*(D20+273)*$D$145*$F$144 -> 4.9270523e-05 | BF20: =IF((273+D20)>=600, 0.00074*EXP(-6613/(1.987*(273+D20)))*128000000000000000*EXP(1174/(1.987*(273+D20))), 0.000304*EXP(-5580/(1.987*(273+D20)))*199000000000000000*EXP(680/(1.987*(273+D20)))) -> 8.8805251e+10 | BG20: =BF20 * 1.17*EXP(-57/(1.987*(273+D20))) -> 9.6308773e+10 | BH20: =(D20+273)*$D$145*$F$144 -> 3.6020625e-16 | BJ20: =R20/(1-EXP(-E20*60*BD20)) -> 0.022412313 | BK20: =2*SQRT( ((S20/2) * (1 / (1 - EXP(-E20 * 60 * BB20 * BH20))))^2 + (BC20 * (-R20 * 60 * E20 * BH20 * EXP(-E20 * 60 * BB20 * BH20) / (1 - EXP(-E20 * 60 * BB20 * BH20))^2))^2 ) -> 0.0024364655 | BL20: =R20/(1-EXP(-E20*60*BB20*BH20)*EXP(-(M20-1560)*$CW$126*$BH$122)) -> 0.022412313 | BM20: =2*SQRT( ((S20/2) * (1 / (1 - EXP(-E20 * 60 * BB20 * BH20) * EXP(-(M20 - 1560) * $CW$126 * $BH$48))))^2 + (BC20 * (-R20 * 60 * E20 * BH20 * EXP(-E20 * 60 * BB20 * BH20) / ((1 - EXP(-E20 * 60 * BB20 * BH20) * EXP(-(M20 - 1560) * $CW$126 * $BH$48))^2)))^2 + ($CX$126 * (-R20 * (M20 - 1560) * $BH$48 * EXP(-(M20 - 1560) * $CW$126 * $BH$48) / ((1 - EXP(-E20 * 60 * BB20 * BH20) * EXP(-(M20 - 1560) * $CW$126 * $BH$48))^2)))^2 ) -> 0.0024364655 | BN20: =BN19*EXP(-BD19*E19*60) -> 0.021908499 | BO20: =2*((((BO19/2)*EXP(-BD19*E19*60))^2+(BN19*EXP(-BD19*E19*60)*E19*60*BC19*BD19/BB19)^2)^0.5) -> 0.0030157255 | BV20: =BV19*EXP(-BB19*BH19*E19*60*0.91357457380209)*EXP(-(M19-1560)*$CW$126*$BH$48*0.91357457380209) -> 0.0049837023 | BW20: =2*SQRT( ((BW19/2) * EXP(-BB19 * BH19 * E19 * 60 * 0.91357457380209) * EXP(-(M19 - 1560) * $CW$126 * $BH$48 * 0.91357457380209))^2 + (BC19 * (-BV19 * BH19 * E19 * 60 * 0.91357457380209 * EXP(-BB19 * BH19 * E19 * 60 * 0.91357457380209) * EXP(-(M19 - 1560) * $CW$126 * $BH$48 * 0.91357457380209)))^2 + ((0.146030972937065 / 2) * BV19 * (-BB19 * BH19 * E19 * 60 - (M19 - 1560) * $CW$126 * $BH$48) * EXP(-BB19 * BH19 * E19 * 60 * 0.91357457380209) * EXP(-(M19 - 1560) * $CW$126 * $BH$48 * 0.91357457380209))^2 + -(M19-1560)*$BH$48*0.91357457380209*BV19*EXP(-BB19*BH19*E19*60*0.91357457380209)*EXP(-(M19-1560)*$CW$126*$BH$48*0.91357457380209)) -> 0.0011854368 | CA20: =CA19*(EXP(-BH20*BG20*E20))*(EXP(-$BG$140*$F$144*D159*(24+273)*M20)) -> 0.13093376 | CD20: =CD19*(EXP(-BH20*BF20*E20))*(EXP(-$BF$140*$F$144*D159*(24+273)*M20)) -> 0.029245785
A21: He30296.txt | B21: IrrWin0601bTube012624: 4805_475.0_210.0 210.00 | C21: 45326.714 | D21: 210 | E21: =J21/60 -> 475 | F21: Experimental | G21: 93 | H21: 0 | I21: 5.64 | J21: 28500 | K21: 28626.295 | L21: =(C21-C20)*24*3600 -> 30060 | M21: =L21-J21 -> 1560 | O21: 0.0062046044 | P21: 0.025884273 | R21: 0.57702821 | S21: 0.0099925221 | T21: 0.1459873 | U21: 0.00061153078 | W21: =(1000*T21/R21)/$AG$140 -> 0.2535767 | Y21: =T21-AVERAGE(T22:T24) -> 0.14020058 | Z21: =U21+AVERAGE(T22:T24) -> 0.0063982505 | AB21: =(Y21*1000)/R21 -> 242.97006 | AC21: =2*((1000*Z21/(2*R21))^2+((S21/2)*1000*Y21/(R21^2))^2)^0.5 -> 11.859745 | AD21: =AB21/$AG$140 -> 0.2435253 | AE21: =2*(($AH$140*AB21/(2*$AG$140^2))^2+(AC21/($AG$140*2))^2)^0.5 -> 0.012168421 | AG21: {=BP21:BQ21} -> 0.61818171 | AH21: 0.011701238 | AI21: {=BX21:BY21} -> 0.15166157 | AJ21: 0.0071272338 | AL21: =1000*AI21/AG21 -> 245.33494 | AM21: =2*((AH21*1000*AI21/(2*AG21^2))^2+(1000*AJ21/(AG21*2))^2)^0.5 -> 12.42944 | AN21: =AL21/$AG$140 -> 0.24589558 | AO21: =2*(($AH$140*AL21/(2*$AG$140^2))^2+(AM21/($AG$140*2))^2)^0.5 -> 0.012731995 | AQ21: =SUM(BP$5:$BP21) -> 3.4446943 | AR21: {=2*SQRT(SUM((BQ$5:$BQ21/2)^2))} -> 0.037192315 | AS21: =SUM($BX$5:BX21) -> 0.36188756 | AT21: {=2*SQRT(SUM(($BY$5:BY21/2)^2))} -> 0.012197689 | AU21: =AU20+R21 -> 3.3798522 | AW21: =AW20+T21 -> 0.40553743 | BF21: =IF((273+D21)>=600, 0.00074*EXP(-6613/(1.987*(273+D21)))*128000000000000000*EXP(1174/(1.987*(273+D21))), 0.000304*EXP(-5580/(1.987*(273+D21)))*199000000000000000*EXP(680/(1.987*(273+D21)))) -> 3.6675059e+11 | BG21: =BF21 * 1.17*EXP(-57/(1.987*(273+D21))) -> 4.0435513e+11 | BH21: =(D21+273)*$D$145*$F$144 -> 4.6026354e-16 | BN21: =BN20*EXP(-BD20*E20*60) -> 0.014061491 | BO21: =2*((((BO20/2)*EXP(-BD20*E20*60))^2+(BN20*EXP(-BD20*E20*60)*E20*60*BC20*BD20/BB20)^2)^0.5) -> 0.002110601 | BP21: =R21+BN22-BN21 -> 0.61818171 | BQ21: =2*(((BO21/2)^2+(BO22/2)^2+(S21/2)^2)^(0.5)) -> 0.011701238 | BR21: =100*(BP21-R21)/R21 -> 7.1319727 | BV21: =BV20*EXP(-BB20*BH20*E20*60*0.91357457380209)*EXP(-(M20-1560)*$CW$126*$BH$48*0.91357457380209) -> 0.003323646 | BW21: =2*SQRT( ((BW20/2) * EXP(-BB20 * BH20 * E20 * 60 * 0.91357457380209) * EXP(-(M20 - 1560) * $CW$126 * $BH$48 * 0.91357457380209))^2 + (BC20 * (-BV20 * BH20 * E20 * 60 * 0.91357457380209 * EXP(-BB20 * BH20 * E20 * 60 * 0.91357457380209) * EXP(-(M20 - 1560) * $CW$126 * $BH$48 * 0.91357457380209)))^2 + ((0.146030972937065 / 2) * BV20 * (-BB20 * BH20 * E20 * 60 - (M20 - 1560) * $CW$126 * $BH$48) * EXP(-BB20 * BH20 * E20 * 60 * 0.91357457380209) * EXP(-(M20 - 1560) * $CW$126 * $BH$48 * 0.91357457380209))^2 + -(M20-1560)*$BH$48*0.91357457380209*BV20*EXP(-BB20*BH20*E20*60*0.91357457380209)*EXP(-(M20-1560)*$CW$126*$BH$48*0.91357457380209)) -> 0.00083925303 | BX21: =Y21+BV22-BV21 -> 0.15166157 | BY21: =2*(((BW21/2)^2+(BW22/2)^2+(Z21/2)^2)^(0.5)) -> 0.0071272338 | BZ21: =100*(BX21-Y21)/Y21 -> 8.1747118 | CA21: =R21*CC21 -> 0.13406376 | CB21: =BH21*BG21*J21 -> 5.3041328 | CC21: =1/(CB21-1) -> 0.23233484 | CD21: =CF21*T21 -> 0.038308281 | CE21: =BH21*BF21*J21 -> 4.8108549 | CF21: =1/(CE21-1) -> 0.26240831 | CG21: =R21-CA17 -> 0.44403441 | CH21: =R21+CA21 -> 0.71109197 | CI21: =T21-CD17 -> 0.11631749 | CJ21: =T21+CD21 -> 0.18429558 | CK21: =CE21*1.29 -> 6.2060028 | CL21: =R21 / (CK21-1) -> 0.11083901 | CM21: =1000*T21/R21 -> 252.99855 | CN21: =1000*(T21+CD21)/(R21+CL21) -> 267.92319 | CO21: =1000*(T21-CD17)/(R21-CL17) -> 248.74942 | CP21: =1000*(T21+CD21-CD17)/(R21+CL21-CL17) -> 267.3114 | CQ21: =MAX(CM21:CP21) -> 267.92319 | CR21: =MIN(CM21:CP21) -> 248.74942
A22: He30298.txt | B22: IrrWin0601bTube012624: 5105_150.0_110.0 109.99 | C22: 45326.836 | D22: 109.99 | E22: =J22/60 -> 150 | F22: Informed/Naïve Bracket | G22: 3.71 | H22: 0 | I22: 0.374 | J22: 9000 | K22: 9128.359 | L22: =(C22-C21)*24*3600 -> 10560 | M22: =L22-J22 -> 1560 | O22: 0.0061766666 | P22: 0.025862224 | R22: 0.022915433 | S22: 0.0003930218 | T22: 0.0096724716 | U22: 4.0523336e-05 | AQ22: =SUM(BP$5:$BP22) -> 3.4446943 | AR22: {=2*SQRT(SUM((BQ$5:$BQ22/2)^2))} -> 0.037192315 | AS22: =SUM($BX$5:BX22) -> 0.36188756 | AT22: {=2*SQRT(SUM(($BY$5:BY22/2)^2))} -> 0.012197689 | AU22: =AU21+R22 -> 3.4027676 | AW22: =AW21+T22 -> 0.4152099 | AZ22: ='Naive Apparent Lambdas'!$U$2*(10000/(D22+273))+'Naive Apparent Lambdas'!$V$2 -> 25.818477 | BA22: ='Naive Apparent Lambdas'!$V$4 -> 0.067480704 | BB22: =EXP(AZ22) -> 1.6323829e+11 | BC22: =BA22*BB22 -> 1.1015435e+10 | BD22: =BB22*(D22+273)*$D$145*$F$144 -> 5.9575669e-05 | BF22: =IF((273+D22)>=600, 0.00074*EXP(-6613/(1.987*(273+D22)))*128000000000000000*EXP(1174/(1.987*(273+D22))), 0.000304*EXP(-5580/(1.987*(273+D22)))*199000000000000000*EXP(680/(1.987*(273+D22)))) -> 9.6683804e+10 | BG22: =BF22 * 1.17*EXP(-57/(1.987*(273+D22))) -> 1.0495674e+11 | BH22: =(D22+273)*$D$145*$F$144 -> 3.6496135e-16 | BJ22: =R22/(1-EXP(-E22*60*BD22)) -> 0.055214986 | BK22: =2*SQRT( ((S22/2) * (1 / (1 - EXP(-E22 * 60 * BB22 * BH22))))^2 + (BC22 * (-R22 * 60 * E22 * BH22 * EXP(-E22 * 60 * BB22 * BH22) / (1 - EXP(-E22 * 60 * BB22 * BH22))^2))^2 ) -> 0.0057108534 | BL22: =R22/(1-EXP(-E22*60*BB22*BH22)*EXP(-(M22-1560)*$CW$126*$BH$122)) -> 0.055214986 | BM22: =2*SQRT( ((S22/2) * (1 / (1 - EXP(-E22 * 60 * BB22 * BH22) * EXP(-(M22 - 1560) * $CW$126 * $BH$48))))^2 + (BC22 * (-R22 * 60 * E22 * BH22 * EXP(-E22 * 60 * BB22 * BH22) / ((1 - EXP(-E22 * 60 * BB22 * BH22) * EXP(-(M22 - 1560) * $CW$126 * $BH$48))^2)))^2 + ($CX$126 * (-R22 * (M22 - 1560) * $BH$48 * EXP(-(M22 - 1560) * $CW$126 * $BH$48) / ((1 - EXP(-E22 * 60 * BB22 * BH22) * EXP(-(M22 - 1560) * $CW$126 * $BH$48))^2)))^2 ) -> 0.0057108534 | BN22: {=BJ22:BK22} -> 0.055214986 | BO22: 0.0057108534 | BT22: =BN22*(Y21/R21)*1.10204926384627 -> 0.014784639 | BU22: =2*(((BO22/2)*1.10204926384627*(AB21/(1000)))^2+((AC21/2000)*1.10204926384627*BN22)^2+((0.187040260207234/2)*BN22*(AB21/(1000)))^2)^0.5 -> 0.0030258068 | BV22: =BT22 -> 0.014784639 | BW22: =BU22 -> 0.0030258068 | CA22: =CA21*(EXP(-BH22*BG22*E22))*(EXP(-$BG$140*$F$144*D161*(24+273)*M22)) -> 0.13329567 | CD22: =CD21*(EXP(-BH22*BF22*E22))*(EXP(-$BF$140*$F$144*D161*(24+273)*M22)) -> 0.038106056
A23: He30301.txt | B23: IrrWin0601bTube012624: 5305_150.0_110.0 110.00 | C23: 45326.958 | D23: 110 | E23: =J23/60 -> 150 | F23: Naïve Bracket | G23: 1.86 | H23: 0 | I23: 0.171 | J23: 9000 | K23: 9129.162 | L23: =(C23-C22)*24*3600 -> 10560 | M23: =L23-J23 -> 1560 | O23: 0.0061889977 | P23: 0.025874449 | R23: 0.011511536 | S23: 0.00020127919 | T23: 0.0044245308 | U23: 1.8146535e-05 | AQ23: =SUM(BP$5:$BP23) -> 3.4446943 | AR23: {=2*SQRT(SUM((BQ$5:$BQ23/2)^2))} -> 0.037192315 | AS23: =SUM($BX$5:BX23) -> 0.36188756 | AT23: {=2*SQRT(SUM(($BY$5:BY23/2)^2))} -> 0.012197689 | AU23: =AU22+R23 -> 3.4142792 | AW23: =AW22+T23 -> 0.41963443 | AZ23: ='Naive Apparent Lambdas'!$U$2*(10000/(D23+273))+'Naive Apparent Lambdas'!$V$2 -> 25.818827 | BA23: ='Naive Apparent Lambdas'!$V$4 -> 0.067480704 | BB23: =EXP(AZ23) -> 1.6329539e+11 | BC23: =BA23*BB23 -> 1.1019288e+10 | BD23: =BB23*(D23+273)*$D$145*$F$144 -> 5.9598062e-05 | BF23: =IF((273+D23)>=600, 0.00074*EXP(-6613/(1.987*(273+D23)))*128000000000000000*EXP(1174/(1.987*(273+D23))), 0.000304*EXP(-5580/(1.987*(273+D23)))*199000000000000000*EXP(680/(1.987*(273+D23)))) -> 9.6700059e+10 | BG23: =BF23 * 1.17*EXP(-57/(1.987*(273+D23))) -> 1.049746e+11 | BH23: =(D23+273)*$D$145*$F$144 -> 3.6497088e-16 | BJ23: =R23/(1-EXP(-E23*60*BD23)) -> 0.027729294 | BK23: =2*SQRT( ((S23/2) * (1 / (1 - EXP(-E23 * 60 * BB23 * BH23))))^2 + (BC23 * (-R23 * 60 * E23 * BH23 * EXP(-E23 * 60 * BB23 * BH23) / (1 - EXP(-E23 * 60 * BB23 * BH23))^2))^2 ) -> 0.0028692692 | BL23: =R23/(1-EXP(-E23*60*BB23*BH23)*EXP(-(M23-1560)*$CW$126*$BH$122)) -> 0.027729294 | BM23: =2*SQRT( ((S23/2) * (1 / (1 - EXP(-E23 * 60 * BB23 * BH23) * EXP(-(M23 - 1560) * $CW$126 * $BH$48))))^2 + (BC23 * (-R23 * 60 * E23 * BH23 * EXP(-E23 * 60 * BB23 * BH23) / ((1 - EXP(-E23 * 60 * BB23 * BH23) * EXP(-(M23 - 1560) * $CW$126 * $BH$48))^2)))^2 + ($CX$126 * (-R23 * (M23 - 1560) * $BH$48 * EXP(-(M23 - 1560) * $CW$126 * $BH$48) / ((1 - EXP(-E23 * 60 * BB23 * BH23) * EXP(-(M23 - 1560) * $CW$126 * $BH$48))^2)))^2 ) -> 0.0028692692 | BN23: =BN22*EXP(-BD22*E22*60) -> 0.032299553 | BO23: =2*((((BO22/2)*EXP(-BD22*E22*60))^2+(BN22*EXP(-BD22*E22*60)*E22*60*BC22*BD22/BB22)^2)^0.5) -> 0.0040771907 | BV23: =BV22*EXP(-BB22*BH22*E22*60*0.91357457380209)*EXP(-(M22-1560)*$CW$126*$BH$48*0.91357457380209) -> 0.0090588974 | BW23: =2*SQRT( ((BW22/2) * EXP(-BB22 * BH22 * E22 * 60 * 0.91357457380209) * EXP(-(M22 - 1560) * $CW$126 * $BH$48 * 0.91357457380209))^2 + (BC22 * (-BV22 * BH22 * E22 * 60 * 0.91357457380209 * EXP(-BB22 * BH22 * E22 * 60 * 0.91357457380209) * EXP(-(M22 - 1560) * $CW$126 * $BH$48 * 0.91357457380209)))^2 + ((0.146030972937065 / 2) * BV22 * (-BB22 * BH22 * E22 * 60 - (M22 - 1560) * $CW$126 * $BH$48) * EXP(-BB22 * BH22 * E22 * 60 * 0.91357457380209) * EXP(-(M22 - 1560) * $CW$126 * $BH$48 * 0.91357457380209))^2 + -(M22-1560)*$BH$48*0.91357457380209*BV22*EXP(-BB22*BH22*E22*60*0.91357457380209)*EXP(-(M22-1560)*$CW$126*$BH$48*0.91357457380209)) -> 0.0020734084 | CA23: =CA22*(EXP(-BH23*BG23*E23))*(EXP(-$BG$140*$F$144*D162*(24+273)*M23)) -> 0.13253183 | CD23: =CD22*(EXP(-BH23*BF23*E23))*(EXP(-$BF$140*$F$144*D162*(24+273)*M23)) -> 0.037904859
